[
    {
        "type": "message",
        "subtype": "bot_message",
        "text": "[GOOD] \/usr\/share\/nginx\/html\/commanders\/omnath-locus-of-mana.html has been updated!",
        "ts": "1558249408.014200",
        "username": "edhrecbot",
        "icons": {
            "emoji": ":robot_face:",
            "image_64": "https:\/\/a.slack-edge.com\/37d58\/img\/emoji_2017_12_06\/apple\/1f916.png"
        },
        "bot_id": "B2867AJ5C"
    },
    {
        "type": "message",
        "subtype": "bot_message",
        "text": "```2019-05-19 08:12:32,783 INFO backup.py took 0:12:30.740540\n```",
        "ts": "1558253457.014300",
        "username": "edhrecbot",
        "icons": {
            "emoji": ":robot_face:",
            "image_64": "https:\/\/a.slack-edge.com\/37d58\/img\/emoji_2017_12_06\/apple\/1f916.png"
        },
        "bot_id": "B2867AJ5C"
    },
    {
        "type": "message",
        "subtype": "bot_message",
        "text": "",
        "ts": "1558253518.014400",
        "username": "incoming-webhook",
        "bot_id": "B5XN109SM",
        "attachments": [
            {
                "fallback": "<@channel>   *[Amazon CloudWatch Notification]* \nSubject: ALARM: \"EDHREC NetworkOut\" in US East (N. Virginia)\nMessage: {\"AlarmName\":\"EDHREC NetworkOut\",\"AlarmDescription\":null,\"AWSAccountId\":\"083767677168\",\"NewStateValue\":\"ALARM\",\"NewStateReason\":\"Threshold Crossed: 1 datapoint [7.040295244E8 (19\/05\/19 08:06:00)] was greater than or equal to the threshold (3.0E8).\",\"StateChangeTime\":\"2019-05-19T08:11:57.673+0000\",\"Region\":\"US East (N. Virginia)\",\"OldStateValue\":\"OK\",\"Trigger\":{\"MetricName\":\"NetworkOut\",\"Namespace\":\"AWS\/EC2\",\"StatisticType\":\"Statistic\",\"Statistic\":\"AVERAGE\",\"Unit\":null,\"Dimensions\":[{\"value\":\"i-0f7f3750e584e120e\",\"name\":\"InstanceId\"}],\"Period\":300,\"EvaluationPeriods\":1,\"ComparisonOperator\":\"GreaterThanOrEqualToThreshold\",\"Threshold\":3.0E8,\"TreatMissingData\":\"- TreatMissingData:                    missing\",\"EvaluateLowSampleCountPercentile\":\"\"}}\nTimestamp: 2019-05-19T08:11:57.753Z ",
                "text": "<@channel>   *[Amazon CloudWatch Notification]* \nSubject: ALARM: \"EDHREC NetworkOut\" in US East (N. Virginia)\nMessage: {\"AlarmName\":\"EDHREC NetworkOut\",\"AlarmDescription\":null,\"AWSAccountId\":\"083767677168\",\"NewStateValue\":\"ALARM\",\"NewStateReason\":\"Threshold Crossed: 1 datapoint [7.040295244E8 (19\/05\/19 08:06:00)] was greater than or equal to the threshold (3.0E8).\",\"StateChangeTime\":\"2019-05-19T08:11:57.673+0000\",\"Region\":\"US East (N. Virginia)\",\"OldStateValue\":\"OK\",\"Trigger\":{\"MetricName\":\"NetworkOut\",\"Namespace\":\"AWS\/EC2\",\"StatisticType\":\"Statistic\",\"Statistic\":\"AVERAGE\",\"Unit\":null,\"Dimensions\":[{\"value\":\"i-0f7f3750e584e120e\",\"name\":\"InstanceId\"}],\"Period\":300,\"EvaluationPeriods\":1,\"ComparisonOperator\":\"GreaterThanOrEqualToThreshold\",\"Threshold\":3.0E8,\"TreatMissingData\":\"- TreatMissingData:                    missing\",\"EvaluateLowSampleCountPercentile\":\"\"}}\nTimestamp: 2019-05-19T08:11:57.753Z ",
                "id": 1,
                "color": "F35A00",
                "fields": [
                    {
                        "title": "Severity",
                        "value": "ALARM",
                        "short": true
                    }
                ],
                "mrkdwn_in": [
                    "text"
                ]
            }
        ]
    },
    {
        "type": "message",
        "subtype": "bot_message",
        "text": "Nightly completed",
        "ts": "1558255139.014500",
        "username": "edhrecbot",
        "icons": {
            "emoji": ":robot_face:",
            "image_64": "https:\/\/a.slack-edge.com\/37d58\/img\/emoji_2017_12_06\/apple\/1f916.png"
        },
        "bot_id": "B2867AJ5C"
    },
    {
        "type": "message",
        "subtype": "bot_message",
        "text": "```2019-05-19 08:40:35,846 INFO nightly.py took 1 day, 6:24:32.870798\n```",
        "ts": "1558255140.014600",
        "username": "edhrecbot",
        "icons": {
            "emoji": ":robot_face:",
            "image_64": "https:\/\/a.slack-edge.com\/37d58\/img\/emoji_2017_12_06\/apple\/1f916.png"
        },
        "bot_id": "B2867AJ5C"
    },
    {
        "type": "message",
        "subtype": "bot_message",
        "text": "```2019-05-19 12:08:25,850 INFO New Trending 2019-05-19\n{\"name\": \"Blighted Woodland\", \"s\": [0, 40, 38, 46, 69, 60, 67], \"z\": 1.3336693378275257}\n{\"name\": \"Kiora, Behemoth Beckoner\", \"s\": [0, 8, 7, 9, 18, 19, 19], \"z\": 1.2928907508578493}\n{\"name\": \"Crucible of Worlds\", \"s\": [0, 38, 27, 35, 47, 56, 57], \"z\": 1.2800106887286478}\n{\"name\": \"Drowned Catacomb\", \"s\": [0, 55, 62, 72, 89, 97, 83], \"z\": 1.2760671551178546}\n{\"name\": \"Buried Alive\", \"s\": [0, 23, 32, 29, 40, 51, 48], \"z\": 1.2750133144267648}\n{\"name\": \"Darksteel Ingot\", \"s\": [0, 68, 83, 77, 113, 91, 117], \"z\": 1.2610522552731263}\n{\"name\": \"Vivid Marsh\", \"s\": [0, 20, 12, 18, 33, 25, 40], \"z\": 1.2485215292978835}\n{\"name\": \"Command the Dreadhorde\", \"s\": [0, 8, 9, 13, 18, 20, 18], \"z\": 1.2323929846063753}\n{\"name\": \"Sylvan Caryatid\", \"s\": [0, 11, 9, 11, 18, 20, 20], \"z\": 1.231954595278264}\n{\"name\": \"Mana Geode\", \"s\": [0, 13, 12, 11, 20, 23, 27], \"z\": 1.2270382187349276}\n2019-05-19 12:08:25,865 INFO daily.py took 4:08:20.949267\n```",
        "ts": "1558267610.014700",
        "username": "edhrecbot",
        "icons": {
            "emoji": ":robot_face:",
            "image_64": "https:\/\/a.slack-edge.com\/37d58\/img\/emoji_2017_12_06\/apple\/1f916.png"
        },
        "bot_id": "B2867AJ5C"
    },
    {
        "type": "message",
        "subtype": "bot_message",
        "text": "Nightly started, onlydecks=False, skipdecks=False",
        "ts": "1558291497.014800",
        "username": "edhrecbot",
        "icons": {
            "emoji": ":robot_face:",
            "image_64": "https:\/\/a.slack-edge.com\/37d58\/img\/emoji_2017_12_06\/apple\/1f916.png"
        },
        "bot_id": "B2867AJ5C"
    },
    {
        "type": "message",
        "subtype": "bot_message",
        "text": "Nightly failed:\nterminating connection due to administrator command\nserver closed the connection unexpectedly\n\tThis probably means the server terminated abnormally\n\tbefore or while processing the request.\n\nmultiprocessing.pool.RemoteTraceback: \n\"\"\"\nTraceback (most recent call last):\n  File \"\/usr\/lib\/python3.5\/multiprocessing\/pool.py\", line 119, in worker\n    result = (True, func(*args, **kwds))\n  File \"\/usr\/lib\/python3.5\/multiprocessing\/pool.py\", line 44, in mapstar\n    return list(map(*args))\n  File \"\/home\/ubuntu\/edhrec\/web\/nightly.py\", line 512, in make_card\n    label = 'In {} decks&lt;br&gt;{:.0f}% of {} decks'.format(\n  File \"\/home\/ubuntu\/edhrec\/web\/origin.py\", line 67, in getcards\n    data = database.tally(decks)\n  File \"\/home\/ubuntu\/edhrec\/core\/database.py\", line 1857, in tally\n    'instant': [],\n  File \"\/home\/ubuntu\/edhrec\/core\/database.py\", line 941, in get_decks\n    return _get_decks_helper(urls) # + _get_decks_helper(urls, brawl=True) + _get_decks_helper(urls, tiny=True) BRAWL\n  File \"\/home\/ubuntu\/edhrec\/core\/database.py\", line 902, in _get_decks_helper\n    ), urls[:fetch_size])\n  File \"\/usr\/local\/lib\/python3.5\/dist-packages\/psycopg2\/extras.py\", line 141, in execute\n    return super(DictCursor, self).execute(query, vars)\npsycopg2.OperationalError: terminating connection due to administrator command\nserver closed the connection unexpectedly\n\tThis probably means the server terminated abnormally\n\tbefore or while processing the request.\n\n\"\"\"\n\nThe above exception was the direct cause of the following exception:\n\nTraceback (most recent call last):\n  File \"\/home\/ubuntu\/edhrec\/web\/nightly.py\", line 950, in nightly\n    make_split_cards()\n  File \"\/home\/ubuntu\/edhrec\/web\/nightly.py\", line 791, in make_cards\n    sys.exit(1)\n  File \"\/usr\/lib\/python3.5\/multiprocessing\/pool.py\", line 260, in map\n    return self._map_async(func, iterable, mapstar, chunksize).get()\n  File \"\/usr\/lib\/python3.5\/multiprocessing\/pool.py\", line 608, in get\n    raise self._value\npsycopg2.OperationalError: terminating connection due to administrator command\nserver closed the connection unexpectedly\n\tThis probably means the server terminated abnormally\n\tbefore or while processing the request.\n\n",
        "ts": "1558292013.014900",
        "username": "edhrecbot",
        "icons": {
            "emoji": ":robot_face:",
            "image_64": "https:\/\/a.slack-edge.com\/37d58\/img\/emoji_2017_12_06\/apple\/1f916.png"
        },
        "bot_id": "B2867AJ5C"
    },
    {
        "type": "message",
        "subtype": "bot_message",
        "text": "```2019-05-19 18:55:09,966 ERROR terminating connection due to administrator command\nserver closed the connection unexpectedly\n\tThis probably means the server terminated abnormally\n\tbefore or while processing the request.\n\n2019-05-19 18:55:09,971 ERROR multiprocessing.pool.RemoteTraceback: \n\"\"\"\nTraceback (most recent call last):\n  File \"\/usr\/lib\/python3.5\/multiprocessing\/pool.py\", line 119, in worker\n    result = (True, func(*args, **kwds))\n  File \"\/usr\/lib\/python3.5\/multiprocessing\/pool.py\", line 44, in mapstar\n    return list(map(*args))\n  File \"\/home\/ubuntu\/edhrec\/web\/nightly.py\", line 512, in make_card\n    label = 'In {} decks&lt;br&gt;{:.0f}% of {} decks'.format(\n  File \"\/home\/ubuntu\/edhrec\/web\/origin.py\", line 67, in getcards\n    data = database.tally(decks)\n  File \"\/home\/ubuntu\/edhrec\/core\/database.py\", line 1857, in tally\n    'instant': [],\n  File \"\/home\/ubuntu\/edhrec\/core\/database.py\", line 941, in get_decks\n    return _get_decks_helper(urls) # + _get_decks_helper(urls, brawl=True) + _get_decks_helper(urls, tiny=True) BRAWL\n  File \"\/home\/ubuntu\/edhrec\/core\/database.py\", line 902, in _get_decks_helper\n    ), urls[:fetch_size])\n  File \"\/usr\/local\/lib\/python3.5\/dist-packages\/psycopg2\/extras.py\", line 141, in execute\n    return super(DictCursor, self).execute(query, vars)\npsycopg2.OperationalError: terminating connection due to administrator command\nserver closed the connection unexpectedly\n\tThis probably means the server terminated abnormally\n\tbefore or while processing the request.\n\n\"\"\"\n\nThe above exception was the direct cause of the following exception:\n\nTraceback (most recent call last):\n  File \"\/home\/ubuntu\/edhrec\/web\/nightly.py\", line 950, in nightly\n    make_split_cards()\n  File \"\/home\/ubuntu\/edhrec\/web\/nightly.py\", line 791, in make_cards\n    sys.exit(1)\n  File \"\/usr\/lib\/python3.5\/multiprocessing\/pool.py\", line 260, in map\n    return self._map_async(func, iterable, mapstar, chunksize).get()\n  File \"\/usr\/lib\/python3.5\/multiprocessing\/pool.py\", line 608, in get\n    raise self._value\npsycopg2.OperationalError: terminating connection due to administrator command\nserver closed the connection unexpectedly\n\tThis probably means the server terminated abnormally\n\tbefore or while processing the request.\n\n\n```",
        "ts": "1558292014.015000",
        "username": "edhrecbot",
        "icons": {
            "emoji": ":robot_face:",
            "image_64": "https:\/\/a.slack-edge.com\/37d58\/img\/emoji_2017_12_06\/apple\/1f916.png"
        },
        "bot_id": "B2867AJ5C"
    },
    {
        "type": "message",
        "subtype": "bot_message",
        "text": "```2019-05-19 18:55:10,776 ERROR Dynamic too many open files - restarting\n2019-05-19 18:55:10,904 ERROR Dynamic too many open files - restarting\n```",
        "ts": "1558292014.015100",
        "username": "edhrecbot",
        "icons": {
            "emoji": ":robot_face:",
            "image_64": "https:\/\/a.slack-edge.com\/37d58\/img\/emoji_2017_12_06\/apple\/1f916.png"
        },
        "bot_id": "B2867AJ5C"
    },
    {
        "type": "message",
        "subtype": "bot_message",
        "text": "```[19\/May\/2019:18:55:10] HTTP \nTraceback (most recent call last):\n  File \"\/usr\/local\/lib\/python3.5\/dist-packages\/cherrypy\/_cprequest.py\", line 630, in respond\n    self._do_respond(path_info)\n  File \"\/usr\/local\/lib\/python3.5\/dist-packages\/cherrypy\/_cprequest.py\", line 689, in _do_respond\n    response.body = self.handler()\n  File \"\/usr\/local\/lib\/python3.5\/dist-packages\/cherrypy\/lib\/encoding.py\", line 221, in __call__\n    self.body = self.oldhandler(*args, **kwargs)\n  File \"\/usr\/local\/lib\/python3.5\/dist-packages\/cherrypy\/_cpdispatch.py\", line 54, in __call__\n    return self.callable(*self.args, **self.kwargs)\n  File \"\/home\/ubuntu\/edhrec\/web\/dynamic.py\", line 61, in index\n    commander = cards.url_to_name(kwargs['cmdr'])\n  File \"\/home\/ubuntu\/edhrec\/core\/cards.py\", line 580, in url_to_name\n    return cache.get('cards\/urls\/' + url)\n  File \"\/home\/ubuntu\/edhrec\/core\/cache.py\", line 47, in get\n    with _getcursor() as cur:\n  File \"\/usr\/lib\/python3.5\/contextlib.py\", line 59, in __enter__\n    return next(self.gen)\n  File \"\/home\/ubuntu\/edhrec\/core\/cache.py\", line 20, in _getcursor\n    pool = psycopg2.pool.ThreadedConnectionPool(1, 10, user='postgres')\n  File \"\/usr\/local\/lib\/python3.5\/dist-packages\/psycopg2\/pool.py\", line 161, in __init__\n    self, minconn, maxconn, *args, **kwargs)\n  File \"\/usr\/local\/lib\/python3.5\/dist-packages\/psycopg2\/pool.py\", line 58, in __init__\n    self._connect()\n  File \"\/usr\/local\/lib\/python3.5\/dist-packages\/psycopg2\/pool.py\", line 62, in _connect\n    conn = psycopg2.connect(*self._args, **self._kwargs)\n  File \"\/usr\/local\/lib\/python3.5\/dist-packages\/psycopg2\/__init__.py\", line 130, in connect\n    conn = _connect(dsn, connection_factory=connection_factory, **kwasync)\npsycopg2.OperationalError: could not connect to server: No such file or directory\n\tIs the server running locally and accepting\n\tconnections on Unix domain socket \"\/var\/run\/postgresql\/.s.PGSQL.5432\"?\n\n```",
        "ts": "1558292014.015200",
        "username": "edhrecbot",
        "icons": {
            "emoji": ":robot_face:",
            "image_64": "https:\/\/a.slack-edge.com\/37d58\/img\/emoji_2017_12_06\/apple\/1f916.png"
        },
        "bot_id": "B2867AJ5C"
    },
    {
        "client_msg_id": "19bb20d8-753d-4fdc-b3f1-58104e0911a8",
        "type": "message",
        "text": "just restarting postgres",
        "user": "U28TLDP0R",
        "ts": "1558292057.015400",
        "team": "T286HM2F3",
        "user_team": "T286HM2F3",
        "source_team": "T286HM2F3",
        "user_profile": {
            "avatar_hash": "2a61603e280e",
            "image_72": "https:\/\/avatars.slack-edge.com\/2016-11-16\/104915990673_2a61603e280ecee0ab38_72.jpg",
            "first_name": "David",
            "real_name": "David Keatts",
            "display_name": "keattz",
            "team": "T286HM2F3",
            "name": "keattz",
            "is_restricted": false,
            "is_ultra_restricted": false
        }
    },
    {
        "type": "message",
        "subtype": "bot_message",
        "text": "```2019-05-19 19:14:44,560 CRITICAL Uncaught exception\nTraceback (most recent call last):\n  File \"&lt;stdin&gt;\", line 1, in &lt;module&gt;\nTypeError: an integer is required (got type str)\n```",
        "ts": "1558293188.015500",
        "username": "edhrecbot",
        "icons": {
            "emoji": ":robot_face:",
            "image_64": "https:\/\/a.slack-edge.com\/37d58\/img\/emoji_2017_12_06\/apple\/1f916.png"
        },
        "bot_id": "B2867AJ5C"
    },
    {
        "type": "message",
        "subtype": "bot_message",
        "text": "```2019-05-19 19:17:42,987 CRITICAL Uncaught exception\nTraceback (most recent call last):\n  File \"&lt;stdin&gt;\", line 1, in &lt;module&gt;\nNameError: name 'mydict' is not defined\n```",
        "ts": "1558293367.015600",
        "username": "edhrecbot",
        "icons": {
            "emoji": ":robot_face:",
            "image_64": "https:\/\/a.slack-edge.com\/37d58\/img\/emoji_2017_12_06\/apple\/1f916.png"
        },
        "bot_id": "B2867AJ5C"
    },
    {
        "type": "message",
        "subtype": "bot_message",
        "text": "```2019-05-19 19:18:37,756 CRITICAL Uncaught exception\nTraceback (most recent call last):\n  File \"&lt;stdin&gt;\", line 1, in &lt;module&gt;\nTypeError: an integer is required (got type str)\n```",
        "ts": "1558293421.015700",
        "username": "edhrecbot",
        "icons": {
            "emoji": ":robot_face:",
            "image_64": "https:\/\/a.slack-edge.com\/37d58\/img\/emoji_2017_12_06\/apple\/1f916.png"
        },
        "bot_id": "B2867AJ5C"
    },
    {
        "type": "message",
        "subtype": "bot_message",
        "text": "```2019-05-19 19:18:56,061 CRITICAL Uncaught exception\nTraceback (most recent call last):\n  File \"&lt;stdin&gt;\", line 1, in &lt;module&gt;\n  File \"\/usr\/lib\/python3.5\/_strptime.py\", line 510, in _strptime_datetime\n    tt, fraction = _strptime(data_string, format)\n  File \"\/usr\/lib\/python3.5\/_strptime.py\", line 343, in _strptime\n    (data_string, format))\nValueError: time data '%Y-%m-%d' does not match format '2017-05-17'\n```",
        "ts": "1558293440.015800",
        "username": "edhrecbot",
        "icons": {
            "emoji": ":robot_face:",
            "image_64": "https:\/\/a.slack-edge.com\/37d58\/img\/emoji_2017_12_06\/apple\/1f916.png"
        },
        "bot_id": "B2867AJ5C"
    },
    {
        "type": "message",
        "subtype": "bot_message",
        "text": "```2019-05-19 19:19:36,357 CRITICAL Uncaught exception\nTraceback (most recent call last):\n  File \"&lt;stdin&gt;\", line 1, in &lt;module&gt;\n  File \"\/usr\/lib\/python3.5\/_strptime.py\", line 510, in _strptime_datetime\n    tt, fraction = _strptime(data_string, format)\n  File \"\/usr\/lib\/python3.5\/_strptime.py\", line 343, in _strptime\n    (data_string, format))\nValueError: time data '%Y-%M-%D' does not match format '2017-05-17'\n```",
        "ts": "1558293480.015900",
        "username": "edhrecbot",
        "icons": {
            "emoji": ":robot_face:",
            "image_64": "https:\/\/a.slack-edge.com\/37d58\/img\/emoji_2017_12_06\/apple\/1f916.png"
        },
        "bot_id": "B2867AJ5C"
    },
    {
        "type": "message",
        "subtype": "bot_message",
        "text": "```2019-05-19 19:20:05,563 CRITICAL Uncaught exception\nTraceback (most recent call last):\n  File \"&lt;stdin&gt;\", line 1, in &lt;module&gt;\n  File \"\/usr\/lib\/python3.5\/_strptime.py\", line 510, in _strptime_datetime\n    tt, fraction = _strptime(data_string, format)\n  File \"\/usr\/lib\/python3.5\/_strptime.py\", line 335, in _strptime\n    (bad_directive, format)) from None\nValueError: 'D' is a bad directive in format '%Y-%M-%D'\n```",
        "ts": "1558293509.016000",
        "username": "edhrecbot",
        "icons": {
            "emoji": ":robot_face:",
            "image_64": "https:\/\/a.slack-edge.com\/37d58\/img\/emoji_2017_12_06\/apple\/1f916.png"
        },
        "bot_id": "B2867AJ5C"
    },
    {
        "type": "message",
        "subtype": "bot_message",
        "text": "```2019-05-19 19:21:24,659 CRITICAL Uncaught exception\n  File \"&lt;stdin&gt;\", line 1\n    for i in range(latest - earliest)\n                                    ^\nSyntaxError: invalid syntax\n```",
        "ts": "1558293588.016100",
        "username": "edhrecbot",
        "icons": {
            "emoji": ":robot_face:",
            "image_64": "https:\/\/a.slack-edge.com\/37d58\/img\/emoji_2017_12_06\/apple\/1f916.png"
        },
        "bot_id": "B2867AJ5C"
    },
    {
        "type": "message",
        "subtype": "bot_message",
        "text": "```2019-05-19 19:21:30,812 CRITICAL Uncaught exception\nTraceback (most recent call last):\n  File \"&lt;stdin&gt;\", line 1, in &lt;module&gt;\nTypeError: 'datetime.timedelta' object cannot be interpreted as an integer\n```",
        "ts": "1558293594.016200",
        "username": "edhrecbot",
        "icons": {
            "emoji": ":robot_face:",
            "image_64": "https:\/\/a.slack-edge.com\/37d58\/img\/emoji_2017_12_06\/apple\/1f916.png"
        },
        "bot_id": "B2867AJ5C"
    },
    {
        "type": "message",
        "subtype": "bot_message",
        "text": "```2019-05-19 19:22:45,331 CRITICAL Uncaught exception\n  File \"&lt;stdin&gt;\", line 2\n    \n    ^\nIndentationError: expected an indented block\n```",
        "ts": "1558293669.016300",
        "username": "edhrecbot",
        "icons": {
            "emoji": ":robot_face:",
            "image_64": "https:\/\/a.slack-edge.com\/37d58\/img\/emoji_2017_12_06\/apple\/1f916.png"
        },
        "bot_id": "B2867AJ5C"
    },
    {
        "type": "message",
        "subtype": "bot_message",
        "text": "```2019-05-19 19:23:48,061 CRITICAL Uncaught exception\n  File \"&lt;stdin&gt;\", line 1\n    [str(earliest) + timedelta(days=i)) for i in range(days)]\n                                      ^\nSyntaxError: invalid syntax\n```",
        "ts": "1558293732.016400",
        "username": "edhrecbot",
        "icons": {
            "emoji": ":robot_face:",
            "image_64": "https:\/\/a.slack-edge.com\/37d58\/img\/emoji_2017_12_06\/apple\/1f916.png"
        },
        "bot_id": "B2867AJ5C"
    },
    {
        "type": "message",
        "subtype": "bot_message",
        "text": "```2019-05-19 19:23:54,069 CRITICAL Uncaught exception\nTraceback (most recent call last):\n  File \"&lt;stdin&gt;\", line 1, in &lt;module&gt;\n  File \"&lt;stdin&gt;\", line 1, in &lt;listcomp&gt;\nTypeError: Can't convert 'datetime.timedelta' object to str implicitly\n```",
        "ts": "1558293738.016500",
        "username": "edhrecbot",
        "icons": {
            "emoji": ":robot_face:",
            "image_64": "https:\/\/a.slack-edge.com\/37d58\/img\/emoji_2017_12_06\/apple\/1f916.png"
        },
        "bot_id": "B2867AJ5C"
    },
    {
        "type": "message",
        "subtype": "bot_message",
        "text": "```2019-05-19 19:33:25,578 CRITICAL Uncaught exception\nTraceback (most recent call last):\n  File \"&lt;stdin&gt;\", line 1, in &lt;module&gt;\n  File \"\/home\/ubuntu\/edhrec\/core\/database.py\", line 856, in get_date_table\n    earliest = datetime.strptime(sorted(mydict)[0], '%Y-%m-%d')\nNameError: name 'datetime' is not defined\n```",
        "ts": "1558294309.016600",
        "username": "edhrecbot",
        "icons": {
            "emoji": ":robot_face:",
            "image_64": "https:\/\/a.slack-edge.com\/37d58\/img\/emoji_2017_12_06\/apple\/1f916.png"
        },
        "bot_id": "B2867AJ5C"
    },
    {
        "type": "message",
        "subtype": "bot_message",
        "text": "```2019-05-19 19:34:06,520 CRITICAL Uncaught exception\nTraceback (most recent call last):\n  File \"\/home\/ubuntu\/edhrec\/core\/database.py\", line 866, in get_date_table\n    for card in mydict[date]:\nKeyError: '2019-03-21'\n\nDuring handling of the above exception, another exception occurred:\n\nTraceback (most recent call last):\n  File \"&lt;stdin&gt;\", line 1, in &lt;module&gt;\n  File \"\/home\/ubuntu\/edhrec\/core\/database.py\", line 871, in get_date_table\n    mydict[date] = mydict[date_range[i+1]]\nKeyError: '2019-03-20'\n```",
        "ts": "1558294350.016700",
        "username": "edhrecbot",
        "icons": {
            "emoji": ":robot_face:",
            "image_64": "https:\/\/a.slack-edge.com\/37d58\/img\/emoji_2017_12_06\/apple\/1f916.png"
        },
        "bot_id": "B2867AJ5C"
    },
    {
        "type": "message",
        "subtype": "bot_message",
        "text": "```2019-05-19 19:39:05,191 CRITICAL Uncaught exception\nTraceback (most recent call last):\n  File \"\/home\/ubuntu\/edhrec\/core\/database.py\", line 873, in get_date_table\n    card_counter[card] += date_table[date][card]\nKeyError: 'Silent Submarine'\n\nDuring handling of the above exception, another exception occurred:\n\nTraceback (most recent call last):\n  File \"&lt;stdin&gt;\", line 1, in &lt;module&gt;\n  File \"\/home\/ubuntu\/edhrec\/core\/database.py\", line 877, in get_date_table\n    date_table[date] = mydict[date_range[i-1]]\nNameError: name 'mydict' is not defined\n```",
        "ts": "1558294649.016800",
        "username": "edhrecbot",
        "icons": {
            "emoji": ":robot_face:",
            "image_64": "https:\/\/a.slack-edge.com\/37d58\/img\/emoji_2017_12_06\/apple\/1f916.png"
        },
        "bot_id": "B2867AJ5C"
    },
    {
        "type": "message",
        "subtype": "bot_message",
        "text": "```2019-05-19 19:51:16,995 CRITICAL Uncaught exception\nTraceback (most recent call last):\n  File \"&lt;stdin&gt;\", line 1, in &lt;module&gt;\n  File \"\/home\/ubuntu\/edhrec\/core\/database.py\", line 861, in get_date_table\n    card_counter = {name: 0 for name in cards.get_all()}\nUnboundLocalError: local variable 'cards' referenced before assignment\n```",
        "ts": "1558295381.016900",
        "username": "edhrecbot",
        "icons": {
            "emoji": ":robot_face:",
            "image_64": "https:\/\/a.slack-edge.com\/37d58\/img\/emoji_2017_12_06\/apple\/1f916.png"
        },
        "bot_id": "B2867AJ5C"
    },
    {
        "type": "message",
        "subtype": "bot_message",
        "text": "```2019-05-19 19:54:56,014 CRITICAL Uncaught exception\nTraceback (most recent call last):\n  File \"&lt;stdin&gt;\", line 1, in &lt;module&gt;\n  File \"\/home\/ubuntu\/edhrec\/core\/database.py\", line 882, in get_count_by_date\n    return cache.get('date_table\/' + date)[name]\n  File \"\/home\/ubuntu\/edhrec\/core\/cache.py\", line 67, in get\n    raise NotInCache(key)\nedhrec.core.cache.NotInCache: date_table\/2019-06-05\n```",
        "ts": "1558295600.017000",
        "username": "edhrecbot",
        "icons": {
            "emoji": ":robot_face:",
            "image_64": "https:\/\/a.slack-edge.com\/37d58\/img\/emoji_2017_12_06\/apple\/1f916.png"
        },
        "bot_id": "B2867AJ5C"
    },
    {
        "type": "message",
        "subtype": "bot_message",
        "text": "```2019-05-19 19:55:32,775 CRITICAL Uncaught exception\nTraceback (most recent call last):\n  File \"\/home\/ubuntu\/edhrec\/core\/database.py\", line 882, in get_count_by_date\n    return cache.get('date_table\/' + date)[name]\n  File \"\/home\/ubuntu\/edhrec\/core\/cache.py\", line 67, in get\n    raise NotInCache(key)\nedhrec.core.cache.NotInCache: date_table\/2019-06-05\n\nDuring handling of the above exception, another exception occurred:\n\nTraceback (most recent call last):\n  File \"&lt;stdin&gt;\", line 1, in &lt;module&gt;\n  File \"\/home\/ubuntu\/edhrec\/core\/database.py\", line 884, in get_count_by_date\n    if date.strptime('%Y%-m-%d').year == datetime.now().year:\nAttributeError: 'str' object has no attribute 'strptime'\n```",
        "ts": "1558295636.017100",
        "username": "edhrecbot",
        "icons": {
            "emoji": ":robot_face:",
            "image_64": "https:\/\/a.slack-edge.com\/37d58\/img\/emoji_2017_12_06\/apple\/1f916.png"
        },
        "bot_id": "B2867AJ5C"
    },
    {
        "type": "message",
        "subtype": "bot_message",
        "text": "```2019-05-19 19:56:20,308 CRITICAL Uncaught exception\nTraceback (most recent call last):\n  File \"\/home\/ubuntu\/edhrec\/core\/database.py\", line 882, in get_count_by_date\n    return cache.get('date_table\/' + carddate)[name]\n  File \"\/home\/ubuntu\/edhrec\/core\/cache.py\", line 67, in get\n    raise NotInCache(key)\nedhrec.core.cache.NotInCache: date_table\/2019-06-05\n\nDuring handling of the above exception, another exception occurred:\n\nTraceback (most recent call last):\n  File \"&lt;stdin&gt;\", line 1, in &lt;module&gt;\n  File \"\/home\/ubuntu\/edhrec\/core\/database.py\", line 884, in get_count_by_date\n    if date.strptime(carddate, '%Y%-m-%d').year == datetime.now().year:\nAttributeError: type object 'datetime.date' has no attribute 'strptime'\n```",
        "ts": "1558295684.017200",
        "username": "edhrecbot",
        "icons": {
            "emoji": ":robot_face:",
            "image_64": "https:\/\/a.slack-edge.com\/37d58\/img\/emoji_2017_12_06\/apple\/1f916.png"
        },
        "bot_id": "B2867AJ5C"
    },
    {
        "type": "message",
        "subtype": "bot_message",
        "text": "```2019-05-19 19:56:38,810 CRITICAL Uncaught exception\nTraceback (most recent call last):\n  File \"&lt;stdin&gt;\", line 1, in &lt;module&gt;\n  File \"\/home\/ubuntu\/edhrec\/core\/database.py\", line 884, in get_count_by_date\n    if datetime.strptime(carddate, '%Y%-m-%d').year == datetime.now().year:\n  File \"\/usr\/lib\/python3.5\/_strptime.py\", line 510, in _strptime_datetime\n    tt, fraction = _strptime(data_string, format)\n  File \"\/usr\/lib\/python3.5\/_strptime.py\", line 335, in _strptime\n    (bad_directive, format)) from None\nValueError: '-' is a bad directive in format '%Y%-m-%d'\n```",
        "ts": "1558295702.017300",
        "username": "edhrecbot",
        "icons": {
            "emoji": ":robot_face:",
            "image_64": "https:\/\/a.slack-edge.com\/37d58\/img\/emoji_2017_12_06\/apple\/1f916.png"
        },
        "bot_id": "B2867AJ5C"
    },
    {
        "type": "message",
        "subtype": "bot_message",
        "text": "```2019-05-19 20:01:03,837 CRITICAL Uncaught exception\nTraceback (most recent call last):\n  File \"\/home\/ubuntu\/edhrec\/core\/database.py\", line 882, in get_count_by_date\n    return cache.get('date_table\/' + carddate)[name]\n  File \"\/home\/ubuntu\/edhrec\/core\/cache.py\", line 67, in get\n    raise NotInCache(key)\nedhrec.core.cache.NotInCache: date_table\/2017-08-41\n\nDuring handling of the above exception, another exception occurred:\n\nTraceback (most recent call last):\n  File \"&lt;stdin&gt;\", line 1, in &lt;module&gt;\n  File \"\/home\/ubuntu\/edhrec\/core\/database.py\", line 884, in get_count_by_date\n    if datetime.strptime(carddate, '%Y-%m-%d').year &gt;= datetime.now().year:\n  File \"\/usr\/lib\/python3.5\/_strptime.py\", line 510, in _strptime_datetime\n    tt, fraction = _strptime(data_string, format)\n  File \"\/usr\/lib\/python3.5\/_strptime.py\", line 346, in _strptime\n    data_string[found.end():])\nValueError: unconverted data remains: 1\n```",
        "ts": "1558295967.017400",
        "username": "edhrecbot",
        "icons": {
            "emoji": ":robot_face:",
            "image_64": "https:\/\/a.slack-edge.com\/37d58\/img\/emoji_2017_12_06\/apple\/1f916.png"
        },
        "bot_id": "B2867AJ5C"
    },
    {
        "type": "message",
        "subtype": "bot_message",
        "text": "```2019-05-19 20:02:02,325 CRITICAL Uncaught exception\nTraceback (most recent call last):\n  File \"&lt;stdin&gt;\", line 1, in &lt;module&gt;\nNameError: name 'datetime' is not defined\n```",
        "ts": "1558296026.017500",
        "username": "edhrecbot",
        "icons": {
            "emoji": ":robot_face:",
            "image_64": "https:\/\/a.slack-edge.com\/37d58\/img\/emoji_2017_12_06\/apple\/1f916.png"
        },
        "bot_id": "B2867AJ5C"
    },
    {
        "type": "message",
        "subtype": "bot_message",
        "text": "```2019-05-19 20:02:09,143 CRITICAL Uncaught exception\nTraceback (most recent call last):\n  File \"&lt;stdin&gt;\", line 1, in &lt;module&gt;\n  File \"\/usr\/lib\/python3.5\/_strptime.py\", line 510, in _strptime_datetime\n    tt, fraction = _strptime(data_string, format)\n  File \"\/usr\/lib\/python3.5\/_strptime.py\", line 343, in _strptime\n    (data_string, format))\nValueError: time data '2020-40-40' does not match format '%Y-%m-%d'\n```",
        "ts": "1558296033.017600",
        "username": "edhrecbot",
        "icons": {
            "emoji": ":robot_face:",
            "image_64": "https:\/\/a.slack-edge.com\/37d58\/img\/emoji_2017_12_06\/apple\/1f916.png"
        },
        "bot_id": "B2867AJ5C"
    },
    {
        "type": "message",
        "subtype": "bot_message",
        "text": "```2019-05-19 20:03:29,104 CRITICAL Uncaught exception\nTraceback (most recent call last):\n  File \"&lt;stdin&gt;\", line 1, in &lt;module&gt;\nTypeError: an integer is required (got type datetime.datetime)\n```",
        "ts": "1558296113.017700",
        "username": "edhrecbot",
        "icons": {
            "emoji": ":robot_face:",
            "image_64": "https:\/\/a.slack-edge.com\/37d58\/img\/emoji_2017_12_06\/apple\/1f916.png"
        },
        "bot_id": "B2867AJ5C"
    },
    {
        "type": "message",
        "subtype": "bot_message",
        "text": "```2019-05-19 20:05:07,442 CRITICAL Uncaught exception\nTraceback (most recent call last):\n  File \"&lt;stdin&gt;\", line 1, in &lt;module&gt;\n  File \"\/home\/ubuntu\/edhrec\/core\/database.py\", line 884, in get_count_by_date\n    carddate = datetime.strptime(carddate, '%Y-%m-%d').date()\n  File \"\/usr\/lib\/python3.5\/_strptime.py\", line 510, in _strptime_datetime\n    tt, fraction = _strptime(data_string, format)\n  File \"\/usr\/lib\/python3.5\/_strptime.py\", line 343, in _strptime\n    (data_string, format))\nValueError: time data 'Thraximundar' does not match format '%Y-%m-%d'\n```",
        "ts": "1558296211.017800",
        "username": "edhrecbot",
        "icons": {
            "emoji": ":robot_face:",
            "image_64": "https:\/\/a.slack-edge.com\/37d58\/img\/emoji_2017_12_06\/apple\/1f916.png"
        },
        "bot_id": "B2867AJ5C"
    },
    {
        "type": "message",
        "subtype": "bot_message",
        "text": "```2019-05-19 20:05:14,916 CRITICAL Uncaught exception\nTraceback (most recent call last):\n  File \"&lt;stdin&gt;\", line 1, in &lt;module&gt;\n  File \"\/home\/ubuntu\/edhrec\/core\/database.py\", line 887, in get_count_by_date\n    return cache.get('date_table\/' + carddate)[name]\nTypeError: Can't convert 'datetime.date' object to str implicitly\n```",
        "ts": "1558296218.017900",
        "username": "edhrecbot",
        "icons": {
            "emoji": ":robot_face:",
            "image_64": "https:\/\/a.slack-edge.com\/37d58\/img\/emoji_2017_12_06\/apple\/1f916.png"
        },
        "bot_id": "B2867AJ5C"
    },
    {
        "type": "message",
        "subtype": "bot_message",
        "text": "```2019-05-19 20:21:23,825 CRITICAL Uncaught exception\nTraceback (most recent call last):\n  File \"&lt;string&gt;\", line 1, in &lt;module&gt;\n  File \"\/home\/ubuntu\/edhrec\/web\/nightly.py\", line 25, in &lt;module&gt;\n    import edhrec.core.database as database\n  File \"\/home\/ubuntu\/edhrec\/core\/database.py\", line 2047\n    out_card['UsageScore'] = out)card['Popularity'] - float(usage_score['usage'])\n                                ^\nSyntaxError: invalid syntax\n```",
        "ts": "1558297187.018000",
        "username": "edhrecbot",
        "icons": {
            "emoji": ":robot_face:",
            "image_64": "https:\/\/a.slack-edge.com\/37d58\/img\/emoji_2017_12_06\/apple\/1f916.png"
        },
        "bot_id": "B2867AJ5C"
    },
    {
        "type": "message",
        "subtype": "bot_message",
        "text": "```2019-05-19 20:29:13,712 INFO archidekt.py took 0:27:19.013490\n```",
        "ts": "1558297657.018100",
        "username": "edhrecbot",
        "icons": {
            "emoji": ":robot_face:",
            "image_64": "https:\/\/a.slack-edge.com\/37d58\/img\/emoji_2017_12_06\/apple\/1f916.png"
        },
        "bot_id": "B2867AJ5C"
    },
    {
        "type": "message",
        "subtype": "bot_message",
        "text": "```2019-05-19 20:29:42,823 CRITICAL Uncaught exception\nTraceback (most recent call last):\n  File \"\/usr\/lib\/python3.5\/code.py\", line 91, in runcode\n    exec(code, self.locals)\n  File \"&lt;console&gt;\", line 1, in &lt;module&gt;\nNameError: name 'database' is not defined\n```",
        "ts": "1558297686.018200",
        "username": "edhrecbot",
        "icons": {
            "emoji": ":robot_face:",
            "image_64": "https:\/\/a.slack-edge.com\/37d58\/img\/emoji_2017_12_06\/apple\/1f916.png"
        },
        "bot_id": "B2867AJ5C"
    },
    {
        "type": "message",
        "subtype": "bot_message",
        "text": "```2019-05-19 21:01:28,469 CRITICAL Uncaught exception\nTraceback (most recent call last):\n  File \"&lt;stdin&gt;\", line 1, in &lt;module&gt;\nAttributeError: 'list' object has no attribute 'keys'\n```",
        "ts": "1558299592.018300",
        "username": "edhrecbot",
        "icons": {
            "emoji": ":robot_face:",
            "image_64": "https:\/\/a.slack-edge.com\/37d58\/img\/emoji_2017_12_06\/apple\/1f916.png"
        },
        "bot_id": "B2867AJ5C"
    },
    {
        "type": "message",
        "subtype": "bot_message",
        "text": "```2019-05-19 21:01:52,752 CRITICAL Uncaught exception\nTraceback (most recent call last):\n  File \"&lt;stdin&gt;\", line 1, in &lt;module&gt;\nAttributeError: 'list' object has no attribute 'keys'\n```",
        "ts": "1558299616.018400",
        "username": "edhrecbot",
        "icons": {
            "emoji": ":robot_face:",
            "image_64": "https:\/\/a.slack-edge.com\/37d58\/img\/emoji_2017_12_06\/apple\/1f916.png"
        },
        "bot_id": "B2867AJ5C"
    },
    {
        "type": "message",
        "subtype": "bot_message",
        "text": "```2019-05-19 21:02:40,864 CRITICAL Uncaught exception\nTraceback (most recent call last):\n  File \"&lt;stdin&gt;\", line 1, in &lt;module&gt;\n  File \"&lt;stdin&gt;\", line 1, in &lt;listcomp&gt;\nTypeError: list indices must be integers or slices, not str\n```",
        "ts": "1558299664.018500",
        "username": "edhrecbot",
        "icons": {
            "emoji": ":robot_face:",
            "image_64": "https:\/\/a.slack-edge.com\/37d58\/img\/emoji_2017_12_06\/apple\/1f916.png"
        },
        "bot_id": "B2867AJ5C"
    },
    {
        "type": "message",
        "subtype": "bot_message",
        "text": "```2019-05-19 21:02:52,602 CRITICAL Uncaught exception\nTraceback (most recent call last):\n  File \"&lt;stdin&gt;\", line 1, in &lt;module&gt;\nAttributeError: 'list' object has no attribute 'values'\n```",
        "ts": "1558299676.018600",
        "username": "edhrecbot",
        "icons": {
            "emoji": ":robot_face:",
            "image_64": "https:\/\/a.slack-edge.com\/37d58\/img\/emoji_2017_12_06\/apple\/1f916.png"
        },
        "bot_id": "B2867AJ5C"
    },
    {
        "type": "message",
        "subtype": "bot_message",
        "text": "```2019-05-19 21:08:43,500 CRITICAL Uncaught exception\nTraceback (most recent call last):\n  File \"&lt;stdin&gt;\", line 1, in &lt;module&gt;\nKeyError: 0\n```",
        "ts": "1558300027.018700",
        "username": "edhrecbot",
        "icons": {
            "emoji": ":robot_face:",
            "image_64": "https:\/\/a.slack-edge.com\/37d58\/img\/emoji_2017_12_06\/apple\/1f916.png"
        },
        "bot_id": "B2867AJ5C"
    },
    {
        "type": "message",
        "subtype": "bot_message",
        "text": "```2019-05-19 21:09:04,529 CRITICAL Uncaught exception\n  File \"&lt;stdin&gt;\", line 1\n    t = database.get_date_tables9)\n                                 ^\nSyntaxError: invalid syntax\n```",
        "ts": "1558300048.018800",
        "username": "edhrecbot",
        "icons": {
            "emoji": ":robot_face:",
            "image_64": "https:\/\/a.slack-edge.com\/37d58\/img\/emoji_2017_12_06\/apple\/1f916.png"
        },
        "bot_id": "B2867AJ5C"
    },
    {
        "type": "message",
        "subtype": "bot_message",
        "text": "```2019-05-19 21:10:09,658 CRITICAL Uncaught exception\nTraceback (most recent call last):\n  File \"&lt;stdin&gt;\", line 1, in &lt;module&gt;\nKeyError: 'Thraximundar'\n```",
        "ts": "1558300113.018900",
        "username": "edhrecbot",
        "icons": {
            "emoji": ":robot_face:",
            "image_64": "https:\/\/a.slack-edge.com\/37d58\/img\/emoji_2017_12_06\/apple\/1f916.png"
        },
        "bot_id": "B2867AJ5C"
    },
    {
        "type": "message",
        "subtype": "bot_message",
        "text": "```2019-05-19 21:14:43,019 CRITICAL Uncaught exception\nTraceback (most recent call last):\n  File \"&lt;stdin&gt;\", line 1, in &lt;module&gt;\n  File \"\/home\/ubuntu\/edhrec\/core\/database.py\", line 886, in get_date_tables\n    commander_counter[card] += commanders_table[date][commander]\nKeyError: \"Yahenni's Expertise\"\n```",
        "ts": "1558300387.019000",
        "username": "edhrecbot",
        "icons": {
            "emoji": ":robot_face:",
            "image_64": "https:\/\/a.slack-edge.com\/37d58\/img\/emoji_2017_12_06\/apple\/1f916.png"
        },
        "bot_id": "B2867AJ5C"
    },
    {
        "type": "message",
        "subtype": "bot_message",
        "text": "```2019-05-19 21:18:36,164 CRITICAL Uncaught exception\nTraceback (most recent call last):\n  File \"&lt;stdin&gt;\", line 1, in &lt;module&gt;\n  File \"\/home\/ubuntu\/edhrec\/core\/database.py\", line 890, in get_date_tables\n    card_counter[card] += cards_table[date][card]\nKeyError: 'Silent Submarine'\n```",
        "ts": "1558300620.019100",
        "username": "edhrecbot",
        "icons": {
            "emoji": ":robot_face:",
            "image_64": "https:\/\/a.slack-edge.com\/37d58\/img\/emoji_2017_12_06\/apple\/1f916.png"
        },
        "bot_id": "B2867AJ5C"
    },
    {
        "type": "message",
        "subtype": "bot_message",
        "text": "```2019-05-19 21:21:51,200 CRITICAL Uncaught exception\nTraceback (most recent call last):\n  File \"&lt;stdin&gt;\", line 1, in &lt;module&gt;\n  File \"\/home\/ubuntu\/edhrec\/core\/database.py\", line 886, in get_date_tables\n    commander_counter[commander] += commanders_table[date][commander]\nKeyError: 'Akiri, Line-SlingerAkiri, Line-Slinger'\n```",
        "ts": "1558300815.019200",
        "username": "edhrecbot",
        "icons": {
            "emoji": ":robot_face:",
            "image_64": "https:\/\/a.slack-edge.com\/37d58\/img\/emoji_2017_12_06\/apple\/1f916.png"
        },
        "bot_id": "B2867AJ5C"
    },
    {
        "type": "message",
        "subtype": "bot_message",
        "text": "```2019-05-19 21:24:52,931 CRITICAL Uncaught exception\nTraceback (most recent call last):\n  File \"&lt;stdin&gt;\", line 1, in &lt;module&gt;\nKeyError: 'commandres'\n```",
        "ts": "1558300996.019300",
        "username": "edhrecbot",
        "icons": {
            "emoji": ":robot_face:",
            "image_64": "https:\/\/a.slack-edge.com\/37d58\/img\/emoji_2017_12_06\/apple\/1f916.png"
        },
        "bot_id": "B2867AJ5C"
    },
    {
        "type": "message",
        "subtype": "bot_message",
        "text": "```2019-05-19 21:26:12,975 CRITICAL Uncaught exception\nTraceback (most recent call last):\n  File \"\/home\/ubuntu\/edhrec\/core\/database.py\", line 918, in get_count_by_date\n    return cache.get('{}\/{}'.format(table, carddate))[name]\n  File \"\/home\/ubuntu\/edhrec\/core\/cache.py\", line 67, in get\n    raise NotInCache(key)\nedhrec.core.cache.NotInCache: commanders_table\/2006-02-03\n\nDuring handling of the above exception, another exception occurred:\n\nTraceback (most recent call last):\n  File \"&lt;string&gt;\", line 1, in &lt;module&gt;\n  File \"\/home\/ubuntu\/edhrec\/web\/nightly.py\", line 510, in make_card\n    data = origin.getcards(card=name)\n  File \"\/home\/ubuntu\/edhrec\/web\/origin.py\", line 67, in getcards\n    data = database.tally(decks, card=card)\n  File \"\/home\/ubuntu\/edhrec\/core\/database.py\", line 2183, in tally\n    num_decks = get_count_by_date(name, cards.get(card)['released_at'], commander=True)\n  File \"\/home\/ubuntu\/edhrec\/core\/database.py\", line 923, in get_count_by_date\n    return cache.get(table + '\/earliest')[name]\nKeyError: 'Devastation Tide'\n```",
        "ts": "1558301076.019400",
        "username": "edhrecbot",
        "icons": {
            "emoji": ":robot_face:",
            "image_64": "https:\/\/a.slack-edge.com\/37d58\/img\/emoji_2017_12_06\/apple\/1f916.png"
        },
        "bot_id": "B2867AJ5C"
    },
    {
        "type": "message",
        "subtype": "bot_message",
        "text": "```2019-05-19 21:47:35,300 CRITICAL Uncaught exception\nTraceback (most recent call last):\n  File \"\/home\/ubuntu\/edhrec\/core\/database.py\", line 918, in get_count_by_date\n    return cache.get('{}\/{}'.format(table, carddate))[name]\n  File \"\/home\/ubuntu\/edhrec\/core\/cache.py\", line 67, in get\n    raise NotInCache(key)\nedhrec.core.cache.NotInCache: cards_table\/2008-05-02\n\nDuring handling of the above exception, another exception occurred:\n\nTraceback (most recent call last):\n  File \"&lt;string&gt;\", line 1, in &lt;module&gt;\n  File \"\/home\/ubuntu\/edhrec\/web\/nightly.py\", line 884, in make_partner_commanders\n    make_commander(commander)\n  File \"\/home\/ubuntu\/edhrec\/web\/nightly.py\", line 582, in make_commander\n    data = origin.getcommanders(cardses=name, checktribe=checktribe, tribe=tribe, outof=outof)\n  File \"\/home\/ubuntu\/edhrec\/web\/origin.py\", line 432, in getcommanders\n    data = database.tally(decks, card=card)\n  File \"\/home\/ubuntu\/edhrec\/core\/database.py\", line 2036, in tally\n    num_decks = get_count_by_date(card, card_age)\n  File \"\/home\/ubuntu\/edhrec\/core\/database.py\", line 923, in get_count_by_date\n    return cache.get(table + '\/earliest')[name]\nKeyError: ('Gorm the Great', 'Virtus the Veiled')\n```",
        "ts": "1558302359.019500",
        "username": "edhrecbot",
        "icons": {
            "emoji": ":robot_face:",
            "image_64": "https:\/\/a.slack-edge.com\/37d58\/img\/emoji_2017_12_06\/apple\/1f916.png"
        },
        "bot_id": "B2867AJ5C"
    },
    {
        "type": "message",
        "subtype": "bot_message",
        "text": "```2019-05-19 21:48:26,967 CRITICAL Uncaught exception\nTraceback (most recent call last):\n  File \"\/home\/ubuntu\/edhrec\/core\/database.py\", line 921, in get_count_by_date\n    return cache.get('{}\/{}'.format(table, carddate))[name]\n  File \"\/home\/ubuntu\/edhrec\/core\/cache.py\", line 67, in get\n    raise NotInCache(key)\nedhrec.core.cache.NotInCache: cards_table\/1994-08-01\n\nDuring handling of the above exception, another exception occurred:\n\nTraceback (most recent call last):\n  File \"&lt;string&gt;\", line 1, in &lt;module&gt;\n  File \"\/home\/ubuntu\/edhrec\/web\/nightly.py\", line 884, in make_partner_commanders\n    make_commander(commander)\n  File \"\/home\/ubuntu\/edhrec\/web\/nightly.py\", line 582, in make_commander\n    data = origin.getcommanders(cardses=name, checktribe=checktribe, tribe=tribe, outof=outof)\n  File \"\/home\/ubuntu\/edhrec\/web\/origin.py\", line 432, in getcommanders\n    data = database.tally(decks, card=card)\n  File \"\/home\/ubuntu\/edhrec\/core\/database.py\", line 2039, in tally\n    num_decks = get_count_by_date(card, card_age)\n  File \"\/home\/ubuntu\/edhrec\/core\/database.py\", line 926, in get_count_by_date\n    return cache.get(table + '\/earliest')[name]\nKeyError: 'Gorm the GreatVirtus the Veiled'\n```",
        "ts": "1558302410.019600",
        "username": "edhrecbot",
        "icons": {
            "emoji": ":robot_face:",
            "image_64": "https:\/\/a.slack-edge.com\/37d58\/img\/emoji_2017_12_06\/apple\/1f916.png"
        },
        "bot_id": "B2867AJ5C"
    },
    {
        "type": "message",
        "subtype": "bot_message",
        "text": "```2019-05-19 21:49:39,944 CRITICAL Uncaught exception\nTraceback (most recent call last):\n  File \"\/home\/ubuntu\/edhrec\/core\/database.py\", line 922, in get_count_by_date\n    return cache.get('{}\/{}'.format(table, carddate))[name]\n  File \"\/home\/ubuntu\/edhrec\/core\/cache.py\", line 67, in get\n    raise NotInCache(key)\nedhrec.core.cache.NotInCache: cards_table\/2011-05-13\n\nDuring handling of the above exception, another exception occurred:\n\nTraceback (most recent call last):\n  File \"&lt;string&gt;\", line 1, in &lt;module&gt;\n  File \"\/home\/ubuntu\/edhrec\/web\/nightly.py\", line 884, in make_partner_commanders\n    make_commander(commander)\n  File \"\/home\/ubuntu\/edhrec\/web\/nightly.py\", line 582, in make_commander\n    data = origin.getcommanders(cardses=name, checktribe=checktribe, tribe=tribe, outof=outof)\n  File \"\/home\/ubuntu\/edhrec\/web\/origin.py\", line 432, in getcommanders\n    data = database.tally(decks, card=card)\n  File \"\/home\/ubuntu\/edhrec\/core\/database.py\", line 2040, in tally\n    num_decks = get_count_by_date(card, card_age)\n  File \"\/home\/ubuntu\/edhrec\/core\/database.py\", line 927, in get_count_by_date\n    return cache.get(table + '\/earliest')[name]\nKeyError: 'Gorm the GreatVirtus the Veiled'\n```",
        "ts": "1558302483.019700",
        "username": "edhrecbot",
        "icons": {
            "emoji": ":robot_face:",
            "image_64": "https:\/\/a.slack-edge.com\/37d58\/img\/emoji_2017_12_06\/apple\/1f916.png"
        },
        "bot_id": "B2867AJ5C"
    },
    {
        "type": "message",
        "subtype": "bot_message",
        "text": "```2019-05-19 21:53:45,940 ERROR Chaos Orb in <http:\/\/www.mtggoldfish.com\/deck\/1923693>\n```",
        "ts": "1558302729.019800",
        "username": "edhrecbot",
        "icons": {
            "emoji": ":robot_face:",
            "image_64": "https:\/\/a.slack-edge.com\/37d58\/img\/emoji_2017_12_06\/apple\/1f916.png"
        },
        "bot_id": "B2867AJ5C"
    },
    {
        "type": "message",
        "subtype": "bot_message",
        "text": "```2019-05-19 21:55:31,925 INFO mtggoldfish.py took 0:32:20.321326\n```",
        "ts": "1558302835.019900",
        "username": "edhrecbot",
        "icons": {
            "emoji": ":robot_face:",
            "image_64": "https:\/\/a.slack-edge.com\/37d58\/img\/emoji_2017_12_06\/apple\/1f916.png"
        },
        "bot_id": "B2867AJ5C"
    },
    {
        "type": "message",
        "subtype": "bot_message",
        "text": "```2019-05-19 21:56:21,241 CRITICAL Uncaught exception\nTraceback (most recent call last):\n  File \"&lt;string&gt;\", line 1, in &lt;module&gt;\n  File \"\/home\/ubuntu\/edhrec\/web\/nightly.py\", line 884, in make_partner_commanders\n    make_commander(commander)\n  File \"\/home\/ubuntu\/edhrec\/web\/nightly.py\", line 582, in make_commander\n    data = origin.getcommanders(cardses=name, checktribe=checktribe, tribe=tribe, outof=outof)\n  File \"\/home\/ubuntu\/edhrec\/web\/origin.py\", line 432, in getcommanders\n    data = database.tally(decks, card=card)\n  File \"\/home\/ubuntu\/edhrec\/core\/database.py\", line 2188, in tally\n    num_decks = get_count_by_date(name, cards.get(card)['released_at'], commander=True)\n  File \"\/home\/ubuntu\/edhrec\/core\/cards.py\", line 384, in get\n    name = sanitize_url(name.split('(')[0].strip())\nAttributeError: 'tuple' object has no attribute 'split'\n```",
        "ts": "1558302885.020000",
        "username": "edhrecbot",
        "icons": {
            "emoji": ":robot_face:",
            "image_64": "https:\/\/a.slack-edge.com\/37d58\/img\/emoji_2017_12_06\/apple\/1f916.png"
        },
        "bot_id": "B2867AJ5C"
    },
    {
        "type": "message",
        "subtype": "bot_message",
        "text": "Nightly started, onlydecks=False, skipdecks=False",
        "ts": "1558303624.020100",
        "username": "edhrecbot",
        "icons": {
            "emoji": ":robot_face:",
            "image_64": "https:\/\/a.slack-edge.com\/37d58\/img\/emoji_2017_12_06\/apple\/1f916.png"
        },
        "bot_id": "B2867AJ5C"
    },
    {
        "type": "message",
        "subtype": "bot_message",
        "text": "Nightly started, onlydecks=False, skipdecks=False",
        "ts": "1558303867.020200",
        "username": "edhrecbot",
        "icons": {
            "emoji": ":robot_face:",
            "image_64": "https:\/\/a.slack-edge.com\/37d58\/img\/emoji_2017_12_06\/apple\/1f916.png"
        },
        "bot_id": "B2867AJ5C"
    },
    {
        "type": "message",
        "subtype": "bot_message",
        "text": "```2019-05-19 22:14:35,625 INFO update_deckswithprices.py took 0:19:01.586685\n```",
        "ts": "1558303979.020300",
        "username": "edhrecbot",
        "icons": {
            "emoji": ":robot_face:",
            "image_64": "https:\/\/a.slack-edge.com\/37d58\/img\/emoji_2017_12_06\/apple\/1f916.png"
        },
        "bot_id": "B2867AJ5C"
    }
]