[
    {
        "type": "message",
        "subtype": "bot_message",
        "text": "```2019-05-17 08:00:34,106 ERROR elusive tormentor missing from cardkingdom prices json\n2019-05-17 08:00:34,106 ERROR convicted killer missing from cardkingdom prices json\n2019-05-17 08:00:34,106 ERROR hinterland hermit missing from cardkingdom prices json\n2019-05-17 08:00:34,106 ERROR tormented pariah missing from cardkingdom prices json\n2019-05-17 08:00:34,107 ERROR chosen of markov missing from cardkingdom prices json\n2019-05-17 08:00:34,107 ERROR cryptolith fragment missing from cardkingdom prices json\n2019-05-17 08:00:34,107 ERROR lambholt elder missing from cardkingdom prices json\n2019-05-17 08:00:34,107 ERROR village ironsmith missing from cardkingdom prices json\n2019-05-17 08:00:34,107 ERROR ravenous demon missing from cardkingdom prices json\n2019-05-17 08:00:34,107 ERROR aberrant researcher missing from cardkingdom prices json\n2019-05-17 08:00:34,107 ERROR lambholt pacifist missing from cardkingdom prices json\n2019-05-17 08:00:34,107 ERROR autumnal gloom missing from cardkingdom prices json\n2019-05-17 08:00:34,107 ERROR civilized scholar missing from cardkingdom prices json\n2019-05-17 08:00:34,108 ERROR gatstaf shepherd missing from cardkingdom prices json\n2019-05-17 08:00:34,108 ERROR villagers of estwald missing from cardkingdom prices json\n2019-05-17 08:00:34,108 ERROR ulvenwald mystics missing from cardkingdom prices json\n2019-05-17 08:00:34,108 ERROR neglected heirloom missing from cardkingdom prices json\n2019-05-17 08:00:34,108 ERROR grizzled outcasts missing from cardkingdom prices json\n2019-05-17 08:00:34,108 ERROR skin invasion missing from cardkingdom prices json\n2019-05-17 08:00:34,108 ERROR thraben sentry missing from cardkingdom prices json\n2019-05-17 08:00:34,108 ERROR soul seizer missing from cardkingdom prices json\n2019-05-17 08:00:34,109 ERROR daring sleuth missing from cardkingdom prices json\n2019-05-17 08:00:34,109 ERROR solitary hunter missing from cardkingdom prices json\n2019-05-17 08:00:34,109 ERROR kindly stranger missing from cardkingdom prices json\n2019-05-17 08:00:34,109 ERROR grizzled angler missing from cardkingdom prices json\n2019-05-17 08:00:34,109 ERROR screeching bat missing from cardkingdom prices json\n2019-05-17 08:00:34,109 ERROR uninvited geist missing from cardkingdom prices json\n2019-05-17 08:00:34,109 ERROR cloistered youth missing from cardkingdom prices json\n2019-05-17 08:00:34,109 ERROR thraben gargoyle missing from cardkingdom prices json\n2019-05-17 08:00:34,110 ERROR avacynian missionaries missing from cardkingdom prices json\n2019-05-17 08:00:34,110 ERROR hinterland logger missing from cardkingdom prices json\n```",
        "ts": "1558079942.030000",
        "username": "edhrecbot",
        "icons": {
            "emoji": ":robot_face:",
            "image_64": "https:\/\/a.slack-edge.com\/37d58\/img\/emoji_2017_12_06\/apple\/1f916.png"
        },
        "bot_id": "B2867AJ5C"
    },
    {
        "type": "message",
        "subtype": "bot_message",
        "text": "```2019-05-17 08:09:11,320 INFO cards.py took 0:09:04.424806\n```",
        "ts": "1558080459.030100",
        "username": "edhrecbot",
        "icons": {
            "emoji": ":robot_face:",
            "image_64": "https:\/\/a.slack-edge.com\/37d58\/img\/emoji_2017_12_06\/apple\/1f916.png"
        },
        "bot_id": "B2867AJ5C"
    },
    {
        "type": "message",
        "subtype": "bot_message",
        "text": "```2019-05-17 08:10:20,330 INFO backup.py took 0:10:17.895523\n```",
        "ts": "1558080528.030200",
        "username": "edhrecbot",
        "icons": {
            "emoji": ":robot_face:",
            "image_64": "https:\/\/a.slack-edge.com\/37d58\/img\/emoji_2017_12_06\/apple\/1f916.png"
        },
        "bot_id": "B2867AJ5C"
    },
    {
        "type": "message",
        "subtype": "bot_message",
        "text": "",
        "ts": "1558080718.030300",
        "username": "incoming-webhook",
        "bot_id": "B5XN109SM",
        "attachments": [
            {
                "fallback": "<@channel>   *[Amazon CloudWatch Notification]* \nSubject: ALARM: \"EDHREC NetworkOut\" in US East (N. Virginia)\nMessage: {\"AlarmName\":\"EDHREC NetworkOut\",\"AlarmDescription\":null,\"AWSAccountId\":\"083767677168\",\"NewStateValue\":\"ALARM\",\"NewStateReason\":\"Threshold Crossed: 1 datapoint [7.062516652E8 (17\/05\/19 08:06:00)] was greater than or equal to the threshold (3.0E8).\",\"StateChangeTime\":\"2019-05-17T08:11:57.785+0000\",\"Region\":\"US East (N. Virginia)\",\"OldStateValue\":\"OK\",\"Trigger\":{\"MetricName\":\"NetworkOut\",\"Namespace\":\"AWS\/EC2\",\"StatisticType\":\"Statistic\",\"Statistic\":\"AVERAGE\",\"Unit\":null,\"Dimensions\":[{\"value\":\"i-0f7f3750e584e120e\",\"name\":\"InstanceId\"}],\"Period\":300,\"EvaluationPeriods\":1,\"ComparisonOperator\":\"GreaterThanOrEqualToThreshold\",\"Threshold\":3.0E8,\"TreatMissingData\":\"- TreatMissingData:                    missing\",\"EvaluateLowSampleCountPercentile\":\"\"}}\nTimestamp: 2019-05-17T08:11:57.856Z ",
                "text": "<@channel>   *[Amazon CloudWatch Notification]* \nSubject: ALARM: \"EDHREC NetworkOut\" in US East (N. Virginia)\nMessage: {\"AlarmName\":\"EDHREC NetworkOut\",\"AlarmDescription\":null,\"AWSAccountId\":\"083767677168\",\"NewStateValue\":\"ALARM\",\"NewStateReason\":\"Threshold Crossed: 1 datapoint [7.062516652E8 (17\/05\/19 08:06:00)] was greater than or equal to the threshold (3.0E8).\",\"StateChangeTime\":\"2019-05-17T08:11:57.785+0000\",\"Region\":\"US East (N. Virginia)\",\"OldStateValue\":\"OK\",\"Trigger\":{\"MetricName\":\"NetworkOut\",\"Namespace\":\"AWS\/EC2\",\"StatisticType\":\"Statistic\",\"Statistic\":\"AVERAGE\",\"Unit\":null,\"Dimensions\":[{\"value\":\"i-0f7f3750e584e120e\",\"name\":\"InstanceId\"}],\"Period\":300,\"EvaluationPeriods\":1,\"ComparisonOperator\":\"GreaterThanOrEqualToThreshold\",\"Threshold\":3.0E8,\"TreatMissingData\":\"- TreatMissingData:                    missing\",\"EvaluateLowSampleCountPercentile\":\"\"}}\nTimestamp: 2019-05-17T08:11:57.856Z ",
                "id": 1,
                "color": "F35A00",
                "fields": [
                    {
                        "title": "Severity",
                        "value": "ALARM",
                        "short": true
                    }
                ],
                "mrkdwn_in": [
                    "text"
                ]
            }
        ]
    },
    {
        "type": "message",
        "subtype": "bot_message",
        "text": "```2019-05-17 08:39:06,629 INFO archidekt.py took 0:27:55.612105\n```",
        "ts": "1558082254.030400",
        "username": "edhrecbot",
        "icons": {
            "emoji": ":robot_face:",
            "image_64": "https:\/\/a.slack-edge.com\/37d58\/img\/emoji_2017_12_06\/apple\/1f916.png"
        },
        "bot_id": "B2867AJ5C"
    },
    {
        "type": "message",
        "subtype": "bot_message",
        "text": "```2019-05-17 08:44:18,598 WARNING Chaos Orb from Crow Storm in <https:\/\/deckstats.net\/decks\/119746\/1185214-kenrith-twins-spellslingers\/en#Row>\n```",
        "ts": "1558082566.030500",
        "username": "edhrecbot",
        "icons": {
            "emoji": ":robot_face:",
            "image_64": "https:\/\/a.slack-edge.com\/37d58\/img\/emoji_2017_12_06\/apple\/1f916.png"
        },
        "bot_id": "B2867AJ5C"
    },
    {
        "type": "message",
        "subtype": "bot_message",
        "text": "```2019-05-17 09:11:47,281 INFO deckstats.py took 0:30:41.944865\n```",
        "ts": "1558084215.030600",
        "username": "edhrecbot",
        "icons": {
            "emoji": ":robot_face:",
            "image_64": "https:\/\/a.slack-edge.com\/37d58\/img\/emoji_2017_12_06\/apple\/1f916.png"
        },
        "bot_id": "B2867AJ5C"
    },
    {
        "type": "message",
        "subtype": "bot_message",
        "text": "```2019-05-17 09:35:14,522 ERROR Chaos Orb in <http:\/\/www.mtggoldfish.com\/deck\/1916311>\n```",
        "ts": "1558085622.030700",
        "username": "edhrecbot",
        "icons": {
            "emoji": ":robot_face:",
            "image_64": "https:\/\/a.slack-edge.com\/37d58\/img\/emoji_2017_12_06\/apple\/1f916.png"
        },
        "bot_id": "B2867AJ5C"
    },
    {
        "type": "message",
        "subtype": "bot_message",
        "text": "```2019-05-17 10:02:24,039 INFO mtggoldfish.py took 0:30:21.792061\n```",
        "ts": "1558087252.000100",
        "username": "edhrecbot",
        "icons": {
            "emoji": ":robot_face:",
            "image_64": "https:\/\/a.slack-edge.com\/37d58\/img\/emoji_2017_12_06\/apple\/1f916.png"
        },
        "bot_id": "B2867AJ5C"
    },
    {
        "type": "message",
        "subtype": "bot_message",
        "text": "```2019-05-17 10:20:37,174 INFO update_deckswithprices.py took 0:18:10.770764\n```",
        "ts": "1558088345.000200",
        "username": "edhrecbot",
        "icons": {
            "emoji": ":robot_face:",
            "image_64": "https:\/\/a.slack-edge.com\/37d58\/img\/emoji_2017_12_06\/apple\/1f916.png"
        },
        "bot_id": "B2867AJ5C"
    },
    {
        "type": "message",
        "subtype": "bot_message",
        "text": "```2019-05-17 11:12:40,586 INFO New Trending 2019-05-17\n{\"name\": \"Buried Ruin\", \"s\": [0, 40, 58, 50, 77, 75, 78], \"z\": 1.322050705820867}\n{\"name\": \"Open the Graves\", \"s\": [0, 7, 11, 11, 19, 22, 23], \"z\": 1.2837239761146397}\n{\"name\": \"Vindictive Vampire\", \"s\": [0, 6, 6, 9, 15, 20, 20], \"z\": 1.2830300847642164}\n{\"name\": \"Reliquary Tower\", \"s\": [0, 236, 243, 260, 291, 292, 316], \"z\": 1.228365690143426}\n{\"name\": \"Coastal Piracy\", \"s\": [0, 6, 4, 8, 12, 13, 14], \"z\": 1.216529305620537}\n{\"name\": \"Scrap Mastery\", \"s\": [0, 2, 5, 8, 11, 13, 14], \"z\": 1.214129989092976}\n{\"name\": \"Bontu's Monument\", \"s\": [0, 12, 11, 11, 18, 22, 23], \"z\": 1.2130646170174488}\n{\"name\": \"Red Elemental Blast\", \"s\": [0, 17, 16, 19, 29, 26, 28], \"z\": 1.2075364907359694}\n{\"name\": \"Diabolic Tutor\", \"s\": [0, 58, 60, 63, 84, 69, 101], \"z\": 1.203694042005148}\n{\"name\": \"Altar of the Brood\", \"s\": [0, 11, 10, 8, 17, 21, 20], \"z\": 1.2006686795729349}\n2019-05-17 11:12:40,601 INFO daily.py took 3:12:34.609291\n```",
        "ts": "1558091468.000300",
        "username": "edhrecbot",
        "icons": {
            "emoji": ":robot_face:",
            "image_64": "https:\/\/a.slack-edge.com\/37d58\/img\/emoji_2017_12_06\/apple\/1f916.png"
        },
        "bot_id": "B2867AJ5C"
    },
    {
        "type": "message",
        "subtype": "bot_message",
        "text": "[BAD] \/usr\/share\/nginx\/html\/commanders\/omnath-locus-of-mana.html has not been updated in the past 30 hours",
        "ts": "1558101810.000400",
        "username": "edhrecbot",
        "icons": {
            "emoji": ":robot_face:",
            "image_64": "https:\/\/a.slack-edge.com\/37d58\/img\/emoji_2017_12_06\/apple\/1f916.png"
        },
        "bot_id": "B2867AJ5C"
    },
    {
        "type": "message",
        "subtype": "bot_message",
        "text": "[BAD] \/usr\/share\/nginx\/html\/decks\/zedruu-the-greathearted.html has not been updated in the past 30 hours",
        "ts": "1558101810.000500",
        "username": "edhrecbot",
        "icons": {
            "emoji": ":robot_face:",
            "image_64": "https:\/\/a.slack-edge.com\/37d58\/img\/emoji_2017_12_06\/apple\/1f916.png"
        },
        "bot_id": "B2867AJ5C"
    },
    {
        "type": "message",
        "subtype": "bot_message",
        "text": "[BAD] \/usr\/share\/nginx\/html\/cards\/capsize.html has not been updated in the past 30 hours",
        "ts": "1558101810.000600",
        "username": "edhrecbot",
        "icons": {
            "emoji": ":robot_face:",
            "image_64": "https:\/\/a.slack-edge.com\/37d58\/img\/emoji_2017_12_06\/apple\/1f916.png"
        },
        "bot_id": "B2867AJ5C"
    },
    {
        "type": "message",
        "subtype": "bot_message",
        "text": "Nightly started, onlydecks=False, skipdecks=False",
        "ts": "1558106861.000700",
        "username": "edhrecbot",
        "icons": {
            "emoji": ":robot_face:",
            "image_64": "https:\/\/a.slack-edge.com\/37d58\/img\/emoji_2017_12_06\/apple\/1f916.png"
        },
        "bot_id": "B2867AJ5C"
    },
    {
        "type": "message",
        "subtype": "bot_message",
        "text": "```2019-05-17 20:31:35,788 INFO archidekt.py took 0:29:41.576773\n```",
        "ts": "1558125003.000800",
        "username": "edhrecbot",
        "icons": {
            "emoji": ":robot_face:",
            "image_64": "https:\/\/a.slack-edge.com\/37d58\/img\/emoji_2017_12_06\/apple\/1f916.png"
        },
        "bot_id": "B2867AJ5C"
    },
    {
        "type": "message",
        "subtype": "bot_message",
        "text": "```2019-05-17 20:33:39,341 WARNING Chaos Orb from A Display of My Dark Power in <https:\/\/deckstats.net\/decks\/129434\/1262972-gruul-counters\/en>\n```",
        "ts": "1558125126.000900",
        "username": "edhrecbot",
        "icons": {
            "emoji": ":robot_face:",
            "image_64": "https:\/\/a.slack-edge.com\/37d58\/img\/emoji_2017_12_06\/apple\/1f916.png"
        },
        "bot_id": "B2867AJ5C"
    },
    {
        "type": "message",
        "subtype": "bot_message",
        "text": "```2019-05-17 20:36:19,044 WARNING Chaos Orb from A Display of My Dark Power in <https:\/\/deckstats.net\/decks\/107010\/1296615-nezahal-primal-tide\/en>\n```",
        "ts": "1558125286.001000",
        "username": "edhrecbot",
        "icons": {
            "emoji": ":robot_face:",
            "image_64": "https:\/\/a.slack-edge.com\/37d58\/img\/emoji_2017_12_06\/apple\/1f916.png"
        },
        "bot_id": "B2867AJ5C"
    },
    {
        "type": "message",
        "subtype": "bot_message",
        "text": "```2019-05-17 20:52:08,292 WARNING Chaos Orb from Crow Storm in <https:\/\/deckstats.net\/decks\/119746\/1185214-kenrith-twins-spellslingers\/en#Row>\n```",
        "ts": "1558126235.001100",
        "username": "edhrecbot",
        "icons": {
            "emoji": ":robot_face:",
            "image_64": "https:\/\/a.slack-edge.com\/37d58\/img\/emoji_2017_12_06\/apple\/1f916.png"
        },
        "bot_id": "B2867AJ5C"
    },
    {
        "type": "message",
        "subtype": "bot_message",
        "text": "```2019-05-17 21:05:02,266 INFO deckstats.py took 0:31:26.900666\n```",
        "ts": "1558127009.001200",
        "username": "edhrecbot",
        "icons": {
            "emoji": ":robot_face:",
            "image_64": "https:\/\/a.slack-edge.com\/37d58\/img\/emoji_2017_12_06\/apple\/1f916.png"
        },
        "bot_id": "B2867AJ5C"
    },
    {
        "type": "message",
        "subtype": "bot_message",
        "text": "```2019-05-17 21:31:11,237 ERROR Chaos Orb in <http:\/\/www.mtggoldfish.com\/deck\/1916311>\n```",
        "ts": "1558128578.001300",
        "username": "edhrecbot",
        "icons": {
            "emoji": ":robot_face:",
            "image_64": "https:\/\/a.slack-edge.com\/37d58\/img\/emoji_2017_12_06\/apple\/1f916.png"
        },
        "bot_id": "B2867AJ5C"
    },
    {
        "type": "message",
        "subtype": "bot_message",
        "text": "```2019-05-17 21:57:56,005 INFO mtggoldfish.py took 0:32:36.437161\n```",
        "ts": "1558130183.001400",
        "username": "edhrecbot",
        "icons": {
            "emoji": ":robot_face:",
            "image_64": "https:\/\/a.slack-edge.com\/37d58\/img\/emoji_2017_12_06\/apple\/1f916.png"
        },
        "bot_id": "B2867AJ5C"
    },
    {
        "type": "message",
        "subtype": "bot_message",
        "text": "```[17\/May\/2019:22:32:27] ENGINE Error in HTTPServer.tick\nTraceback (most recent call last):\n  File \"\/usr\/local\/lib\/python3.5\/dist-packages\/cheroot\/server.py\", line 1721, in serve\n  File \"\/usr\/local\/lib\/python3.5\/dist-packages\/cheroot\/server.py\", line 1899, in tick\n  File \"\/usr\/lib\/python3.5\/socket.py\", line 195, in accept\nOSError: [Errno 24] Too many open files\n\n[17\/May\/2019:22:32:27] ENGINE Error in HTTPServer.tick\nTraceback (most recent call last):\n  File \"\/usr\/local\/lib\/python3.5\/dist-packages\/cheroot\/server.py\", line 1721, in serve\n  File \"\/usr\/local\/lib\/python3.5\/dist-packages\/cheroot\/server.py\", line 1899, in tick\n  File \"\/usr\/lib\/python3.5\/socket.py\", line 195, in accept\nOSError: [Errno 24] Too many open files\n\n[17\/May\/2019:22:32:27] ENGINE Error in HTTPServer.tick\nTraceback (most recent call last):\n  File \"\/usr\/local\/lib\/python3.5\/dist-packages\/cheroot\/server.py\", line 1721, in serve\n  File \"\/usr\/local\/lib\/python3.5\/dist-packages\/cheroot\/server.py\", line 1899, in tick\n  File \"\/usr\/lib\/python3.5\/socket.py\", line 195, in accept\nOSError: [Errno 24] Too many open files\n\n[17\/May\/2019:22:32:27] ENGINE Error in HTTPServer.tick\nTraceback (most recent call last):\n  File \"\/usr\/local\/lib\/python3.5\/dist-packages\/cheroot\/server.py\", line 1721, in serve\n  File \"\/usr\/local\/lib\/python3.5\/dist-packages\/cheroot\/server.py\", line 1899, in tick\n  File \"\/usr\/lib\/python3.5\/socket.py\", line 195, in accept\nOSError: [Errno 24] Too many open files\n\n[17\/May\/2019:22:32:27] ENGINE Error in HTTPServer.tick\nTraceback (most recent call last):\n  File \"\/usr\/local\/lib\/python3.5\/dist-packages\/cheroot\/server.py\", line 1721, in serve\n  File \"\/usr\/local\/lib\/python3.5\/dist-packages\/cheroot\/server.py\", line 1899, in tick\n  File \"\/usr\/lib\/python3.5\/socket.py\", line 195, in accept\nOSError: [Errno 24] Too many open files\n\n[17\/May\/2019:22:32:27] ENGINE Error in HTTPServer.tick\nTraceback (most recent call last):\n  File \"\/usr\/local\/lib\/python3.5\/dist-packages\/cheroot\/server.py\", line 1721, in serve\n  File \"\/usr\/local\/lib\/python3.5\/dist-packages\/cheroot\/server.py\", line 1899, in tick\n  File \"\/usr\/lib\/python3.5\/socket.py\", line 195, in accept\nOSError: [Errno 24] Too many open files\n\n[17\/May\/2019:22:32:27] ENGINE Error in HTTPServer.tick\nTraceback (most recent call last):\n  File \"\/usr\/local\/lib\/python3.5\/dist-packages\/cheroot\/server.py\", line 1721, in serve\n  File \"\/usr\/local\/lib\/python3.5\/dist-packages\/cheroot\/server.py\", line 1899, in tick\n  File \"\/usr\/lib\/python3.5\/socket.py\", line 195, in accept\nOSError: [Errno 24] Too many open files\n\n[17\/May\/2019:22:32:27] ENGINE Error in HTTPServer.tick\nTraceback (most recent call last):\n  File \"\/usr\/local\/lib\/python3.5\/dist-packages\/cheroot\/server.py\", line 1721, in serve\n  File \"\/usr\/local\/lib\/python3.5\/dist-packages\/cheroot\/server.py\", line 1899, in tick\n  File \"\/usr\/lib\/python3.5\/socket.py\", line 195, in accept\nOSError: [Errno 24] Too many open files\n\n[17\/May\/2019:22:32:27] ENGINE Error in HTTPServer.tick\nTraceback (most recent call last):\n  File \"\/usr\/local\/lib\/python3.5\/dist-packages\/cheroot\/server.py\", line 1721, in serve\n  File \"\/usr\/local\/lib\/python3.5\/dist-packages\/cheroot\/server.py\", line 1899, in tick\n  File \"\/usr\/lib\/python3.5\/socket.py\", line 195, in accept\nOSError: [Errno 24] Too many open files\n\n[17\/May\/2019:22:32:27] ENGINE Error in HTTPServer.tick\nTraceback (most recent call last):\n  File \"\/usr\/local\/lib\/python3.5\/dist-packages\/cheroot\/server.py\", line 1721, in serve\n  File \"\/usr\/local\/lib\/python3.5\/dist-packages\/cheroot\/server.py\", line 1899, in tick\n  File \"\/usr\/lib\/python3.5\/socket.py\", line 195, in accept\nOSError: [Errno 24] Too many open files\n\n[17\/May\/2019:22:32:27] ENGINE Error in HTTPServer.tick\nTraceback (most recent call last):\n  File \"\/usr\/local\/lib\/python3.5\/dist-packages\/cheroot\/server.py\", line 1721, in serve\n  File \"\/usr\/local\/lib\/python3.5\/dist-packages\/cheroot\/server.py\", line 1899, in tick\n  File \"\/usr\/lib\/python3.5\/socket.py\", line 195, in accept\nOSError: [Errno 24] Too many open files\n",
        "ts": "1558132255.001500",
        "username": "edhrecbot",
        "icons": {
            "emoji": ":robot_face:",
            "image_64": "https:\/\/a.slack-edge.com\/37d58\/img\/emoji_2017_12_06\/apple\/1f916.png"
        },
        "bot_id": "B2867AJ5C"
    },
    {
        "type": "message",
        "subtype": "bot_message",
        "text": "[17\/May\/2019:22:32:27] ENGINE Error in HTTPServer.tick\nTraceback (most recent call last):\n  File \"\/usr\/local\/lib\/python3.5\/dist-packages\/cheroot\/server.py\", line 1721, in serve\n  File \"\/usr\/local\/lib\/python3.5\/dist-packages\/cheroot\/server.py\", line 1899, in tick\n  File \"\/usr\/lib\/python3.5\/socket.py\", line 195, in accept\nOSError: [Errno 24] Too many open files\n\n[17\/May\/2019:22:32:27] ENGINE Error in HTTPServer.tick\nTraceback (most recent call last):\n  File \"\/usr\/local\/lib\/python3.5\/dist-packages\/cheroot\/server.py\", line 1721, in serve\n  File \"\/usr\/local\/lib\/python3.5\/dist-packages\/cheroot\/server.py\", line 1899, in tick\n  File \"\/usr\/lib\/python3.5\/socket.py\", line 195, in accept\nOSError: [Errno 24] Too many open files\n\n[17\/May\/2019:22:32:27] ENGINE Error in HTTPServer.tick\nTraceback (most recent call last):\n  File \"\/usr\/local\/lib\/python3.5\/dist-packages\/cheroot\/server.py\", line 1721, in serve\n  File \"\/usr\/local\/lib\/python3.5\/dist-packages\/cheroot\/server.py\", line 1899, in tick\n  File \"\/usr\/lib\/python3.5\/socket.py\", line 195, in accept\nOSError: [Errno 24] Too many open files\n\n[17\/May\/2019:22:32:27] ENGINE Error in HTTPServer.tick\nTraceback (most recent call last):\n  File \"\/usr\/local\/lib\/python3.5\/dist-packages\/cheroot\/server.py\", line 1721, in serve\n  File \"\/usr\/local\/lib\/python3.5\/dist-packages\/cheroot\/server.py\", line 1899, in tick\n  File \"\/usr\/lib\/python3.5\/socket.py\", line 195, in accept\nOSError: [Errno 24] Too many open files\n\n[17\/May\/2019:22:32:27] ENGINE Error in HTTPServer.tick\nTraceback (most recent call last):\n  File \"\/usr\/local\/lib\/python3.5\/dist-packages\/cheroot\/server.py\", line 1721, in serve\n  File \"\/usr\/local\/lib\/python3.5\/dist-packages\/cheroot\/server.py\", line 1899, in tick\n  File \"\/usr\/lib\/python3.5\/socket.py\", line 195, in accept\nOSError: [Errno 24] Too many open files\n\n[17\/May\/2019:22:32:27] ENGINE Error in HTTPServer.tick\nTraceback (most recent call last):\n  File \"\/usr\/local\/lib\/python3.5\/dist-packages\/cheroot\/server.py\", line 1721, in serve\n  File \"\/usr\/local\/lib\/python3.5\/dist-packages\/cheroot\/server.py\", line 1899, in tick\n  File \"\/usr\/lib\/python3.5\/socket.py\", line 195, in accept\nOSError: [Errno 24] Too many open files\n\n[17\/May\/2019:22:32:27] ENGINE Error in HTTPServer.tick\nTraceback (most recent call last):\n  File \"\/usr\/local\/lib\/python3.5\/dist-packages\/cheroot\/server.py\", line 1721, in serve\n  File \"\/usr\/local\/lib\/python3.5\/dist-packages\/cheroot\/server.py\", line 1899, in tick\n  File \"\/usr\/lib\/python3.5\/socket.py\", line 195, in accept\nOSError: [Errno 24] Too many open files\n\n[17\/May\/2019:22:32:27] ENGINE Error in HTTPServer.tick\nTraceback (most recent call last):\n  File \"\/usr\/local\/lib\/python3.5\/dist-packages\/cheroot\/server.py\", line 1721, in serve\n  File \"\/usr\/local\/lib\/python3.5\/dist-packages\/cheroot\/server.py\", line 1899, in tick\n  File \"\/usr\/lib\/python3.5\/socket.py\", line 195, in accept\nOSError: [Errno 24] Too many open files\n\n[17\/May\/2019:22:32:27] ENGINE Error in HTTPServer.tick\nTraceback (most recent call last):\n  File \"\/usr\/local\/lib\/python3.5\/dist-packages\/cheroot\/server.py\", line 1721, in serve\n  File \"\/usr\/local\/lib\/python3.5\/dist-packages\/cheroot\/server.py\", line 1899, in tick\n  File \"\/usr\/lib\/python3.5\/socket.py\", line 195, in accept\nOSError: [Errno 24] Too many open files\n\n[17\/May\/2019:22:32:27] ENGINE Error in HTTPServer.tick\nTraceback (most recent call last):\n  File \"\/usr\/local\/lib\/python3.5\/dist-packages\/cheroot\/server.py\", line 1721, in serve\n  File \"\/usr\/local\/lib\/python3.5\/dist-packages\/cheroot\/server.py\", line 1899, in tick\n  File \"\/usr\/lib\/python3.5\/socket.py\", line 195, in accept\nOSError: [Errno 24] Too many open files\n\n[17\/May\/2019:22:32:27] ENGINE Error in HTTPServer.tick\nTraceback (most recent call last):\n  File \"\/usr\/local\/lib\/python3.5\/dist-packages\/cheroot\/server.py\", line 1721, in serve\n  File \"\/usr\/local\/lib\/python3.5\/dist-packages\/cheroot\/server.py\", line 1899, in tick\n  File \"\/usr\/lib\/python3.5\/socket.py\", line 195, in accept\nOSError: [Errno 24] Too many open files\n",
        "ts": "1558132255.001600",
        "username": "edhrecbot",
        "icons": {
            "emoji": ":robot_face:",
            "image_64": "https:\/\/a.slack-edge.com\/37d58\/img\/emoji_2017_12_06\/apple\/1f916.png"
        },
        "bot_id": "B2867AJ5C"
    },
    {
        "type": "message",
        "subtype": "bot_message",
        "text": "[17\/May\/2019:22:32:27] ENGINE Error in HTTPServer.tick\nTraceback (most recent call last):\n  File \"\/usr\/local\/lib\/python3.5\/dist-packages\/cheroot\/server.py\", line 1721, in serve\n  File \"\/usr\/local\/lib\/python3.5\/dist-packages\/cheroot\/server.py\", line 1899, in tick\n  File \"\/usr\/lib\/python3.5\/socket.py\", line 195, in accept\nOSError: [Errno 24] Too many open files\n\n[17\/May\/2019:22:32:27] ENGINE Error in HTTPServer.tick\nTraceback (most recent call last):\n  File \"\/usr\/local\/lib\/python3.5\/dist-packages\/cheroot\/server.py\", line 1721, in serve\n  File \"\/usr\/local\/lib\/python3.5\/dist-packages\/cheroot\/server.py\", line 1899, in tick\n  File \"\/usr\/lib\/python3.5\/socket.py\", line 195, in accept\nOSError: [Errno 24] Too many open files\n\n[17\/May\/2019:22:32:27] ENGINE Error in HTTPServer.tick\nTraceback (most recent call last):\n  File \"\/usr\/local\/lib\/python3.5\/dist-packages\/cheroot\/server.py\", line 1721, in serve\n  File \"\/usr\/local\/lib\/python3.5\/dist-packages\/cheroot\/server.py\", line 1899, in tick\n  File \"\/usr\/lib\/python3.5\/socket.py\", line 195, in accept\nOSError: [Errno 24] Too many open files\n\n[17\/May\/2019:22:32:27] ENGINE Error in HTTPServer.tick\nTraceback (most recent call last):\n  File \"\/usr\/local\/lib\/python3.5\/dist-packages\/cheroot\/server.py\", line 1721, in serve\n  File \"\/usr\/local\/lib\/python3.5\/dist-packages\/cheroot\/server.py\", line 1899, in tick\n  File \"\/usr\/lib\/python3.5\/socket.py\", line 195, in accept\nOSError: [Errno 24] Too many open files\n\n[17\/May\/2019:22:32:27] ENGINE Error in HTTPServer.tick\nTraceback (most recent call last):\n  File \"\/usr\/local\/lib\/python3.5\/dist-packages\/cheroot\/server.py\", line 1721, in serve\n  File \"\/usr\/local\/lib\/python3.5\/dist-packages\/cheroot\/server.py\", line 1899, in tick\n  File \"\/usr\/lib\/python3.5\/socket.py\", line 195, in accept\nOSError: [Errno 24] Too many open files\n\n[17\/May\/2019:22:32:27] ENGINE Error in HTTPServer.tick\nTraceback (most recent call last):\n  File \"\/usr\/local\/lib\/python3.5\/dist-packages\/cheroot\/server.py\", line 1721, in serve\n  File \"\/usr\/local\/lib\/python3.5\/dist-packages\/cheroot\/server.py\", line 1899, in tick\n  File \"\/usr\/lib\/python3.5\/socket.py\", line 195, in accept\nOSError: [Errno 24] Too many open files\n\n[17\/May\/2019:22:32:27] ENGINE Error in HTTPServer.tick\nTraceback (most recent call last):\n  File \"\/usr\/local\/lib\/python3.5\/dist-packages\/cheroot\/server.py\", line 1721, in serve\n  File \"\/usr\/local\/lib\/python3.5\/dist-packages\/cheroot\/server.py\", line 1899, in tick\n  File \"\/usr\/lib\/python3.5\/socket.py\", line 195, in accept\nOSError: [Errno 24] Too many open files\n\n[17\/May\/2019:22:32:27] ENGINE Error in HTTPServer.tick\nTraceback (most recent call last):\n  File \"\/usr\/local\/lib\/python3.5\/dist-packages\/cheroot\/server.py\", line 1721, in serve\n  File \"\/usr\/local\/lib\/python3.5\/dist-packages\/cheroot\/server.py\", line 1899, in tick\n  File \"\/usr\/lib\/python3.5\/socket.py\", line 195, in accept\nOSError: [Errno 24] Too many open files\n\n[17\/May\/2019:22:32:27] ENGINE Error in HTTPServer.tick\nTraceback (most recent call last):\n  File \"\/usr\/local\/lib\/python3.5\/dist-packages\/cheroot\/server.py\", line 1721, in serve\n  File \"\/usr\/local\/lib\/python3.5\/dist-packages\/cheroot\/server.py\", line 1899, in tick\n  File \"\/usr\/lib\/python3.5\/socket.py\", line 195, in accept\nOSError: [Errno 24] Too many open files\n\n[17\/May\/2019:22:32:27] ENGINE Error in HTTPServer.tick\nTraceback (most recent call last):\n  File \"\/usr\/local\/lib\/python3.5\/dist-packages\/cheroot\/server.py\", line 1721, in serve\n  File \"\/usr\/local\/lib\/python3.5\/dist-packages\/cheroot\/server.py\", line 1899, in tick\n  File \"\/usr\/lib\/python3.5\/socket.py\", line 195, in accept\nOSError: [Errno 24] Too many open files\n\n[17\/May\/2019:22:32:27] ENGINE Error in HTTPServer.tick\nTraceback (most recent call last):\n  File \"\/usr\/local\/lib\/python3.5\/dist-packages\/cheroot\/server.py\", line 1721, in serve\n  File \"\/usr\/local\/lib\/python3.5\/dist-packages\/cheroot\/server.py\", line 1899, in tick\n  File \"\/usr\/lib\/python3.5\/socket.py\", line 195, in accept\nOSError: [Errno 24] Too many open files\n",
        "ts": "1558132255.001700",
        "username": "edhrecbot",
        "icons": {
            "emoji": ":robot_face:",
            "image_64": "https:\/\/a.slack-edge.com\/37d58\/img\/emoji_2017_12_06\/apple\/1f916.png"
        },
        "bot_id": "B2867AJ5C"
    },
    {
        "type": "message",
        "subtype": "bot_message",
        "text": "[17\/May\/2019:22:32:27] ENGINE Error in HTTPServer.tick\nTraceback (most recent call last):\n  File \"\/usr\/local\/lib\/python3.5\/dist-packages\/cheroot\/server.py\", line 1721, in serve\n  File \"\/usr\/local\/lib\/python3.5\/dist-packages\/cheroot\/server.py\", line 1899, in tick\n  File \"\/usr\/lib\/python3.5\/socket.py\", line 195, in accept\nOSError: [Errno 24] Too many open files\n\n[17\/May\/2019:22:32:27] ENGINE Error in HTTPServer.tick\nTraceback (most recent call last):\n  File \"\/usr\/local\/lib\/python3.5\/dist-packages\/cheroot\/server.py\", line 1721, in serve\n  File \"\/usr\/local\/lib\/python3.5\/dist-packages\/cheroot\/server.py\", line 1899, in tick\n  File \"\/usr\/lib\/python3.5\/socket.py\", line 195, in accept\nOSError: [Errno 24] Too many open files\n\n[17\/May\/2019:22:32:27] ENGINE Error in HTTPServer.tick\nTraceback (most recent call last):\n  File \"\/usr\/local\/lib\/python3.5\/dist-packages\/cheroot\/server.py\", line 1721, in serve\n  File \"\/usr\/local\/lib\/python3.5\/dist-packages\/cheroot\/server.py\", line 1899, in tick\n  File \"\/usr\/lib\/python3.5\/socket.py\", line 195, in accept\nOSError: [Errno 24] Too many open files\n\n[17\/May\/2019:22:32:27] ENGINE Error in HTTPServer.tick\nTraceback (most recent call last):\n  File \"\/usr\/local\/lib\/python3.5\/dist-packages\/cheroot\/server.py\", line 1721, in serve\n  File \"\/usr\/local\/lib\/python3.5\/dist-packages\/cheroot\/server.py\", line 1899, in tick\n  File \"\/usr\/lib\/python3.5\/socket.py\", line 195, in accept\nOSError: [Errno 24] Too many open files\n\n[17\/May\/2019:22:32:27] ENGINE Error in HTTPServer.tick\nTraceback (most recent call last):\n  File \"\/usr\/local\/lib\/python3.5\/dist-packages\/cheroot\/server.py\", line 1721, in serve\n  File \"\/usr\/local\/lib\/python3.5\/dist-packages\/cheroot\/server.py\", line 1899, in tick\n  File \"\/usr\/lib\/python3.5\/socket.py\", line 195, in accept\nOSError: [Errno 24] Too many open files\n\n[17\/May\/2019:22:32:27] ENGINE Error in HTTPServer.tick\nTraceback (most recent call last):\n  File \"\/usr\/local\/lib\/python3.5\/dist-packages\/cheroot\/server.py\", line 1721, in serve\n  File \"\/usr\/local\/lib\/python3.5\/dist-packages\/cheroot\/server.py\", line 1899, in tick\n  File \"\/usr\/lib\/python3.5\/socket.py\", line 195, in accept\nOSError: [Errno 24] Too many open files\n\n[17\/May\/2019:22:32:27] ENGINE Error in HTTPServer.tick\nTraceback (most recent call last):\n  File \"\/usr\/local\/lib\/python3.5\/dist-packages\/cheroot\/server.py\", line 1721, in serve\n  File \"\/usr\/local\/lib\/python3.5\/dist-packages\/cheroot\/server.py\", line 1899, in tick\n  File \"\/usr\/lib\/python3.5\/socket.py\", line 195, in accept\nOSError: [Errno 24] Too many open files\n\n[17\/May\/2019:22:32:27] ENGINE Error in HTTPServer.tick\nTraceback (most recent call last):\n  File \"\/usr\/local\/lib\/python3.5\/dist-packages\/cheroot\/server.py\", line 1721, in serve\n  File \"\/usr\/local\/lib\/python3.5\/dist-packages\/cheroot\/server.py\", line 1899, in tick\n  File \"\/usr\/lib\/python3.5\/socket.py\", line 195, in accept\nOSError: [Errno 24] Too many open files\n\n[17\/May\/2019:22:32:27] ENGINE Error in HTTPServer.tick\nTraceback (most recent call last):\n  File \"\/usr\/local\/lib\/python3.5\/dist-packages\/cheroot\/server.py\", line 1721, in serve\n  File \"\/usr\/local\/lib\/python3.5\/dist-packages\/cheroot\/server.py\", line 1899, in tick\n  File \"\/usr\/lib\/python3.5\/socket.py\", line 195, in accept\nOSError: [Errno 24] Too many open files\n\n[17\/May\/2019:22:32:27] ENGINE Error in HTTPServer.tick\nTraceback (most recent call last):\n  File \"\/usr\/local\/lib\/python3.5\/dist-packages\/cheroot\/server.py\", line 1721, in serve\n  File \"\/usr\/local\/lib\/python3.5\/dist-packages\/cheroot\/server.py\", line 1899, in tick\n  File \"\/usr\/lib\/python3.5\/socket.py\", line 195, in accept\nOSError: [Errno 24] Too many open files\n\n[17\/May\/2019:22:32:27] ENGINE Error in HTTPServer.tick\nTraceback (most recent call last):\n  File \"\/usr\/local\/lib\/python3.5\/dist-packages\/cheroot\/server.py\", line 1721, in serve\n  File \"\/usr\/local\/lib\/python3.5\/dist-packages\/cheroot\/server.py\", line 1899, in tick\n  File \"\/usr\/lib\/python3.5\/socket.py\", line 195, in accept\nOSError: [Errno 24] Too many open files\n",
        "ts": "1558132255.001800",
        "username": "edhrecbot",
        "icons": {
            "emoji": ":robot_face:",
            "image_64": "https:\/\/a.slack-edge.com\/37d58\/img\/emoji_2017_12_06\/apple\/1f916.png"
        },
        "bot_id": "B2867AJ5C"
    },
    {
        "type": "message",
        "subtype": "bot_message",
        "text": "[17\/May\/2019:22:32:27] ENGINE Error in HTTPServer.tick\nTraceback (most recent call last):\n  File \"\/usr\/local\/lib\/python3.5\/dist-packages\/cheroot\/server.py\", line 1721, in serve\n  File \"\/usr\/local\/lib\/python3.5\/dist-packages\/cheroot\/server.py\", line 1899, in tick\n  File \"\/usr\/lib\/python3.5\/socket.py\", line 195, in accept\nOSError: [Errno 24] Too many open files\n\n[17\/May\/2019:22:32:27] ENGINE Error in HTTPServer.tick\nTraceback (most recent call last):\n  File \"\/usr\/local\/lib\/python3.5\/dist-packages\/cheroot\/server.py\", line 1721, in serve\n  File \"\/usr\/local\/lib\/python3.5\/dist-packages\/cheroot\/server.py\", line 1899, in tick\n  File \"\/usr\/lib\/python3.5\/socket.py\", line 195, in accept\nOSError: [Errno 24] Too many open files\n\n[17\/May\/2019:22:32:27] ENGINE Error in HTTPServer.tick\nTraceback (most recent call last):\n  File \"\/usr\/local\/lib\/python3.5\/dist-packages\/cheroot\/server.py\", line 1721, in serve\n  File \"\/usr\/local\/lib\/python3.5\/dist-packages\/cheroot\/server.py\", line 1899, in tick\n  File \"\/usr\/lib\/python3.5\/socket.py\", line 195, in accept\nOSError: [Errno 24] Too many open files\n\n[17\/May\/2019:22:32:27] ENGINE Error in HTTPServer.tick\nTraceback (most recent call last):\n  File \"\/usr\/local\/lib\/python3.5\/dist-packages\/cheroot\/server.py\", line 1721, in serve\n  File \"\/usr\/local\/lib\/python3.5\/dist-packages\/cheroot\/server.py\", line 1899, in tick\n  File \"\/usr\/lib\/python3.5\/socket.py\", line 195, in accept\nOSError: [Errno 24] Too many open files\n\n[17\/May\/2019:22:32:27] ENGINE Error in HTTPServer.tick\nTraceback (most recent call last):\n  File \"\/usr\/local\/lib\/python3.5\/dist-packages\/cheroot\/server.py\", line 1721, in serve\n  File \"\/usr\/local\/lib\/python3.5\/dist-packages\/cheroot\/server.py\", line 1899, in tick\n  File \"\/usr\/lib\/python3.5\/socket.py\", line 195, in accept\nOSError: [Errno 24] Too many open files\n\n[17\/May\/2019:22:32:27] ENGINE Error in HTTPServer.tick\nTraceback (most recent call last):\n  File \"\/usr\/local\/lib\/python3.5\/dist-packages\/cheroot\/server.py\", line 1721, in serve\n  File \"\/usr\/local\/lib\/python3.5\/dist-packages\/cheroot\/server.py\", line 1899, in tick\n  File \"\/usr\/lib\/python3.5\/socket.py\", line 195, in accept\nOSError: [Errno 24] Too many open files\n\n[17\/May\/2019:22:32:27] ENGINE Error in HTTPServer.tick\nTraceback (most recent call last):\n  File \"\/usr\/local\/lib\/python3.5\/dist-packages\/cheroot\/server.py\", line 1721, in serve\n  File \"\/usr\/local\/lib\/python3.5\/dist-packages\/cheroot\/server.py\", line 1899, in tick\n  File \"\/usr\/lib\/python3.5\/socket.py\", line 195, in accept\nOSError: [Errno 24] Too many open files\n\n[17\/May\/2019:22:32:27] ENGINE Error in HTTPServer.tick\nTraceback (most recent call last):\n  File \"\/usr\/local\/lib\/python3.5\/dist-packages\/cheroot\/server.py\", line 1721, in serve\n  File \"\/usr\/local\/lib\/python3.5\/dist-packages\/cheroot\/server.py\", line 1899, in tick\n  File \"\/usr\/lib\/python3.5\/socket.py\", line 195, in accept\nOSError: [Errno 24] Too many open files\n\n[17\/May\/2019:22:32:27] ENGINE Error in HTTPServer.tick\nTraceback (most recent call last):\n  File \"\/usr\/local\/lib\/python3.5\/dist-packages\/cheroot\/server.py\", line 1721, in serve\n  File \"\/usr\/local\/lib\/python3.5\/dist-packages\/cheroot\/server.py\", line 1899, in tick\n  File \"\/usr\/lib\/python3.5\/socket.py\", line 195, in accept\nOSError: [Errno 24] Too many open files\n\n[17\/May\/2019:22:32:27] ENGINE Error in HTTPServer.tick\nTraceback (most recent call last):\n  File \"\/usr\/local\/lib\/python3.5\/dist-packages\/cheroot\/server.py\", line 1721, in serve\n  File \"\/usr\/local\/lib\/python3.5\/dist-packages\/cheroot\/server.py\", line 1899, in tick\n  File \"\/usr\/lib\/python3.5\/socket.py\", line 195, in accept\nOSError: [Errno 24] Too many open files\n\n[17\/May\/2019:22:32:27] ENGINE Error in HTTPServer.tick\nTraceback (most recent call last):\n  File \"\/usr\/local\/lib\/python3.5\/dist-packages\/cheroot\/server.py\", line 1721, in serve\n  File \"\/usr\/local\/lib\/python3.5\/dist-packages\/cheroot\/server.py\", line 1899, in tick\n  File \"\/usr\/lib\/python3.5\/socket.py\", line 195, in accept\nOSError: [Errno 24] Too many open files\n",
        "ts": "1558132255.001900",
        "username": "edhrecbot",
        "icons": {
            "emoji": ":robot_face:",
            "image_64": "https:\/\/a.slack-edge.com\/37d58\/img\/emoji_2017_12_06\/apple\/1f916.png"
        },
        "bot_id": "B2867AJ5C"
    },
    {
        "type": "message",
        "subtype": "bot_message",
        "text": "[17\/May\/2019:22:32:27] ENGINE Error in HTTPServer.tick\nTraceback (most recent call last):\n  File \"\/usr\/local\/lib\/python3.5\/dist-packages\/cheroot\/server.py\", line 1721, in serve\n  File \"\/usr\/local\/lib\/python3.5\/dist-packages\/cheroot\/server.py\", line 1899, in tick\n  File \"\/usr\/lib\/python3.5\/socket.py\", line 195, in accept\nOSError: [Errno 24] Too many open files\n\n[17\/May\/2019:22:32:27] ENGINE Error in HTTPServer.tick\nTraceback (most recent call last):\n  File \"\/usr\/local\/lib\/python3.5\/dist-packages\/cheroot\/server.py\", line 1721, in serve\n  File \"\/usr\/local\/lib\/python3.5\/dist-packages\/cheroot\/server.py\", line 1899, in tick\n  File \"\/usr\/lib\/python3.5\/socket.py\", line 195, in accept\nOSError: [Errno 24] Too many open files\n\n[17\/May\/2019:22:32:27] ENGINE Error in HTTPServer.tick\nTraceback (most recent call last):\n  File \"\/usr\/local\/lib\/python3.5\/dist-packages\/cheroot\/server.py\", line 1721, in serve\n  File \"\/usr\/local\/lib\/python3.5\/dist-packages\/cheroot\/server.py\", line 1899, in tick\n  File \"\/usr\/lib\/python3.5\/socket.py\", line 195, in accept\nOSError: [Errno 24] Too many open files\n\n[17\/May\/2019:22:32:27] ENGINE Error in HTTPServer.tick\nTraceback (most recent call last):\n  File \"\/usr\/local\/lib\/python3.5\/dist-packages\/cheroot\/server.py\", line 1721, in serve\n  File \"\/usr\/local\/lib\/python3.5\/dist-packages\/cheroot\/server.py\", line 1899, in tick\n  File \"\/usr\/lib\/python3.5\/socket.py\", line 195, in accept\nOSError: [Errno 24] Too many open files\n\n[17\/May\/2019:22:32:27] ENGINE Error in HTTPServer.tick\nTraceback (most recent call last):\n  File \"\/usr\/local\/lib\/python3.5\/dist-packages\/cheroot\/server.py\", line 1721, in serve\n  File \"\/usr\/local\/lib\/python3.5\/dist-packages\/cheroot\/server.py\", line 1899, in tick\n  File \"\/usr\/lib\/python3.5\/socket.py\", line 195, in accept\nOSError: [Errno 24] Too many open files\n\n[17\/May\/2019:22:32:27] ENGINE Error in HTTPServer.tick\nTraceback (most recent call last):\n  File \"\/usr\/local\/lib\/python3.5\/dist-packages\/cheroot\/server.py\", line 1721, in serve\n  File \"\/usr\/local\/lib\/python3.5\/dist-packages\/cheroot\/server.py\", line 1899, in tick\n  File \"\/usr\/lib\/python3.5\/socket.py\", line 195, in accept\nOSError: [Errno 24] Too many open files\n\n[17\/May\/2019:22:32:27] ENGINE Error in HTTPServer.tick\nTraceback (most recent call last):\n  File \"\/usr\/local\/lib\/python3.5\/dist-packages\/cheroot\/server.py\", line 1721, in serve\n  File \"\/usr\/local\/lib\/python3.5\/dist-packages\/cheroot\/server.py\", line 1899, in tick\n  File \"\/usr\/lib\/python3.5\/socket.py\", line 195, in accept\nOSError: [Errno 24] Too many open files\n\n[17\/May\/2019:22:32:27] ENGINE Error in HTTPServer.tick\nTraceback (most recent call last):\n  File \"\/usr\/local\/lib\/python3.5\/dist-packages\/cheroot\/server.py\", line 1721, in serve\n  File \"\/usr\/local\/lib\/python3.5\/dist-packages\/cheroot\/server.py\", line 1899, in tick\n  File \"\/usr\/lib\/python3.5\/socket.py\", line 195, in accept\nOSError: [Errno 24] Too many open files\n\n[17\/May\/2019:22:32:27] ENGINE Error in HTTPServer.tick\nTraceback (most recent call last):\n  File \"\/usr\/local\/lib\/python3.5\/dist-packages\/cheroot\/server.py\", line 1721, in serve\n  File \"\/usr\/local\/lib\/python3.5\/dist-packages\/cheroot\/server.py\", line 1899, in tick\n  File \"\/usr\/lib\/python3.5\/socket.py\", line 195, in accept\nOSError: [Errno 24] Too many open files\n\n[17\/May\/2019:22:32:27] ENGINE Error in HTTPServer.tick\nTraceback (most recent call last):\n  File \"\/usr\/local\/lib\/python3.5\/dist-packages\/cheroot\/server.py\", line 1721, in serve\n  File \"\/usr\/local\/lib\/python3.5\/dist-packages\/cheroot\/server.py\", line 1899, in tick\n  File \"\/usr\/lib\/python3.5\/socket.py\", line 195, in accept\nOSError: [Errno 24] Too many open files\n\n[17\/May\/2019:22:32:27] ENGINE Error in HTTPServer.tick\nTraceback (most recent call last):\n  File \"\/usr\/local\/lib\/python3.5\/dist-packages\/cheroot\/server.py\", line 1721, in serve\n  File \"\/usr\/local\/lib\/python3.5\/dist-packages\/cheroot\/server.py\", line 1899, in tick\n  File \"\/usr\/lib\/python3.5\/socket.py\", line 195, in accept\nOSError: [Errno 24] Too many open files\n",
        "ts": "1558132255.002000",
        "username": "edhrecbot",
        "icons": {
            "emoji": ":robot_face:",
            "image_64": "https:\/\/a.slack-edge.com\/37d58\/img\/emoji_2017_12_06\/apple\/1f916.png"
        },
        "bot_id": "B2867AJ5C"
    },
    {
        "type": "message",
        "subtype": "bot_message",
        "text": "[17\/May\/2019:22:32:27] ENGINE Error in HTTPServer.tick\nTraceback (most recent call last):\n  File \"\/usr\/local\/lib\/python3.5\/dist-packages\/cheroot\/server.py\", line 1721, in serve\n  File \"\/usr\/local\/lib\/python3.5\/dist-packages\/cheroot\/server.py\", line 1899, in tick\n  File \"\/usr\/lib\/python3.5\/socket.py\", line 195, in accept\nOSError: [Errno 24] Too many open files\n\n[17\/May\/2019:22:32:27] ENGINE Error in HTTPServer.tick\nTraceback (most recent call last):\n  File \"\/usr\/local\/lib\/python3.5\/dist-packages\/cheroot\/server.py\", line 1721, in serve\n  File \"\/usr\/local\/lib\/python3.5\/dist-packages\/cheroot\/server.py\", line 1899, in tick\n  File \"\/usr\/lib\/python3.5\/socket.py\", line 195, in accept\nOSError: [Errno 24] Too many open files\n\n[17\/May\/2019:22:32:27] ENGINE Error in HTTPServer.tick\nTraceback (most recent call last):\n  File \"\/usr\/local\/lib\/python3.5\/dist-packages\/cheroot\/server.py\", line 1721, in serve\n  File \"\/usr\/local\/lib\/python3.5\/dist-packages\/cheroot\/server.py\", line 1899, in tick\n  File \"\/usr\/lib\/python3.5\/socket.py\", line 195, in accept\nOSError: [Errno 24] Too many open files\n\n[17\/May\/2019:22:32:27] ENGINE Error in HTTPServer.tick\nTraceback (most recent call last):\n  File \"\/usr\/local\/lib\/python3.5\/dist-packages\/cheroot\/server.py\", line 1721, in serve\n  File \"\/usr\/local\/lib\/python3.5\/dist-packages\/cheroot\/server.py\", line 1899, in tick\n  File \"\/usr\/lib\/python3.5\/socket.py\", line 195, in accept\nOSError: [Errno 24] Too many open files\n\n[17\/May\/2019:22:32:27] ENGINE Error in HTTPServer.tick\nTraceback (most recent call last):\n  File \"\/usr\/local\/lib\/python3.5\/dist-packages\/cheroot\/server.py\", line 1721, in serve\n  File \"\/usr\/local\/lib\/python3.5\/dist-packages\/cheroot\/server.py\", line 1899, in tick\n  File \"\/usr\/lib\/python3.5\/socket.py\", line 195, in accept\nOSError: [Errno 24] Too many open files\n\n[17\/May\/2019:22:32:27] ENGINE Error in HTTPServer.tick\nTraceback (most recent call last):\n  File \"\/usr\/local\/lib\/python3.5\/dist-packages\/cheroot\/server.py\", line 1721, in serve\n  File \"\/usr\/local\/lib\/python3.5\/dist-packages\/cheroot\/server.py\", line 1899, in tick\n  File \"\/usr\/lib\/python3.5\/socket.py\", line 195, in accept\nOSError: [Errno 24] Too many open files\n\n[17\/May\/2019:22:32:27] ENGINE Error in HTTPServer.tick\nTraceback (most recent call last):\n  File \"\/usr\/local\/lib\/python3.5\/dist-packages\/cheroot\/server.py\", line 1721, in serve\n  File \"\/usr\/local\/lib\/python3.5\/dist-packages\/cheroot\/server.py\", line 1899, in tick\n  File \"\/usr\/lib\/python3.5\/socket.py\", line 195, in accept\nOSError: [Errno 24] Too many open files\n\n[17\/May\/2019:22:32:27] ENGINE Error in HTTPServer.tick\nTraceback (most recent call last):\n  File \"\/usr\/local\/lib\/python3.5\/dist-packages\/cheroot\/server.py\", line 1721, in serve\n  File \"\/usr\/local\/lib\/python3.5\/dist-packages\/cheroot\/server.py\", line 1899, in tick\n  File \"\/usr\/lib\/python3.5\/socket.py\", line 195, in accept\nOSError: [Errno 24] Too many open files\n\n[17\/May\/2019:22:32:27] ENGINE Error in HTTPServer.tick\nTraceback (most recent call last):\n  File \"\/usr\/local\/lib\/python3.5\/dist-packages\/cheroot\/server.py\", line 1721, in serve\n  File \"\/usr\/local\/lib\/python3.5\/dist-packages\/cheroot\/server.py\", line 1899, in tick\n  File \"\/usr\/lib\/python3.5\/socket.py\", line 195, in accept\nOSError: [Errno 24] Too many open files\n\n[17\/May\/2019:22:32:27] ENGINE Error in HTTPServer.tick\nTraceback (most recent call last):\n  File \"\/usr\/local\/lib\/python3.5\/dist-packages\/cheroot\/server.py\", line 1721, in serve\n  File \"\/usr\/local\/lib\/python3.5\/dist-packages\/cheroot\/server.py\", line 1899, in tick\n  File \"\/usr\/lib\/python3.5\/socket.py\", line 195, in accept\nOSError: [Errno 24] Too many open files\n\n[17\/May\/2019:22:32:27] ENGINE Error in HTTPServer.tick\nTraceback (most recent call last):\n  File \"\/usr\/local\/lib\/python3.5\/dist-packages\/cheroot\/server.py\", line 1721, in serve\n  File \"\/usr\/local\/lib\/python3.5\/dist-packages\/cheroot\/server.py\", line 1899, in tick\n  File \"\/usr\/lib\/python3.5\/socket.py\", line 195, in accept\nOSError: [Errno 24] Too many open files\n",
        "ts": "1558132255.002100",
        "username": "edhrecbot",
        "icons": {
            "emoji": ":robot_face:",
            "image_64": "https:\/\/a.slack-edge.com\/37d58\/img\/emoji_2017_12_06\/apple\/1f916.png"
        },
        "bot_id": "B2867AJ5C"
    },
    {
        "type": "message",
        "subtype": "bot_message",
        "text": "[17\/May\/2019:22:32:27] ENGINE Error in HTTPServer.tick\nTraceback (most recent call last):\n  File \"\/usr\/local\/lib\/python3.5\/dist-packages\/cheroot\/server.py\", line 1721, in serve\n  File \"\/usr\/local\/lib\/python3.5\/dist-packages\/cheroot\/server.py\", line 1899, in tick\n  File \"\/usr\/lib\/python3.5\/socket.py\", line 195, in accept\nOSError: [Errno 24] Too many open files\n\n[17\/May\/2019:22:32:27] ENGINE Error in HTTPServer.tick\nTraceback (most recent call last):\n  File \"\/usr\/local\/lib\/python3.5\/dist-packages\/cheroot\/server.py\", line 1721, in serve\n  File \"\/usr\/local\/lib\/python3.5\/dist-packages\/cheroot\/server.py\", line 1899, in tick\n  File \"\/usr\/lib\/python3.5\/socket.py\", line 195, in accept\nOSError: [Errno 24] Too many open files\n\n[17\/May\/2019:22:32:27] ENGINE Error in HTTPServer.tick\nTraceback (most recent call last):\n  File \"\/usr\/local\/lib\/python3.5\/dist-packages\/cheroot\/server.py\", line 1721, in serve\n  File \"\/usr\/local\/lib\/python3.5\/dist-packages\/cheroot\/server.py\", line 1899, in tick\n  File \"\/usr\/lib\/python3.5\/socket.py\", line 195, in accept\nOSError: [Errno 24] Too many open files\n\n[17\/May\/2019:22:32:27] ENGINE Error in HTTPServer.tick\nTraceback (most recent call last):\n  File \"\/usr\/local\/lib\/python3.5\/dist-packages\/cheroot\/server.py\", line 1721, in serve\n  File \"\/usr\/local\/lib\/python3.5\/dist-packages\/cheroot\/server.py\", line 1899, in tick\n  File \"\/usr\/lib\/python3.5\/socket.py\", line 195, in accept\nOSError: [Errno 24] Too many open files\n\n[17\/May\/2019:22:32:27] ENGINE Error in HTTPServer.tick\nTraceback (most recent call last):\n  File \"\/usr\/local\/lib\/python3.5\/dist-packages\/cheroot\/server.py\", line 1721, in serve\n  File \"\/usr\/local\/lib\/python3.5\/dist-packages\/cheroot\/server.py\", line 1899, in tick\n  File \"\/usr\/lib\/python3.5\/socket.py\", line 195, in accept\nOSError: [Errno 24] Too many open files\n\n[17\/May\/2019:22:32:27] ENGINE Error in HTTPServer.tick\nTraceback (most recent call last):\n  File \"\/usr\/local\/lib\/python3.5\/dist-packages\/cheroot\/server.py\", line 1721, in serve\n  File \"\/usr\/local\/lib\/python3.5\/dist-packages\/cheroot\/server.py\", line 1899, in tick\n  File \"\/usr\/lib\/python3.5\/socket.py\", line 195, in accept\nOSError: [Errno 24] Too many open files\n\n[17\/May\/2019:22:32:27] ENGINE Error in HTTPServer.tick\nTraceback (most recent call last):\n  File \"\/usr\/local\/lib\/python3.5\/dist-packages\/cheroot\/server.py\", line 1721, in serve\n  File \"\/usr\/local\/lib\/python3.5\/dist-packages\/cheroot\/server.py\", line 1899, in tick\n  File \"\/usr\/lib\/python3.5\/socket.py\", line 195, in accept\nOSError: [Errno 24] Too many open files\n\n[17\/May\/2019:22:32:27] ENGINE Error in HTTPServer.tick\nTraceback (most recent call last):\n  File \"\/usr\/local\/lib\/python3.5\/dist-packages\/cheroot\/server.py\", line 1721, in serve\n  File \"\/usr\/local\/lib\/python3.5\/dist-packages\/cheroot\/server.py\", line 1899, in tick\n  File \"\/usr\/lib\/python3.5\/socket.py\", line 195, in accept\nOSError: [Errno 24] Too many open files\n\n[17\/May\/2019:22:32:27] ENGINE Error in HTTPServer.tick\nTraceback (most recent call last):\n  File \"\/usr\/local\/lib\/python3.5\/dist-packages\/cheroot\/server.py\", line 1721, in serve\n  File \"\/usr\/local\/lib\/python3.5\/dist-packages\/cheroot\/server.py\", line 1899, in tick\n  File \"\/usr\/lib\/python3.5\/socket.py\", line 195, in accept\nOSError: [Errno 24] Too many open files\n\n[17\/May\/2019:22:32:27] ENGINE Error in HTTPServer.tick\nTraceback (most recent call last):\n  File \"\/usr\/local\/lib\/python3.5\/dist-packages\/cheroot\/server.py\", line 1721, in serve\n  File \"\/usr\/local\/lib\/python3.5\/dist-packages\/cheroot\/server.py\", line 1899, in tick\n  File \"\/usr\/lib\/python3.5\/socket.py\", line 195, in accept\nOSError: [Errno 24] Too many open files\n\n[17\/May\/2019:22:32:27] ENGINE Error in HTTPServer.tick\nTraceback (most recent call last):\n  File \"\/usr\/local\/lib\/python3.5\/dist-packages\/cheroot\/server.py\", line 1721, in serve\n  File \"\/usr\/local\/lib\/python3.5\/dist-packages\/cheroot\/server.py\", line 1899, in tick\n  File \"\/usr\/lib\/python3.5\/socket.py\", line 195, in accept\nOSError: [Errno 24] Too many open files\n",
        "ts": "1558132255.002200",
        "username": "edhrecbot",
        "icons": {
            "emoji": ":robot_face:",
            "image_64": "https:\/\/a.slack-edge.com\/37d58\/img\/emoji_2017_12_06\/apple\/1f916.png"
        },
        "bot_id": "B2867AJ5C"
    },
    {
        "type": "message",
        "subtype": "bot_message",
        "text": "[17\/May\/2019:22:32:27] ENGINE Error in HTTPServer.tick\nTraceback (most recent call last):\n  File \"\/usr\/local\/lib\/python3.5\/dist-packages\/cheroot\/server.py\", line 1721, in serve\n  File \"\/usr\/local\/lib\/python3.5\/dist-packages\/cheroot\/server.py\", line 1899, in tick\n  File \"\/usr\/lib\/python3.5\/socket.py\", line 195, in accept\nOSError: [Errno 24] Too many open files\n\n[17\/May\/2019:22:32:27] ENGINE Error in HTTPServer.tick\nTraceback (most recent call last):\n  File \"\/usr\/local\/lib\/python3.5\/dist-packages\/cheroot\/server.py\", line 1721, in serve\n  File \"\/usr\/local\/lib\/python3.5\/dist-packages\/cheroot\/server.py\", line 1899, in tick\n  File \"\/usr\/lib\/python3.5\/socket.py\", line 195, in accept\nOSError: [Errno 24] Too many open files\n\n[17\/May\/2019:22:32:27] ENGINE Error in HTTPServer.tick\nTraceback (most recent call last):\n  File \"\/usr\/local\/lib\/python3.5\/dist-packages\/cheroot\/server.py\", line 1721, in serve\n  File \"\/usr\/local\/lib\/python3.5\/dist-packages\/cheroot\/server.py\", line 1899, in tick\n  File \"\/usr\/lib\/python3.5\/socket.py\", line 195, in accept\nOSError: [Errno 24] Too many open files\n\n[17\/May\/2019:22:32:27] ENGINE Error in HTTPServer.tick\nTraceback (most recent call last):\n  File \"\/usr\/local\/lib\/python3.5\/dist-packages\/cheroot\/server.py\", line 1721, in serve\n  File \"\/usr\/local\/lib\/python3.5\/dist-packages\/cheroot\/server.py\", line 1899, in tick\n  File \"\/usr\/lib\/python3.5\/socket.py\", line 195, in accept\nOSError: [Errno 24] Too many open files\n\n[17\/May\/2019:22:32:27] ENGINE Error in HTTPServer.tick\nTraceback (most recent call last):\n  File \"\/usr\/local\/lib\/python3.5\/dist-packages\/cheroot\/server.py\", line 1721, in serve\n  File \"\/usr\/local\/lib\/python3.5\/dist-packages\/cheroot\/server.py\", line 1899, in tick\n  File \"\/usr\/lib\/python3.5\/socket.py\", line 195, in accept\nOSError: [Errno 24] Too many open files\n\n[17\/May\/2019:22:32:27] ENGINE Error in HTTPServer.tick\nTraceback (most recent call last):\n  File \"\/usr\/local\/lib\/python3.5\/dist-packages\/cheroot\/server.py\", line 1721, in serve\n  File \"\/usr\/local\/lib\/python3.5\/dist-packages\/cheroot\/server.py\", line 1899, in tick\n  File \"\/usr\/lib\/python3.5\/socket.py\", line 195, in accept\nOSError: [Errno 24] Too many open files\n\n[17\/May\/2019:22:32:27] ENGINE Error in HTTPServer.tick\nTraceback (most recent call last):\n  File \"\/usr\/local\/lib\/python3.5\/dist-packages\/cheroot\/server.py\", line 1721, in serve\n  File \"\/usr\/local\/lib\/python3.5\/dist-packages\/cheroot\/server.py\", line 1899, in tick\n  File \"\/usr\/lib\/python3.5\/socket.py\", line 195, in accept\nOSError: [Errno 24] Too many open files\n\n[17\/May\/2019:22:32:27] ENGINE Error in HTTPServer.tick\nTraceback (most recent call last):\n  File \"\/usr\/local\/lib\/python3.5\/dist-packages\/cheroot\/server.py\", line 1721, in serve\n  File \"\/usr\/local\/lib\/python3.5\/dist-packages\/cheroot\/server.py\", line 1899, in tick\n  File \"\/usr\/lib\/python3.5\/socket.py\", line 195, in accept\nOSError: [Errno 24] Too many open files\n\n[17\/May\/2019:22:32:27] ENGINE Error in HTTPServer.tick\nTraceback (most recent call last):\n  File \"\/usr\/local\/lib\/python3.5\/dist-packages\/cheroot\/server.py\", line 1721, in serve\n  File \"\/usr\/local\/lib\/python3.5\/dist-packages\/cheroot\/server.py\", line 1899, in tick\n  File \"\/usr\/lib\/python3.5\/socket.py\", line 195, in accept\nOSError: [Errno 24] Too many open files\n\n[17\/May\/2019:22:32:27] ENGINE Error in HTTPServer.tick\nTraceback (most recent call last):\n  File \"\/usr\/local\/lib\/python3.5\/dist-packages\/cheroot\/server.py\", line 1721, in serve\n  File \"\/usr\/local\/lib\/python3.5\/dist-packages\/cheroot\/server.py\", line 1899, in tick\n  File \"\/usr\/lib\/python3.5\/socket.py\", line 195, in accept\nOSError: [Errno 24] Too many open files\n\n[17\/May\/2019:22:32:27] ENGINE Error in HTTPServer.tick\nTraceback (most recent call last):\n  File \"\/usr\/local\/lib\/python3.5\/dist-packages\/cheroot\/server.py\", line 1721, in serve\n  File \"\/usr\/local\/lib\/python3.5\/dist-packages\/cheroot\/server.py\", line 1899, in tick\n  File \"\/usr\/lib\/python3.5\/socket.py\", line 195, in accept\nOSError: [Errno 24] Too many open files\n",
        "ts": "1558132255.002300",
        "username": "edhrecbot",
        "icons": {
            "emoji": ":robot_face:",
            "image_64": "https:\/\/a.slack-edge.com\/37d58\/img\/emoji_2017_12_06\/apple\/1f916.png"
        },
        "bot_id": "B2867AJ5C"
    },
    {
        "type": "message",
        "subtype": "bot_message",
        "text": "[17\/May\/2019:22:32:27] ENGINE Error in HTTPServer.tick\nTraceback (most recent call last):\n  File \"\/usr\/local\/lib\/python3.5\/dist-packages\/cheroot\/server.py\", line 1721, in serve\n  File \"\/usr\/local\/lib\/python3.5\/dist-packages\/cheroot\/server.py\", line 1899, in tick\n  File \"\/usr\/lib\/python3.5\/socket.py\", line 195, in accept\nOSError: [Errno 24] Too many open files\n\n[17\/May\/2019:22:32:27] ENGINE Error in HTTPServer.tick\nTraceback (most recent call last):\n  File \"\/usr\/local\/lib\/python3.5\/dist-packages\/cheroot\/server.py\", line 1721, in serve\n  File \"\/usr\/local\/lib\/python3.5\/dist-packages\/cheroot\/server.py\", line 1899, in tick\n  File \"\/usr\/lib\/python3.5\/socket.py\", line 195, in accept\nOSError: [Errno 24] Too many open files\n\n[17\/May\/2019:22:32:27] ENGINE Error in HTTPServer.tick\nTraceback (most recent call last):\n  File \"\/usr\/local\/lib\/python3.5\/dist-packages\/cheroot\/server.py\", line 1721, in serve\n  File \"\/usr\/local\/lib\/python3.5\/dist-packages\/cheroot\/server.py\", line 1899, in tick\n  File \"\/usr\/lib\/python3.5\/socket.py\", line 195, in accept\nOSError: [Errno 24] Too many open files\n\n[17\/May\/2019:22:32:27] ENGINE Error in HTTPServer.tick\nTraceback (most recent call last):\n  File \"\/usr\/local\/lib\/python3.5\/dist-packages\/cheroot\/server.py\", line 1721, in serve\n  File \"\/usr\/local\/lib\/python3.5\/dist-packages\/cheroot\/server.py\", line 1899, in tick\n  File \"\/usr\/lib\/python3.5\/socket.py\", line 195, in accept\nOSError: [Errno 24] Too many open files\n\n[17\/May\/2019:22:32:27] ENGINE Error in HTTPServer.tick\nTraceback (most recent call last):\n  File \"\/usr\/local\/lib\/python3.5\/dist-packages\/cheroot\/server.py\", line 1721, in serve\n  File \"\/usr\/local\/lib\/python3.5\/dist-packages\/cheroot\/server.py\", line 1899, in tick\n  File \"\/usr\/lib\/python3.5\/socket.py\", line 195, in accept\nOSError: [Errno 24] Too many open files\n\n[17\/May\/2019:22:32:27] ENGINE Error in HTTPServer.tick\nTraceback (most recent call last):\n  File \"\/usr\/local\/lib\/python3.5\/dist-packages\/cheroot\/server.py\", line 1721, in serve\n  File \"\/usr\/local\/lib\/python3.5\/dist-packages\/cheroot\/server.py\", line 1899, in tick\n  File \"\/usr\/lib\/python3.5\/socket.py\", line 195, in accept\nOSError: [Errno 24] Too many open files\n\n[17\/May\/2019:22:32:27] ENGINE Error in HTTPServer.tick\nTraceback (most recent call last):\n  File \"\/usr\/local\/lib\/python3.5\/dist-packages\/cheroot\/server.py\", line 1721, in serve\n  File \"\/usr\/local\/lib\/python3.5\/dist-packages\/cheroot\/server.py\", line 1899, in tick\n  File \"\/usr\/lib\/python3.5\/socket.py\", line 195, in accept\nOSError: [Errno 24] Too many open files\n\n[17\/May\/2019:22:32:27] ENGINE Error in HTTPServer.tick\nTraceback (most recent call last):\n  File \"\/usr\/local\/lib\/python3.5\/dist-packages\/cheroot\/server.py\", line 1721, in serve\n  File \"\/usr\/local\/lib\/python3.5\/dist-packages\/cheroot\/server.py\", line 1899, in tick\n  File \"\/usr\/lib\/python3.5\/socket.py\", line 195, in accept\nOSError: [Errno 24] Too many open files\n\n[17\/May\/2019:22:32:27] ENGINE Error in HTTPServer.tick\nTraceback (most recent call last):\n  File \"\/usr\/local\/lib\/python3.5\/dist-packages\/cheroot\/server.py\", line 1721, in serve\n  File \"\/usr\/local\/lib\/python3.5\/dist-packages\/cheroot\/server.py\", line 1899, in tick\n  File \"\/usr\/lib\/python3.5\/socket.py\", line 195, in accept\nOSError: [Errno 24] Too many open files\n\n[17\/May\/2019:22:32:27] ENGINE Error in HTTPServer.tick\nTraceback (most recent call last):\n  File \"\/usr\/local\/lib\/python3.5\/dist-packages\/cheroot\/server.py\", line 1721, in serve\n  File \"\/usr\/local\/lib\/python3.5\/dist-packages\/cheroot\/server.py\", line 1899, in tick\n  File \"\/usr\/lib\/python3.5\/socket.py\", line 195, in accept\nOSError: [Errno 24] Too many open files\n\n[17\/May\/2019:22:32:27] ENGINE Error in HTTPServer.tick\nTraceback (most recent call last):\n  File \"\/usr\/local\/lib\/python3.5\/dist-packages\/cheroot\/server.py\", line 1721, in serve\n  File \"\/usr\/local\/lib\/python3.5\/dist-packages\/cheroot\/server.py\", line 1899, in tick\n  File \"\/usr\/lib\/python3.5\/socket.py\", line 195, in accept\nOSError: [Errno 24] Too many open files\n",
        "ts": "1558132255.002400",
        "username": "edhrecbot",
        "icons": {
            "emoji": ":robot_face:",
            "image_64": "https:\/\/a.slack-edge.com\/37d58\/img\/emoji_2017_12_06\/apple\/1f916.png"
        },
        "bot_id": "B2867AJ5C"
    },
    {
        "type": "message",
        "subtype": "bot_message",
        "text": "```[17\/May\/2019:22:32:28] ENGINE Error in HTTPServer.tick\nTraceback (most recent call last):\n  File \"\/usr\/local\/lib\/python3.5\/dist-packages\/cheroot\/server.py\", line 1721, in serve\n  File \"\/usr\/local\/lib\/python3.5\/dist-packages\/cheroot\/server.py\", line 1899, in tick\n  File \"\/usr\/lib\/python3.5\/socket.py\", line 195, in accept\nOSError: [Errno 24] Too many open files\n\n```",
        "ts": "1558132255.002500",
        "username": "edhrecbot",
        "icons": {
            "emoji": ":robot_face:",
            "image_64": "https:\/\/a.slack-edge.com\/37d58\/img\/emoji_2017_12_06\/apple\/1f916.png"
        },
        "bot_id": "B2867AJ5C"
    },
    {
        "type": "message",
        "subtype": "bot_message",
        "text": "```[17\/May\/2019:22:32:29] ENGINE Error in HTTPServer.tick\nTraceback (most recent call last):\n  File \"\/usr\/local\/lib\/python3.5\/dist-packages\/cheroot\/server.py\", line 1721, in serve\n  File \"\/usr\/local\/lib\/python3.5\/dist-packages\/cheroot\/server.py\", line 1899, in tick\n  File \"\/usr\/lib\/python3.5\/socket.py\", line 195, in accept\nOSError: [Errno 24] Too many open files\n\n```",
        "ts": "1558132255.002600",
        "username": "edhrecbot",
        "icons": {
            "emoji": ":robot_face:",
            "image_64": "https:\/\/a.slack-edge.com\/37d58\/img\/emoji_2017_12_06\/apple\/1f916.png"
        },
        "bot_id": "B2867AJ5C"
    },
    {
        "type": "message",
        "subtype": "bot_message",
        "text": "```[17\/May\/2019:22:32:29] ENGINE Error in HTTPServer.tick\nTraceback (most recent call last):\n  File \"\/usr\/local\/lib\/python3.5\/dist-packages\/cheroot\/server.py\", line 1721, in serve\n  File \"\/usr\/local\/lib\/python3.5\/dist-packages\/cheroot\/server.py\", line 1899, in tick\n  File \"\/usr\/lib\/python3.5\/socket.py\", line 195, in accept\nOSError: [Errno 24] Too many open files\n\n[17\/May\/2019:22:32:29] ENGINE Error in HTTPServer.tick\nTraceback (most recent call last):\n  File \"\/usr\/local\/lib\/python3.5\/dist-packages\/cheroot\/server.py\", line 1721, in serve\n  File \"\/usr\/local\/lib\/python3.5\/dist-packages\/cheroot\/server.py\", line 1899, in tick\n  File \"\/usr\/lib\/python3.5\/socket.py\", line 195, in accept\nOSError: [Errno 24] Too many open files\n\n```",
        "ts": "1558132255.002700",
        "username": "edhrecbot",
        "icons": {
            "emoji": ":robot_face:",
            "image_64": "https:\/\/a.slack-edge.com\/37d58\/img\/emoji_2017_12_06\/apple\/1f916.png"
        },
        "bot_id": "B2867AJ5C"
    },
    {
        "type": "message",
        "subtype": "bot_message",
        "text": "```[17\/May\/2019:22:32:29] ENGINE Error in HTTPServer.tick\nTraceback (most recent call last):\n  File \"\/usr\/local\/lib\/python3.5\/dist-packages\/cheroot\/server.py\", line 1721, in serve\n  File \"\/usr\/local\/lib\/python3.5\/dist-packages\/cheroot\/server.py\", line 1899, in tick\n  File \"\/usr\/lib\/python3.5\/socket.py\", line 195, in accept\nOSError: [Errno 24] Too many open files\n\n[17\/May\/2019:22:32:29] ENGINE Error in HTTPServer.tick\nTraceback (most recent call last):\n  File \"\/usr\/local\/lib\/python3.5\/dist-packages\/cheroot\/server.py\", line 1721, in serve\n  File \"\/usr\/local\/lib\/python3.5\/dist-packages\/cheroot\/server.py\", line 1899, in tick\n  File \"\/usr\/lib\/python3.5\/socket.py\", line 195, in accept\nOSError: [Errno 24] Too many open files\n\n```",
        "ts": "1558132256.002800",
        "username": "edhrecbot",
        "icons": {
            "emoji": ":robot_face:",
            "image_64": "https:\/\/a.slack-edge.com\/37d58\/img\/emoji_2017_12_06\/apple\/1f916.png"
        },
        "bot_id": "B2867AJ5C"
    },
    {
        "type": "message",
        "subtype": "bot_message",
        "text": "```[17\/May\/2019:22:32:29] ENGINE Error in HTTPServer.tick\nTraceback (most recent call last):\n  File \"\/usr\/local\/lib\/python3.5\/dist-packages\/cheroot\/server.py\", line 1721, in serve\n  File \"\/usr\/local\/lib\/python3.5\/dist-packages\/cheroot\/server.py\", line 1899, in tick\n  File \"\/usr\/lib\/python3.5\/socket.py\", line 195, in accept\nOSError: [Errno 24] Too many open files\n\n```",
        "ts": "1558132256.002900",
        "username": "edhrecbot",
        "icons": {
            "emoji": ":robot_face:",
            "image_64": "https:\/\/a.slack-edge.com\/37d58\/img\/emoji_2017_12_06\/apple\/1f916.png"
        },
        "bot_id": "B2867AJ5C"
    },
    {
        "type": "message",
        "subtype": "bot_message",
        "text": "```[17\/May\/2019:22:32:30] ENGINE Error in HTTPServer.tick\nTraceback (most recent call last):\n  File \"\/usr\/local\/lib\/python3.5\/dist-packages\/cheroot\/server.py\", line 1721, in serve\n  File \"\/usr\/local\/lib\/python3.5\/dist-packages\/cheroot\/server.py\", line 1899, in tick\n  File \"\/usr\/lib\/python3.5\/socket.py\", line 195, in accept\nOSError: [Errno 24] Too many open files\n\n[17\/May\/2019:22:32:30] ENGINE Error in HTTPServer.tick\nTraceback (most recent call last):\n  File \"\/usr\/local\/lib\/python3.5\/dist-packages\/cheroot\/server.py\", line 1721, in serve\n  File \"\/usr\/local\/lib\/python3.5\/dist-packages\/cheroot\/server.py\", line 1899, in tick\n  File \"\/usr\/lib\/python3.5\/socket.py\", line 195, in accept\nOSError: [Errno 24] Too many open files\n\n```",
        "ts": "1558132256.003000",
        "username": "edhrecbot",
        "icons": {
            "emoji": ":robot_face:",
            "image_64": "https:\/\/a.slack-edge.com\/37d58\/img\/emoji_2017_12_06\/apple\/1f916.png"
        },
        "bot_id": "B2867AJ5C"
    },
    {
        "type": "message",
        "subtype": "bot_message",
        "text": "```[17\/May\/2019:22:32:30] ENGINE Error in HTTPServer.tick\nTraceback (most recent call last):\n  File \"\/usr\/local\/lib\/python3.5\/dist-packages\/cheroot\/server.py\", line 1721, in serve\n  File \"\/usr\/local\/lib\/python3.5\/dist-packages\/cheroot\/server.py\", line 1899, in tick\n  File \"\/usr\/lib\/python3.5\/socket.py\", line 195, in accept\nOSError: [Errno 24] Too many open files\n\n[17\/May\/2019:22:32:30] ENGINE Error in HTTPServer.tick\nTraceback (most recent call last):\n  File \"\/usr\/local\/lib\/python3.5\/dist-packages\/cheroot\/server.py\", line 1721, in serve\n  File \"\/usr\/local\/lib\/python3.5\/dist-packages\/cheroot\/server.py\", line 1899, in tick\n  File \"\/usr\/lib\/python3.5\/socket.py\", line 195, in accept\nOSError: [Errno 24] Too many open files\n\n[17\/May\/2019:22:32:30] ENGINE Error in HTTPServer.tick\nTraceback (most recent call last):\n  File \"\/usr\/local\/lib\/python3.5\/dist-packages\/cheroot\/server.py\", line 1721, in serve\n  File \"\/usr\/local\/lib\/python3.5\/dist-packages\/cheroot\/server.py\", line 1899, in tick\n  File \"\/usr\/lib\/python3.5\/socket.py\", line 195, in accept\nOSError: [Errno 24] Too many open files\n\n[17\/May\/2019:22:32:30] ENGINE Error in HTTPServer.tick\nTraceback (most recent call last):\n  File \"\/usr\/local\/lib\/python3.5\/dist-packages\/cheroot\/server.py\", line 1721, in serve\n  File \"\/usr\/local\/lib\/python3.5\/dist-packages\/cheroot\/server.py\", line 1899, in tick\n  File \"\/usr\/lib\/python3.5\/socket.py\", line 195, in accept\nOSError: [Errno 24] Too many open files\n\n[17\/May\/2019:22:32:30] ENGINE Error in HTTPServer.tick\nTraceback (most recent call last):\n  File \"\/usr\/local\/lib\/python3.5\/dist-packages\/cheroot\/server.py\", line 1721, in serve\n  File \"\/usr\/local\/lib\/python3.5\/dist-packages\/cheroot\/server.py\", line 1899, in tick\n  File \"\/usr\/lib\/python3.5\/socket.py\", line 195, in accept\nOSError: [Errno 24] Too many open files\n\n[17\/May\/2019:22:32:30] ENGINE Error in HTTPServer.tick\nTraceback (most recent call last):\n  File \"\/usr\/local\/lib\/python3.5\/dist-packages\/cheroot\/server.py\", line 1721, in serve\n  File \"\/usr\/local\/lib\/python3.5\/dist-packages\/cheroot\/server.py\", line 1899, in tick\n  File \"\/usr\/lib\/python3.5\/socket.py\", line 195, in accept\nOSError: [Errno 24] Too many open files\n\n[17\/May\/2019:22:32:30] ENGINE Error in HTTPServer.tick\nTraceback (most recent call last):\n  File \"\/usr\/local\/lib\/python3.5\/dist-packages\/cheroot\/server.py\", line 1721, in serve\n  File \"\/usr\/local\/lib\/python3.5\/dist-packages\/cheroot\/server.py\", line 1899, in tick\n  File \"\/usr\/lib\/python3.5\/socket.py\", line 195, in accept\nOSError: [Errno 24] Too many open files\n\n```",
        "ts": "1558132256.003100",
        "username": "edhrecbot",
        "icons": {
            "emoji": ":robot_face:",
            "image_64": "https:\/\/a.slack-edge.com\/37d58\/img\/emoji_2017_12_06\/apple\/1f916.png"
        },
        "bot_id": "B2867AJ5C"
    },
    {
        "type": "message",
        "subtype": "bot_message",
        "text": "```[17\/May\/2019:22:32:30] ENGINE Error in HTTPServer.tick\nTraceback (most recent call last):\n  File \"\/usr\/local\/lib\/python3.5\/dist-packages\/cheroot\/server.py\", line 1721, in serve\n  File \"\/usr\/local\/lib\/python3.5\/dist-packages\/cheroot\/server.py\", line 1899, in tick\n  File \"\/usr\/lib\/python3.5\/socket.py\", line 195, in accept\nOSError: [Errno 24] Too many open files\n\n```",
        "ts": "1558132257.003200",
        "username": "edhrecbot",
        "icons": {
            "emoji": ":robot_face:",
            "image_64": "https:\/\/a.slack-edge.com\/37d58\/img\/emoji_2017_12_06\/apple\/1f916.png"
        },
        "bot_id": "B2867AJ5C"
    },
    {
        "type": "message",
        "subtype": "bot_message",
        "text": "```[17\/May\/2019:22:32:30] ENGINE Error in HTTPServer.tick\nTraceback (most recent call last):\n  File \"\/usr\/local\/lib\/python3.5\/dist-packages\/cheroot\/server.py\", line 1721, in serve\n  File \"\/usr\/local\/lib\/python3.5\/dist-packages\/cheroot\/server.py\", line 1899, in tick\n  File \"\/usr\/lib\/python3.5\/socket.py\", line 195, in accept\nOSError: [Errno 24] Too many open files\n\n```",
        "ts": "1558132257.003300",
        "username": "edhrecbot",
        "icons": {
            "emoji": ":robot_face:",
            "image_64": "https:\/\/a.slack-edge.com\/37d58\/img\/emoji_2017_12_06\/apple\/1f916.png"
        },
        "bot_id": "B2867AJ5C"
    },
    {
        "type": "message",
        "subtype": "bot_message",
        "text": "```[17\/May\/2019:22:32:31] ENGINE Error in HTTPServer.tick\nTraceback (most recent call last):\n  File \"\/usr\/local\/lib\/python3.5\/dist-packages\/cheroot\/server.py\", line 1721, in serve\n  File \"\/usr\/local\/lib\/python3.5\/dist-packages\/cheroot\/server.py\", line 1899, in tick\n  File \"\/usr\/lib\/python3.5\/socket.py\", line 195, in accept\nOSError: [Errno 24] Too many open files\n\n```",
        "ts": "1558132257.003400",
        "username": "edhrecbot",
        "icons": {
            "emoji": ":robot_face:",
            "image_64": "https:\/\/a.slack-edge.com\/37d58\/img\/emoji_2017_12_06\/apple\/1f916.png"
        },
        "bot_id": "B2867AJ5C"
    },
    {
        "type": "message",
        "subtype": "bot_message",
        "text": "```[17\/May\/2019:22:32:31] ENGINE Error in HTTPServer.tick\nTraceback (most recent call last):\n  File \"\/usr\/local\/lib\/python3.5\/dist-packages\/cheroot\/server.py\", line 1721, in serve\n  File \"\/usr\/local\/lib\/python3.5\/dist-packages\/cheroot\/server.py\", line 1899, in tick\n  File \"\/usr\/lib\/python3.5\/socket.py\", line 195, in accept\nOSError: [Errno 24] Too many open files\n\n[17\/May\/2019:22:32:31] ENGINE Error in HTTPServer.tick\nTraceback (most recent call last):\n  File \"\/usr\/local\/lib\/python3.5\/dist-packages\/cheroot\/server.py\", line 1721, in serve\n  File \"\/usr\/local\/lib\/python3.5\/dist-packages\/cheroot\/server.py\", line 1899, in tick\n  File \"\/usr\/lib\/python3.5\/socket.py\", line 195, in accept\nOSError: [Errno 24] Too many open files\n\n```",
        "ts": "1558132257.003500",
        "username": "edhrecbot",
        "icons": {
            "emoji": ":robot_face:",
            "image_64": "https:\/\/a.slack-edge.com\/37d58\/img\/emoji_2017_12_06\/apple\/1f916.png"
        },
        "bot_id": "B2867AJ5C"
    },
    {
        "type": "message",
        "subtype": "bot_message",
        "text": "```[17\/May\/2019:22:32:31] ENGINE Error in HTTPServer.tick\nTraceback (most recent call last):\n  File \"\/usr\/local\/lib\/python3.5\/dist-packages\/cheroot\/server.py\", line 1721, in serve\n  File \"\/usr\/local\/lib\/python3.5\/dist-packages\/cheroot\/server.py\", line 1899, in tick\n  File \"\/usr\/lib\/python3.5\/socket.py\", line 195, in accept\nOSError: [Errno 24] Too many open files\n\n```",
        "ts": "1558132258.003600",
        "username": "edhrecbot",
        "icons": {
            "emoji": ":robot_face:",
            "image_64": "https:\/\/a.slack-edge.com\/37d58\/img\/emoji_2017_12_06\/apple\/1f916.png"
        },
        "bot_id": "B2867AJ5C"
    },
    {
        "type": "message",
        "subtype": "bot_message",
        "text": "```[17\/May\/2019:22:32:31] ENGINE Error in HTTPServer.tick\nTraceback (most recent call last):\n  File \"\/usr\/local\/lib\/python3.5\/dist-packages\/cheroot\/server.py\", line 1721, in serve\n  File \"\/usr\/local\/lib\/python3.5\/dist-packages\/cheroot\/server.py\", line 1899, in tick\n  File \"\/usr\/lib\/python3.5\/socket.py\", line 195, in accept\nOSError: [Errno 24] Too many open files\n\n[17\/May\/2019:22:32:31] ENGINE Error in HTTPServer.tick\nTraceback (most recent call last):\n  File \"\/usr\/local\/lib\/python3.5\/dist-packages\/cheroot\/server.py\", line 1721, in serve\n  File \"\/usr\/local\/lib\/python3.5\/dist-packages\/cheroot\/server.py\", line 1899, in tick\n  File \"\/usr\/lib\/python3.5\/socket.py\", line 195, in accept\nOSError: [Errno 24] Too many open files\n\n```",
        "ts": "1558132258.003700",
        "username": "edhrecbot",
        "icons": {
            "emoji": ":robot_face:",
            "image_64": "https:\/\/a.slack-edge.com\/37d58\/img\/emoji_2017_12_06\/apple\/1f916.png"
        },
        "bot_id": "B2867AJ5C"
    },
    {
        "type": "message",
        "subtype": "bot_message",
        "text": "```[17\/May\/2019:22:32:32] ENGINE Error in HTTPServer.tick\nTraceback (most recent call last):\n  File \"\/usr\/local\/lib\/python3.5\/dist-packages\/cheroot\/server.py\", line 1721, in serve\n  File \"\/usr\/local\/lib\/python3.5\/dist-packages\/cheroot\/server.py\", line 1899, in tick\n  File \"\/usr\/lib\/python3.5\/socket.py\", line 195, in accept\nOSError: [Errno 24] Too many open files\n\n```",
        "ts": "1558132258.003800",
        "username": "edhrecbot",
        "icons": {
            "emoji": ":robot_face:",
            "image_64": "https:\/\/a.slack-edge.com\/37d58\/img\/emoji_2017_12_06\/apple\/1f916.png"
        },
        "bot_id": "B2867AJ5C"
    },
    {
        "type": "message",
        "subtype": "bot_message",
        "text": "```[17\/May\/2019:22:32:32] ENGINE Error in HTTPServer.tick\nTraceback (most recent call last):\n  File \"\/usr\/local\/lib\/python3.5\/dist-packages\/cheroot\/server.py\", line 1721, in serve\n  File \"\/usr\/local\/lib\/python3.5\/dist-packages\/cheroot\/server.py\", line 1899, in tick\n  File \"\/usr\/lib\/python3.5\/socket.py\", line 195, in accept\nOSError: [Errno 24] Too many open files\n\n[17\/May\/2019:22:32:32] ENGINE Error in HTTPServer.tick\nTraceback (most recent call last):\n  File \"\/usr\/local\/lib\/python3.5\/dist-packages\/cheroot\/server.py\", line 1721, in serve\n  File \"\/usr\/local\/lib\/python3.5\/dist-packages\/cheroot\/server.py\", line 1899, in tick\n  File \"\/usr\/lib\/python3.5\/socket.py\", line 195, in accept\nOSError: [Errno 24] Too many open files\n\n[17\/May\/2019:22:32:32] ENGINE Error in HTTPServer.tick\nTraceback (most recent call last):\n  File \"\/usr\/local\/lib\/python3.5\/dist-packages\/cheroot\/server.py\", line 1721, in serve\n  File \"\/usr\/local\/lib\/python3.5\/dist-packages\/cheroot\/server.py\", line 1899, in tick\n  File \"\/usr\/lib\/python3.5\/socket.py\", line 195, in accept\nOSError: [Errno 24] Too many open files\n\n[17\/May\/2019:22:32:32] ENGINE Error in HTTPServer.tick\nTraceback (most recent call last):\n  File \"\/usr\/local\/lib\/python3.5\/dist-packages\/cheroot\/server.py\", line 1721, in serve\n  File \"\/usr\/local\/lib\/python3.5\/dist-packages\/cheroot\/server.py\", line 1899, in tick\n  File \"\/usr\/lib\/python3.5\/socket.py\", line 195, in accept\nOSError: [Errno 24] Too many open files\n\n[17\/May\/2019:22:32:32] ENGINE Error in HTTPServer.tick\nTraceback (most recent call last):\n  File \"\/usr\/local\/lib\/python3.5\/dist-packages\/cheroot\/server.py\", line 1721, in serve\n  File \"\/usr\/local\/lib\/python3.5\/dist-packages\/cheroot\/server.py\", line 1899, in tick\n  File \"\/usr\/lib\/python3.5\/socket.py\", line 195, in accept\nOSError: [Errno 24] Too many open files\n\n[17\/May\/2019:22:32:32] ENGINE Error in HTTPServer.tick\nTraceback (most recent call last):\n  File \"\/usr\/local\/lib\/python3.5\/dist-packages\/cheroot\/server.py\", line 1721, in serve\n  File \"\/usr\/local\/lib\/python3.5\/dist-packages\/cheroot\/server.py\", line 1899, in tick\n  File \"\/usr\/lib\/python3.5\/socket.py\", line 195, in accept\nOSError: [Errno 24] Too many open files\n\n[17\/May\/2019:22:32:32] ENGINE Error in HTTPServer.tick\nTraceback (most recent call last):\n  File \"\/usr\/local\/lib\/python3.5\/dist-packages\/cheroot\/server.py\", line 1721, in serve\n  File \"\/usr\/local\/lib\/python3.5\/dist-packages\/cheroot\/server.py\", line 1899, in tick\n  File \"\/usr\/lib\/python3.5\/socket.py\", line 195, in accept\nOSError: [Errno 24] Too many open files\n\n[17\/May\/2019:22:32:32] ENGINE Error in HTTPServer.tick\nTraceback (most recent call last):\n  File \"\/usr\/local\/lib\/python3.5\/dist-packages\/cheroot\/server.py\", line 1721, in serve\n  File \"\/usr\/local\/lib\/python3.5\/dist-packages\/cheroot\/server.py\", line 1899, in tick\n  File \"\/usr\/lib\/python3.5\/socket.py\", line 195, in accept\nOSError: [Errno 24] Too many open files\n\n```",
        "ts": "1558132258.003900",
        "username": "edhrecbot",
        "icons": {
            "emoji": ":robot_face:",
            "image_64": "https:\/\/a.slack-edge.com\/37d58\/img\/emoji_2017_12_06\/apple\/1f916.png"
        },
        "bot_id": "B2867AJ5C"
    },
    {
        "type": "message",
        "subtype": "bot_message",
        "text": "```[17\/May\/2019:22:32:32] ENGINE Error in HTTPServer.tick\nTraceback (most recent call last):\n  File \"\/usr\/local\/lib\/python3.5\/dist-packages\/cheroot\/server.py\", line 1721, in serve\n  File \"\/usr\/local\/lib\/python3.5\/dist-packages\/cheroot\/server.py\", line 1899, in tick\n  File \"\/usr\/lib\/python3.5\/socket.py\", line 195, in accept\nOSError: [Errno 24] Too many open files\n\n```",
        "ts": "1558132259.004000",
        "username": "edhrecbot",
        "icons": {
            "emoji": ":robot_face:",
            "image_64": "https:\/\/a.slack-edge.com\/37d58\/img\/emoji_2017_12_06\/apple\/1f916.png"
        },
        "bot_id": "B2867AJ5C"
    },
    {
        "type": "message",
        "subtype": "bot_message",
        "text": "```[17\/May\/2019:22:32:33] ENGINE Error in HTTPServer.tick\nTraceback (most recent call last):\n  File \"\/usr\/local\/lib\/python3.5\/dist-packages\/cheroot\/server.py\", line 1721, in serve\n  File \"\/usr\/local\/lib\/python3.5\/dist-packages\/cheroot\/server.py\", line 1899, in tick\n  File \"\/usr\/lib\/python3.5\/socket.py\", line 195, in accept\nOSError: [Errno 24] Too many open files\n\n```",
        "ts": "1558132259.004100",
        "username": "edhrecbot",
        "icons": {
            "emoji": ":robot_face:",
            "image_64": "https:\/\/a.slack-edge.com\/37d58\/img\/emoji_2017_12_06\/apple\/1f916.png"
        },
        "bot_id": "B2867AJ5C"
    },
    {
        "type": "message",
        "subtype": "bot_message",
        "text": "```[17\/May\/2019:22:32:33] ENGINE Error in HTTPServer.tick\nTraceback (most recent call last):\n  File \"\/usr\/local\/lib\/python3.5\/dist-packages\/cheroot\/server.py\", line 1721, in serve\n  File \"\/usr\/local\/lib\/python3.5\/dist-packages\/cheroot\/server.py\", line 1899, in tick\n  File \"\/usr\/lib\/python3.5\/socket.py\", line 195, in accept\nOSError: [Errno 24] Too many open files\n\n[17\/May\/2019:22:32:33] ENGINE Error in HTTPServer.tick\nTraceback (most recent call last):\n  File \"\/usr\/local\/lib\/python3.5\/dist-packages\/cheroot\/server.py\", line 1721, in serve\n  File \"\/usr\/local\/lib\/python3.5\/dist-packages\/cheroot\/server.py\", line 1899, in tick\n  File \"\/usr\/lib\/python3.5\/socket.py\", line 195, in accept\nOSError: [Errno 24] Too many open files\n\n```",
        "ts": "1558132259.004200",
        "username": "edhrecbot",
        "icons": {
            "emoji": ":robot_face:",
            "image_64": "https:\/\/a.slack-edge.com\/37d58\/img\/emoji_2017_12_06\/apple\/1f916.png"
        },
        "bot_id": "B2867AJ5C"
    },
    {
        "type": "message",
        "subtype": "bot_message",
        "text": "```[17\/May\/2019:22:32:33] ENGINE Error in HTTPServer.tick\nTraceback (most recent call last):\n  File \"\/usr\/local\/lib\/python3.5\/dist-packages\/cheroot\/server.py\", line 1721, in serve\n  File \"\/usr\/local\/lib\/python3.5\/dist-packages\/cheroot\/server.py\", line 1899, in tick\n  File \"\/usr\/lib\/python3.5\/socket.py\", line 195, in accept\nOSError: [Errno 24] Too many open files\n\n[17\/May\/2019:22:32:33] ENGINE Error in HTTPServer.tick\nTraceback (most recent call last):\n  File \"\/usr\/local\/lib\/python3.5\/dist-packages\/cheroot\/server.py\", line 1721, in serve\n  File \"\/usr\/local\/lib\/python3.5\/dist-packages\/cheroot\/server.py\", line 1899, in tick\n  File \"\/usr\/lib\/python3.5\/socket.py\", line 195, in accept\nOSError: [Errno 24] Too many open files\n\n```",
        "ts": "1558132260.004300",
        "username": "edhrecbot",
        "icons": {
            "emoji": ":robot_face:",
            "image_64": "https:\/\/a.slack-edge.com\/37d58\/img\/emoji_2017_12_06\/apple\/1f916.png"
        },
        "bot_id": "B2867AJ5C"
    },
    {
        "type": "message",
        "subtype": "bot_message",
        "text": "```[17\/May\/2019:22:32:33] ENGINE Error in HTTPServer.tick\nTraceback (most recent call last):\n  File \"\/usr\/local\/lib\/python3.5\/dist-packages\/cheroot\/server.py\", line 1721, in serve\n  File \"\/usr\/local\/lib\/python3.5\/dist-packages\/cheroot\/server.py\", line 1899, in tick\n  File \"\/usr\/lib\/python3.5\/socket.py\", line 195, in accept\nOSError: [Errno 24] Too many open files\n\n[17\/May\/2019:22:32:33] ENGINE Error in HTTPServer.tick\nTraceback (most recent call last):\n  File \"\/usr\/local\/lib\/python3.5\/dist-packages\/cheroot\/server.py\", line 1721, in serve\n  File \"\/usr\/local\/lib\/python3.5\/dist-packages\/cheroot\/server.py\", line 1899, in tick\n  File \"\/usr\/lib\/python3.5\/socket.py\", line 195, in accept\nOSError: [Errno 24] Too many open files\n\n```",
        "ts": "1558132260.004400",
        "username": "edhrecbot",
        "icons": {
            "emoji": ":robot_face:",
            "image_64": "https:\/\/a.slack-edge.com\/37d58\/img\/emoji_2017_12_06\/apple\/1f916.png"
        },
        "bot_id": "B2867AJ5C"
    },
    {
        "type": "message",
        "subtype": "bot_message",
        "text": "```[17\/May\/2019:22:32:34] ENGINE Error in HTTPServer.tick\nTraceback (most recent call last):\n  File \"\/usr\/local\/lib\/python3.5\/dist-packages\/cheroot\/server.py\", line 1721, in serve\n  File \"\/usr\/local\/lib\/python3.5\/dist-packages\/cheroot\/server.py\", line 1899, in tick\n  File \"\/usr\/lib\/python3.5\/socket.py\", line 195, in accept\nOSError: [Errno 24] Too many open files\n\n[17\/May\/2019:22:32:34] ENGINE Error in HTTPServer.tick\nTraceback (most recent call last):\n  File \"\/usr\/local\/lib\/python3.5\/dist-packages\/cheroot\/server.py\", line 1721, in serve\n  File \"\/usr\/local\/lib\/python3.5\/dist-packages\/cheroot\/server.py\", line 1899, in tick\n  File \"\/usr\/lib\/python3.5\/socket.py\", line 195, in accept\nOSError: [Errno 24] Too many open files\n\n[17\/May\/2019:22:32:34] ENGINE Error in HTTPServer.tick\nTraceback (most recent call last):\n  File \"\/usr\/local\/lib\/python3.5\/dist-packages\/cheroot\/server.py\", line 1721, in serve\n  File \"\/usr\/local\/lib\/python3.5\/dist-packages\/cheroot\/server.py\", line 1899, in tick\n  File \"\/usr\/lib\/python3.5\/socket.py\", line 195, in accept\nOSError: [Errno 24] Too many open files\n\n```",
        "ts": "1558132260.004500",
        "username": "edhrecbot",
        "icons": {
            "emoji": ":robot_face:",
            "image_64": "https:\/\/a.slack-edge.com\/37d58\/img\/emoji_2017_12_06\/apple\/1f916.png"
        },
        "bot_id": "B2867AJ5C"
    },
    {
        "type": "message",
        "subtype": "bot_message",
        "text": "```[17\/May\/2019:22:32:34] ENGINE Error in HTTPServer.tick\nTraceback (most recent call last):\n  File \"\/usr\/local\/lib\/python3.5\/dist-packages\/cheroot\/server.py\", line 1721, in serve\n  File \"\/usr\/local\/lib\/python3.5\/dist-packages\/cheroot\/server.py\", line 1899, in tick\n  File \"\/usr\/lib\/python3.5\/socket.py\", line 195, in accept\nOSError: [Errno 24] Too many open files\n\n[17\/May\/2019:22:32:34] ENGINE Error in HTTPServer.tick\nTraceback (most recent call last):\n  File \"\/usr\/local\/lib\/python3.5\/dist-packages\/cheroot\/server.py\", line 1721, in serve\n  File \"\/usr\/local\/lib\/python3.5\/dist-packages\/cheroot\/server.py\", line 1899, in tick\n  File \"\/usr\/lib\/python3.5\/socket.py\", line 195, in accept\nOSError: [Errno 24] Too many open files\n\n```",
        "ts": "1558132260.004600",
        "username": "edhrecbot",
        "icons": {
            "emoji": ":robot_face:",
            "image_64": "https:\/\/a.slack-edge.com\/37d58\/img\/emoji_2017_12_06\/apple\/1f916.png"
        },
        "bot_id": "B2867AJ5C"
    },
    {
        "type": "message",
        "subtype": "bot_message",
        "text": "```[17\/May\/2019:22:32:34] ENGINE Error in HTTPServer.tick\nTraceback (most recent call last):\n  File \"\/usr\/local\/lib\/python3.5\/dist-packages\/cheroot\/server.py\", line 1721, in serve\n  File \"\/usr\/local\/lib\/python3.5\/dist-packages\/cheroot\/server.py\", line 1899, in tick\n  File \"\/usr\/lib\/python3.5\/socket.py\", line 195, in accept\nOSError: [Errno 24] Too many open files\n\n[17\/May\/2019:22:32:34] ENGINE Error in HTTPServer.tick\nTraceback (most recent call last):\n  File \"\/usr\/local\/lib\/python3.5\/dist-packages\/cheroot\/server.py\", line 1721, in serve\n  File \"\/usr\/local\/lib\/python3.5\/dist-packages\/cheroot\/server.py\", line 1899, in tick\n  File \"\/usr\/lib\/python3.5\/socket.py\", line 195, in accept\nOSError: [Errno 24] Too many open files\n\n[17\/May\/2019:22:32:34] ENGINE Error in HTTPServer.tick\nTraceback (most recent call last):\n  File \"\/usr\/local\/lib\/python3.5\/dist-packages\/cheroot\/server.py\", line 1721, in serve\n  File \"\/usr\/local\/lib\/python3.5\/dist-packages\/cheroot\/server.py\", line 1899, in tick\n  File \"\/usr\/lib\/python3.5\/socket.py\", line 195, in accept\nOSError: [Errno 24] Too many open files\n\n[17\/May\/2019:22:32:34] ENGINE Error in HTTPServer.tick\nTraceback (most recent call last):\n  File \"\/usr\/local\/lib\/python3.5\/dist-packages\/cheroot\/server.py\", line 1721, in serve\n  File \"\/usr\/local\/lib\/python3.5\/dist-packages\/cheroot\/server.py\", line 1899, in tick\n  File \"\/usr\/lib\/python3.5\/socket.py\", line 195, in accept\nOSError: [Errno 24] Too many open files\n\n[17\/May\/2019:22:32:34] ENGINE Error in HTTPServer.tick\nTraceback (most recent call last):\n  File \"\/usr\/local\/lib\/python3.5\/dist-packages\/cheroot\/server.py\", line 1721, in serve\n  File \"\/usr\/local\/lib\/python3.5\/dist-packages\/cheroot\/server.py\", line 1899, in tick\n  File \"\/usr\/lib\/python3.5\/socket.py\", line 195, in accept\nOSError: [Errno 24] Too many open files\n\n[17\/May\/2019:22:32:34] ENGINE Error in HTTPServer.tick\nTraceback (most recent call last):\n  File \"\/usr\/local\/lib\/python3.5\/dist-packages\/cheroot\/server.py\", line 1721, in serve\n  File \"\/usr\/local\/lib\/python3.5\/dist-packages\/cheroot\/server.py\", line 1899, in tick\n  File \"\/usr\/lib\/python3.5\/socket.py\", line 195, in accept\nOSError: [Errno 24] Too many open files\n\n[17\/May\/2019:22:32:34] ENGINE Error in HTTPServer.tick\nTraceback (most recent call last):\n  File \"\/usr\/local\/lib\/python3.5\/dist-packages\/cheroot\/server.py\", line 1721, in serve\n  File \"\/usr\/local\/lib\/python3.5\/dist-packages\/cheroot\/server.py\", line 1899, in tick\n  File \"\/usr\/lib\/python3.5\/socket.py\", line 195, in accept\nOSError: [Errno 24] Too many open files\n\n[17\/May\/2019:22:32:34] ENGINE Error in HTTPServer.tick\nTraceback (most recent call last):\n  File \"\/usr\/local\/lib\/python3.5\/dist-packages\/cheroot\/server.py\", line 1721, in serve\n  File \"\/usr\/local\/lib\/python3.5\/dist-packages\/cheroot\/server.py\", line 1899, in tick\n  File \"\/usr\/lib\/python3.5\/socket.py\", line 195, in accept\nOSError: [Errno 24] Too many open files\n\n[17\/May\/2019:22:32:34] ENGINE Error in HTTPServer.tick\nTraceback (most recent call last):\n  File \"\/usr\/local\/lib\/python3.5\/dist-packages\/cheroot\/server.py\", line 1721, in serve\n  File \"\/usr\/local\/lib\/python3.5\/dist-packages\/cheroot\/server.py\", line 1899, in tick\n  File \"\/usr\/lib\/python3.5\/socket.py\", line 195, in accept\nOSError: [Errno 24] Too many open files\n\n[17\/May\/2019:22:32:34] ENGINE Error in HTTPServer.tick\nTraceback (most recent call last):\n  File \"\/usr\/local\/lib\/python3.5\/dist-packages\/cheroot\/server.py\", line 1721, in serve\n  File \"\/usr\/local\/lib\/python3.5\/dist-packages\/cheroot\/server.py\", line 1899, in tick\n  File \"\/usr\/lib\/python3.5\/socket.py\", line 195, in accept\nOSError: [Errno 24] Too many open files\n\n[17\/May\/2019:22:32:34] ENGINE Error in HTTPServer.tick\nTraceback (most recent call last):\n  File \"\/usr\/local\/lib\/python3.5\/dist-packages\/cheroot\/server.py\", line 1721, in serve\n  File \"\/usr\/local\/lib\/python3.5\/dist-packages\/cheroot\/server.py\", line 1899, in tick\n  File \"\/usr\/lib\/python3.5\/socket.py\", line 195, in accept\nOSError: [Errno 24] Too many open files\n",
        "ts": "1558132261.004700",
        "username": "edhrecbot",
        "icons": {
            "emoji": ":robot_face:",
            "image_64": "https:\/\/a.slack-edge.com\/37d58\/img\/emoji_2017_12_06\/apple\/1f916.png"
        },
        "bot_id": "B2867AJ5C"
    },
    {
        "type": "message",
        "subtype": "bot_message",
        "text": "[17\/May\/2019:22:32:34] ENGINE Error in HTTPServer.tick\nTraceback (most recent call last):\n  File \"\/usr\/local\/lib\/python3.5\/dist-packages\/cheroot\/server.py\", line 1721, in serve\n  File \"\/usr\/local\/lib\/python3.5\/dist-packages\/cheroot\/server.py\", line 1899, in tick\n  File \"\/usr\/lib\/python3.5\/socket.py\", line 195, in accept\nOSError: [Errno 24] Too many open files\n\n[17\/May\/2019:22:32:34] ENGINE Error in HTTPServer.tick\nTraceback (most recent call last):\n  File \"\/usr\/local\/lib\/python3.5\/dist-packages\/cheroot\/server.py\", line 1721, in serve\n  File \"\/usr\/local\/lib\/python3.5\/dist-packages\/cheroot\/server.py\", line 1899, in tick\n  File \"\/usr\/lib\/python3.5\/socket.py\", line 195, in accept\nOSError: [Errno 24] Too many open files\n\n[17\/May\/2019:22:32:34] ENGINE Error in HTTPServer.tick\nTraceback (most recent call last):\n  File \"\/usr\/local\/lib\/python3.5\/dist-packages\/cheroot\/server.py\", line 1721, in serve\n  File \"\/usr\/local\/lib\/python3.5\/dist-packages\/cheroot\/server.py\", line 1899, in tick\n  File \"\/usr\/lib\/python3.5\/socket.py\", line 195, in accept\nOSError: [Errno 24] Too many open files\n\n[17\/May\/2019:22:32:34] ENGINE Error in HTTPServer.tick\nTraceback (most recent call last):\n  File \"\/usr\/local\/lib\/python3.5\/dist-packages\/cheroot\/server.py\", line 1721, in serve\n  File \"\/usr\/local\/lib\/python3.5\/dist-packages\/cheroot\/server.py\", line 1899, in tick\n  File \"\/usr\/lib\/python3.5\/socket.py\", line 195, in accept\nOSError: [Errno 24] Too many open files\n\n[17\/May\/2019:22:32:34] ENGINE Error in HTTPServer.tick\nTraceback (most recent call last):\n  File \"\/usr\/local\/lib\/python3.5\/dist-packages\/cheroot\/server.py\", line 1721, in serve\n  File \"\/usr\/local\/lib\/python3.5\/dist-packages\/cheroot\/server.py\", line 1899, in tick\n  File \"\/usr\/lib\/python3.5\/socket.py\", line 195, in accept\nOSError: [Errno 24] Too many open files\n\n```",
        "ts": "1558132261.004800",
        "username": "edhrecbot",
        "icons": {
            "emoji": ":robot_face:",
            "image_64": "https:\/\/a.slack-edge.com\/37d58\/img\/emoji_2017_12_06\/apple\/1f916.png"
        },
        "bot_id": "B2867AJ5C"
    },
    {
        "type": "message",
        "subtype": "bot_message",
        "text": "```[17\/May\/2019:22:32:34] ENGINE Error in HTTPServer.tick\nTraceback (most recent call last):\n  File \"\/usr\/local\/lib\/python3.5\/dist-packages\/cheroot\/server.py\", line 1721, in serve\n  File \"\/usr\/local\/lib\/python3.5\/dist-packages\/cheroot\/server.py\", line 1899, in tick\n  File \"\/usr\/lib\/python3.5\/socket.py\", line 195, in accept\nOSError: [Errno 24] Too many open files\n\n```",
        "ts": "1558132261.004900",
        "username": "edhrecbot",
        "icons": {
            "emoji": ":robot_face:",
            "image_64": "https:\/\/a.slack-edge.com\/37d58\/img\/emoji_2017_12_06\/apple\/1f916.png"
        },
        "bot_id": "B2867AJ5C"
    },
    {
        "type": "message",
        "subtype": "bot_message",
        "text": "```[17\/May\/2019:22:32:35] ENGINE Error in HTTPServer.tick\nTraceback (most recent call last):\n  File \"\/usr\/local\/lib\/python3.5\/dist-packages\/cheroot\/server.py\", line 1721, in serve\n  File \"\/usr\/local\/lib\/python3.5\/dist-packages\/cheroot\/server.py\", line 1899, in tick\n  File \"\/usr\/lib\/python3.5\/socket.py\", line 195, in accept\nOSError: [Errno 24] Too many open files\n\n```",
        "ts": "1558132261.005000",
        "username": "edhrecbot",
        "icons": {
            "emoji": ":robot_face:",
            "image_64": "https:\/\/a.slack-edge.com\/37d58\/img\/emoji_2017_12_06\/apple\/1f916.png"
        },
        "bot_id": "B2867AJ5C"
    },
    {
        "type": "message",
        "subtype": "bot_message",
        "text": "```[17\/May\/2019:22:32:35] ENGINE Error in HTTPServer.tick\nTraceback (most recent call last):\n  File \"\/usr\/local\/lib\/python3.5\/dist-packages\/cheroot\/server.py\", line 1721, in serve\n  File \"\/usr\/local\/lib\/python3.5\/dist-packages\/cheroot\/server.py\", line 1899, in tick\n  File \"\/usr\/lib\/python3.5\/socket.py\", line 195, in accept\nOSError: [Errno 24] Too many open files\n\n```",
        "ts": "1558132261.005100",
        "username": "edhrecbot",
        "icons": {
            "emoji": ":robot_face:",
            "image_64": "https:\/\/a.slack-edge.com\/37d58\/img\/emoji_2017_12_06\/apple\/1f916.png"
        },
        "bot_id": "B2867AJ5C"
    },
    {
        "type": "message",
        "subtype": "bot_message",
        "text": "```[17\/May\/2019:22:32:35] ENGINE Error in HTTPServer.tick\nTraceback (most recent call last):\n  File \"\/usr\/local\/lib\/python3.5\/dist-packages\/cheroot\/server.py\", line 1721, in serve\n  File \"\/usr\/local\/lib\/python3.5\/dist-packages\/cheroot\/server.py\", line 1899, in tick\n  File \"\/usr\/lib\/python3.5\/socket.py\", line 195, in accept\nOSError: [Errno 24] Too many open files\n\n```",
        "ts": "1558132262.005200",
        "username": "edhrecbot",
        "icons": {
            "emoji": ":robot_face:",
            "image_64": "https:\/\/a.slack-edge.com\/37d58\/img\/emoji_2017_12_06\/apple\/1f916.png"
        },
        "bot_id": "B2867AJ5C"
    },
    {
        "type": "message",
        "subtype": "bot_message",
        "text": "```[17\/May\/2019:22:32:35] ENGINE Error in HTTPServer.tick\nTraceback (most recent call last):\n  File \"\/usr\/local\/lib\/python3.5\/dist-packages\/cheroot\/server.py\", line 1721, in serve\n  File \"\/usr\/local\/lib\/python3.5\/dist-packages\/cheroot\/server.py\", line 1899, in tick\n  File \"\/usr\/lib\/python3.5\/socket.py\", line 195, in accept\nOSError: [Errno 24] Too many open files\n\n[17\/May\/2019:22:32:35] ENGINE Error in HTTPServer.tick\nTraceback (most recent call last):\n  File \"\/usr\/local\/lib\/python3.5\/dist-packages\/cheroot\/server.py\", line 1721, in serve\n  File \"\/usr\/local\/lib\/python3.5\/dist-packages\/cheroot\/server.py\", line 1899, in tick\n  File \"\/usr\/lib\/python3.5\/socket.py\", line 195, in accept\nOSError: [Errno 24] Too many open files\n\n```",
        "ts": "1558132262.005300",
        "username": "edhrecbot",
        "icons": {
            "emoji": ":robot_face:",
            "image_64": "https:\/\/a.slack-edge.com\/37d58\/img\/emoji_2017_12_06\/apple\/1f916.png"
        },
        "bot_id": "B2867AJ5C"
    },
    {
        "type": "message",
        "subtype": "bot_message",
        "text": "```[17\/May\/2019:22:32:36] ENGINE Error in HTTPServer.tick\nTraceback (most recent call last):\n  File \"\/usr\/local\/lib\/python3.5\/dist-packages\/cheroot\/server.py\", line 1721, in serve\n  File \"\/usr\/local\/lib\/python3.5\/dist-packages\/cheroot\/server.py\", line 1899, in tick\n  File \"\/usr\/lib\/python3.5\/socket.py\", line 195, in accept\nOSError: [Errno 24] Too many open files\n\n```",
        "ts": "1558132262.005400",
        "username": "edhrecbot",
        "icons": {
            "emoji": ":robot_face:",
            "image_64": "https:\/\/a.slack-edge.com\/37d58\/img\/emoji_2017_12_06\/apple\/1f916.png"
        },
        "bot_id": "B2867AJ5C"
    },
    {
        "type": "message",
        "subtype": "bot_message",
        "text": "```[17\/May\/2019:22:32:36] ENGINE Error in HTTPServer.tick\nTraceback (most recent call last):\n  File \"\/usr\/local\/lib\/python3.5\/dist-packages\/cheroot\/server.py\", line 1721, in serve\n  File \"\/usr\/local\/lib\/python3.5\/dist-packages\/cheroot\/server.py\", line 1899, in tick\n  File \"\/usr\/lib\/python3.5\/socket.py\", line 195, in accept\nOSError: [Errno 24] Too many open files\n\n[17\/May\/2019:22:32:36] ENGINE Error in HTTPServer.tick\nTraceback (most recent call last):\n  File \"\/usr\/local\/lib\/python3.5\/dist-packages\/cheroot\/server.py\", line 1721, in serve\n  File \"\/usr\/local\/lib\/python3.5\/dist-packages\/cheroot\/server.py\", line 1899, in tick\n  File \"\/usr\/lib\/python3.5\/socket.py\", line 195, in accept\nOSError: [Errno 24] Too many open files\n\n```",
        "ts": "1558132315.005500",
        "username": "edhrecbot",
        "icons": {
            "emoji": ":robot_face:",
            "image_64": "https:\/\/a.slack-edge.com\/37d58\/img\/emoji_2017_12_06\/apple\/1f916.png"
        },
        "bot_id": "B2867AJ5C"
    },
    {
        "type": "message",
        "subtype": "bot_message",
        "text": "```[17\/May\/2019:22:33:28] ENGINE Error in HTTPServer.tick\nTraceback (most recent call last):\n  File \"\/usr\/local\/lib\/python3.5\/dist-packages\/cheroot\/server.py\", line 1721, in serve\n  File \"\/usr\/local\/lib\/python3.5\/dist-packages\/cheroot\/server.py\", line 1899, in tick\n  File \"\/usr\/lib\/python3.5\/socket.py\", line 195, in accept\nOSError: [Errno 24] Too many open files\n\n[17\/May\/2019:22:33:28] ENGINE Error in HTTPServer.tick\nTraceback (most recent call last):\n  File \"\/usr\/local\/lib\/python3.5\/dist-packages\/cheroot\/server.py\", line 1721, in serve\n  File \"\/usr\/local\/lib\/python3.5\/dist-packages\/cheroot\/server.py\", line 1899, in tick\n  File \"\/usr\/lib\/python3.5\/socket.py\", line 195, in accept\nOSError: [Errno 24] Too many open files\n\n```",
        "ts": "1558132375.005600",
        "username": "edhrecbot",
        "icons": {
            "emoji": ":robot_face:",
            "image_64": "https:\/\/a.slack-edge.com\/37d58\/img\/emoji_2017_12_06\/apple\/1f916.png"
        },
        "bot_id": "B2867AJ5C"
    },
    {
        "type": "message",
        "subtype": "bot_message",
        "text": "```[17\/May\/2019:22:34:29] ENGINE Error in HTTPServer.tick\nTraceback (most recent call last):\n  File \"\/usr\/local\/lib\/python3.5\/dist-packages\/cheroot\/server.py\", line 1721, in serve\n  File \"\/usr\/local\/lib\/python3.5\/dist-packages\/cheroot\/server.py\", line 1899, in tick\n  File \"\/usr\/lib\/python3.5\/socket.py\", line 195, in accept\nOSError: [Errno 24] Too many open files\n\n[17\/May\/2019:22:34:29] ENGINE Error in HTTPServer.tick\nTraceback (most recent call last):\n  File \"\/usr\/local\/lib\/python3.5\/dist-packages\/cheroot\/server.py\", line 1721, in serve\n  File \"\/usr\/local\/lib\/python3.5\/dist-packages\/cheroot\/server.py\", line 1899, in tick\n  File \"\/usr\/lib\/python3.5\/socket.py\", line 195, in accept\nOSError: [Errno 24] Too many open files\n\n```",
        "ts": "1558132435.005700",
        "username": "edhrecbot",
        "icons": {
            "emoji": ":robot_face:",
            "image_64": "https:\/\/a.slack-edge.com\/37d58\/img\/emoji_2017_12_06\/apple\/1f916.png"
        },
        "bot_id": "B2867AJ5C"
    },
    {
        "type": "message",
        "subtype": "bot_message",
        "text": "```2019-05-17 22:35:11,484 ERROR Dynamic too many open files - restarting\n2019-05-17 22:35:11,503 CRITICAL Uncaught exception\nTraceback (most recent call last):\n  File \"\/home\/ubuntu\/edhrec\/core\/wordpress.py\", line 295, in &lt;module&gt;\n    update_all()\n  File \"\/home\/ubuntu\/edhrec\/core\/wordpress.py\", line 282, in update_all\n    _get_multipage('posts')\n  File \"\/home\/ubuntu\/edhrec\/core\/wordpress.py\", line 60, in _get_multipage\n    cache.set('wp\/by-category\/{}\/{}'.format(endpoint, category), item)\n  File \"\/home\/ubuntu\/edhrec\/core\/cache.py\", line 86, in set\n    with _getcursor() as cur:\n  File \"\/usr\/lib\/python3.5\/contextlib.py\", line 59, in __enter__\n    return next(self.gen)\n  File \"\/home\/ubuntu\/edhrec\/core\/cache.py\", line 20, in _getcursor\n    pool = psycopg2.pool.ThreadedConnectionPool(1, 10, user='postgres')\n  File \"\/usr\/local\/lib\/python3.5\/dist-packages\/psycopg2\/pool.py\", line 161, in __init__\n    self, minconn, maxconn, *args, **kwargs)\n  File \"\/usr\/local\/lib\/python3.5\/dist-packages\/psycopg2\/pool.py\", line 58, in __init__\n    self._connect()\n  File \"\/usr\/local\/lib\/python3.5\/dist-packages\/psycopg2\/pool.py\", line 62, in _connect\n    conn = psycopg2.connect(*self._args, **self._kwargs)\n  File \"\/usr\/local\/lib\/python3.5\/dist-packages\/psycopg2\/__init__.py\", line 130, in connect\n    conn = _connect(dsn, connection_factory=connection_factory, **kwasync)\npsycopg2.OperationalError: server closed the connection unexpectedly\n\tThis probably means the server terminated abnormally\n\tbefore or while processing the request.\n\n2019-05-17 22:35:11,518 CRITICAL Uncaught exception\nTraceback (most recent call last):\n  File \"\/home\/ubuntu\/edhrec\/api\/api.py\", line 117, in &lt;module&gt;\n    class App(object):\n  File \"\/home\/ubuntu\/edhrec\/api\/api.py\", line 125, in App\n    commanders = commanders.Commanders()\n  File \"\/home\/ubuntu\/edhrec\/api\/commanders.py\", line 17, in __init__\n    alltime = database.get_commanderlist()\n  File \"\/home\/ubuntu\/edhrec\/core\/database.py\", line 829, in get_commanderlist\n    '''.format(_TABLE_PREFIX), (start_date, end_date))\n  File \"\/usr\/local\/lib\/python3.5\/dist-packages\/psycopg2\/extras.py\", line 141, in execute\n    return super(DictCursor, self).execute(query, vars)\npsycopg2.OperationalError: terminating connection due to administrator command\nLINE 3: ...         SELECT commander, COUNT(*) as count FROM deckswithp...\n                                                             ^\nserver closed the connection unexpectedly\n\tThis probably means the server terminated abnormally\n\tbefore or while processing the request.\n\n2019-05-17 22:35:11,537 ERROR terminating connection due to administrator command\nserver closed the connection unexpectedly\n\tThis probably means the server terminated abnormally\n\tbefore or while processing the request.\n\n2019-05-17 22:35:11,539 ERROR multiprocessing.pool.RemoteTraceback: \n\"\"\"\nTraceback (most recent call last):\n  File \"\/usr\/lib\/python3.5\/multiprocessing\/pool.py\", line 119, in worker\n    result = (True, func(*args, **kwds))\n  File \"\/usr\/lib\/python3.5\/multiprocessing\/pool.py\", line 44, in mapstar\n    return list(map(*args))\n  File \".\/nightly.py\", line 504, in make_card\n    data = origin.getcards(card=name)\n  File \"\/home\/ubuntu\/edhrec\/web\/origin.py\", line 67, in getcards\n    data = database.tally(decks)\n  File \"\/home\/ubuntu\/edhrec\/core\/database.py\", line 1844, in tally\n    deckdata = get_decks(deck_keys)\n  File \"\/home\/ubuntu\/edhrec\/core\/database.py\", line 941, in get_decks\n    return _get_decks_helper(urls) # + _get_decks_helper(urls, brawl=True) + _get_decks_helper(urls, tiny=True) BRAWL\n  File \"\/home\/ubuntu\/edhrec\/core\/database.py\", line 902, in _get_decks_helper\n    ), urls[:fetch_size])\n  File \"\/usr\/local\/lib\/python3.5\/dist-packages\/psycopg2\/extras.py\", line 141, in execute\n    return super(DictCursor, self).execute(query, vars)\npsycopg2.OperationalError: terminating connection due to administrator command\nserver closed the connection unexpectedly\n\tThis probably means the server terminated abnormally",
        "ts": "1558132496.005800",
        "username": "edhrecbot",
        "icons": {
            "emoji": ":robot_face:",
            "image_64": "https:\/\/a.slack-edge.com\/37d58\/img\/emoji_2017_12_06\/apple\/1f916.png"
        },
        "bot_id": "B2867AJ5C"
    },
    {
        "type": "message",
        "subtype": "bot_message",
        "text": "\tbefore or while processing the request.\n\n\"\"\"\n\nThe above exception was the direct cause of the following exception:\n\nTraceback (most recent call last):\n  File \".\/nightly.py\", line 942, in nightly\n    make_cards()\n  File \".\/nightly.py\", line 783, in make_cards\n    pool.map(make_card, cards.get_all(transform=False, split=False))\n  File \"\/usr\/lib\/python3.5\/multiprocessing\/pool.py\", line 260, in map\n    return self._map_async(func, iterable, mapstar, chunksize).get()\n  File \"\/usr\/lib\/python3.5\/multiprocessing\/pool.py\", line 608, in get\n    raise self._value\npsycopg2.OperationalError: terminating connection due to administrator command\nserver closed the connection unexpectedly\n\tThis probably means the server terminated abnormally\n\tbefore or while processing the request.\n\n\n2019-05-17 22:35:11,546 ERROR Dynamic too many open files - restarting\n2019-05-17 22:35:11,547 ERROR Dynamic too many open files - restarting\n2019-05-17 22:35:11,548 ERROR Dynamic too many open files - restarting\n2019-05-17 22:35:11,549 ERROR Dynamic too many open files - restarting\n2019-05-17 22:35:11,551 ERROR Dynamic too many open files - restarting\n2019-05-17 22:35:11,551 ERROR Dynamic too many open files - restarting\n2019-05-17 22:35:11,552 ERROR Dynamic too many open files - restarting\n2019-05-17 22:35:11,553 ERROR Dynamic too many open files - restarting\n2019-05-17 22:35:11,553 ERROR Dynamic too many open files - restarting\n2019-05-17 22:35:11,554 ERROR Dynamic too many open files - restarting\n2019-05-17 22:35:11,556 ERROR Dynamic too many open files - restarting\n2019-05-17 22:35:11,557 ERROR Dynamic too many open files - restarting\n2019-05-17 22:35:11,558 ERROR Dynamic too many open files - restarting\n2019-05-17 22:35:11,558 ERROR Dynamic too many open files - restarting\n2019-05-17 22:35:11,564 CRITICAL Uncaught exception\nTraceback (most recent call last):\n  File \"\/home\/ubuntu\/edhrec\/batch\/update_deckswithprices.py\", line 15, in &lt;module&gt;\n    database.update_deckswithprices()\n  File \"\/home\/ubuntu\/edhrec\/core\/database.py\", line 2217, in update_deckswithprices\n    ''')\n  File \"\/usr\/local\/lib\/python3.5\/dist-packages\/psycopg2\/extras.py\", line 141, in execute\n    return super(DictCursor, self).execute(query, vars)\npsycopg2.OperationalError: terminating connection due to administrator command\nserver closed the connection unexpectedly\n\tThis probably means the server terminated abnormally\n\tbefore or while processing the request.\n\n2019-05-17 22:35:11,558 ERROR Dynamic too many open files - restarting\n2019-05-17 22:35:11,559 ERROR Dynamic too many open files - restarting\n2019-05-17 22:35:11,559 ERROR Dynamic too many open files - restarting\n2019-05-17 22:35:11,559 ERROR Dynamic too many open files - restarting\n2019-05-17 22:35:11,559 ERROR Dynamic too many open files - restarting\n2019-05-17 22:35:11,559 ERROR Dynamic too many open files - restarting\n2019-05-17 22:35:11,560 ERROR Dynamic too many open files - restarting\n2019-05-17 22:35:11,560 ERROR Dynamic too many open files - restarting\n2019-05-17 22:35:11,565 ERROR Dynamic too many open files - restarting\n2019-05-17 22:35:11,565 ERROR Dynamic too many open files - restarting\n2019-05-17 22:35:11,565 ERROR Dynamic too many open files - restarting\n2019-05-17 22:35:11,565 ERROR Dynamic too many open files - restarting\n2019-05-17 22:35:11,563 ERROR Dynamic too many open files - restarting\n2019-05-17 22:35:11,563 ERROR Dynamic too many open files - restarting\n2019-05-17 22:35:11,563 ERROR Dynamic too many open files - restarting\n2019-05-17 22:35:11,563 ERROR Dynamic too many open files - restarting\n2019-05-17 22:35:11,564 ERROR Dynamic too many open files - restarting\n2019-05-17 22:35:11,564 ERROR Dynamic too many open files - restarting\n2019-05-17 22:35:11,564 ERROR Dynamic too many open files - restarting\n2019-05-17 22:35:11,564 ERROR Dynamic too many open files - restarting\n2019-05-17 22:35:11,564 ERROR Dynamic too many open files - restarting\n2019-05-17 22:35:11,564 ERROR Dynamic too many open files - restarting",
        "ts": "1558132496.005900",
        "username": "edhrecbot",
        "icons": {
            "emoji": ":robot_face:",
            "image_64": "https:\/\/a.slack-edge.com\/37d58\/img\/emoji_2017_12_06\/apple\/1f916.png"
        },
        "bot_id": "B2867AJ5C"
    },
    {
        "type": "message",
        "subtype": "bot_message",
        "text": "2019-05-17 22:35:11,564 ERROR Dynamic too many open files - restarting\n2019-05-17 22:35:11,563 ERROR Dynamic too many open files - restarting\n2019-05-17 22:35:11,560 ERROR Dynamic too many open files - restarting\n2019-05-17 22:35:11,560 ERROR Dynamic too many open files - restarting\n2019-05-17 22:35:11,560 ERROR Dynamic too many open files - restarting\n2019-05-17 22:35:11,566 ERROR Dynamic too many open files - restarting\n2019-05-17 22:35:11,566 ERROR Dynamic too many open files - restarting\n2019-05-17 22:35:11,566 ERROR Dynamic too many open files - restarting\n2019-05-17 22:35:11,566 ERROR Dynamic too many open files - restarting\n2019-05-17 22:35:11,566 ERROR Dynamic too many open files - restarting\n2019-05-17 22:35:11,566 ERROR Dynamic too many open files - restarting\n2019-05-17 22:35:11,566 ERROR Dynamic too many open files - restarting\n2019-05-17 22:35:11,566 ERROR Dynamic too many open files - restarting\n2019-05-17 22:35:11,566 ERROR Dynamic too many open files - restarting\n2019-05-17 22:35:11,566 ERROR Dynamic too many open files - restarting\n2019-05-17 22:35:11,568 ERROR Dynamic too many open files - restarting\n2019-05-17 22:35:11,568 ERROR Dynamic too many open files - restarting\n2019-05-17 22:35:11,569 ERROR Dynamic too many open files - restarting\n2019-05-17 22:35:11,583 ERROR Dynamic too many open files - restarting\n2019-05-17 22:35:11,570 ERROR Dynamic too many open files - restarting\n2019-05-17 22:35:11,583 ERROR Dynamic too many open files - restarting\n2019-05-17 22:35:11,570 ERROR Dynamic too many open files - restarting\n2019-05-17 22:35:11,570 ERROR Dynamic too many open files - restarting\n2019-05-17 22:35:11,570 ERROR Dynamic too many open files - restarting\n2019-05-17 22:35:11,570 ERROR Dynamic too many open files - restarting\n2019-05-17 22:35:11,571 ERROR Dynamic too many open files - restarting\n2019-05-17 22:35:11,571 ERROR Dynamic too many open files - restarting\n2019-05-17 22:35:11,571 ERROR Dynamic too many open files - restarting\n2019-05-17 22:35:11,571 ERROR Dynamic too many open files - restarting\n2019-05-17 22:35:11,571 ERROR Dynamic too many open files - restarting\n2019-05-17 22:35:11,571 ERROR Dynamic too many open files - restarting\n2019-05-17 22:35:11,571 ERROR Dynamic too many open files - restarting\n2019-05-17 22:35:11,571 ERROR Dynamic too many open files - restarting\n2019-05-17 22:35:11,571 ERROR Dynamic too many open files - restarting\n2019-05-17 22:35:11,571 ERROR Dynamic too many open files - restarting\n2019-05-17 22:35:11,571 ERROR Dynamic too many open files - restarting\n2019-05-17 22:35:11,571 ERROR Dynamic too many open files - restarting\n2019-05-17 22:35:11,571 ERROR Dynamic too many open files - restarting\n2019-05-17 22:35:11,572 ERROR Dynamic too many open files - restarting\n2019-05-17 22:35:11,572 ERROR Dynamic too many open files - restarting\n2019-05-17 22:35:11,572 ERROR Dynamic too many open files - restarting\n2019-05-17 22:35:11,572 ERROR Dynamic too many open files - restarting\n2019-05-17 22:35:11,572 ERROR Dynamic too many open files - restarting\n2019-05-17 22:35:11,572 ERROR Dynamic too many open files - restarting\n2019-05-17 22:35:11,572 ERROR Dynamic too many open files - restarting\n2019-05-17 22:35:11,572 ERROR Dynamic too many open files - restarting\n2019-05-17 22:35:11,572 ERROR Dynamic too many open files - restarting\n2019-05-17 22:35:11,572 ERROR Dynamic too many open files - restarting\n2019-05-17 22:35:11,573 ERROR Dynamic too many open files - restarting\n2019-05-17 22:35:11,573 ERROR Dynamic too many open files - restarting\n2019-05-17 22:35:11,573 ERROR Dynamic too many open files - restarting\n2019-05-17 22:35:11,573 ERROR Dynamic too many open files - restarting\n2019-05-17 22:35:11,573 ERROR Dynamic too many open files - restarting\n2019-05-17 22:35:11,573 ERROR Dynamic too many open files - restarting\n2019-05-17 22:35:11,573 ERROR Dynamic too many open files - restarting\n2019-05-17 22:35:11,573 ERROR Dynamic too many open files - restarting",
        "ts": "1558132496.006000",
        "username": "edhrecbot",
        "icons": {
            "emoji": ":robot_face:",
            "image_64": "https:\/\/a.slack-edge.com\/37d58\/img\/emoji_2017_12_06\/apple\/1f916.png"
        },
        "bot_id": "B2867AJ5C"
    },
    {
        "type": "message",
        "subtype": "bot_message",
        "text": "2019-05-17 22:35:11,573 ERROR Dynamic too many open files - restarting\n2019-05-17 22:35:11,574 ERROR Dynamic too many open files - restarting\n2019-05-17 22:35:11,574 ERROR Dynamic too many open files - restarting\n2019-05-17 22:35:11,574 ERROR Dynamic too many open files - restarting\n2019-05-17 22:35:11,574 ERROR Dynamic too many open files - restarting\n2019-05-17 22:35:11,574 ERROR Dynamic too many open files - restarting\n2019-05-17 22:35:11,574 ERROR Dynamic too many open files - restarting\n2019-05-17 22:35:11,575 ERROR Dynamic too many open files - restarting\n2019-05-17 22:35:11,575 ERROR Dynamic too many open files - restarting\n2019-05-17 22:35:11,575 ERROR Dynamic too many open files - restarting\n2019-05-17 22:35:11,575 ERROR Dynamic too many open files - restarting\n2019-05-17 22:35:11,575 ERROR Dynamic too many open files - restarting\n2019-05-17 22:35:11,575 ERROR Dynamic too many open files - restarting\n2019-05-17 22:35:11,576 ERROR Dynamic too many open files - restarting\n2019-05-17 22:35:11,576 ERROR Dynamic too many open files - restarting\n2019-05-17 22:35:11,576 ERROR Dynamic too many open files - restarting\n2019-05-17 22:35:11,576 ERROR Dynamic too many open files - restarting\n2019-05-17 22:35:11,576 ERROR Dynamic too many open files - restarting\n2019-05-17 22:35:11,576 ERROR Dynamic too many open files - restarting\n2019-05-17 22:35:11,576 ERROR Dynamic too many open files - restarting\n2019-05-17 22:35:11,577 ERROR Dynamic too many open files - restarting\n2019-05-17 22:35:11,577 ERROR Dynamic too many open files - restarting\n2019-05-17 22:35:11,577 ERROR Dynamic too many open files - restarting\n2019-05-17 22:35:11,577 ERROR Dynamic too many open files - restarting\n2019-05-17 22:35:11,577 ERROR Dynamic too many open files - restarting\n2019-05-17 22:35:11,577 ERROR Dynamic too many open files - restarting\n2019-05-17 22:35:11,577 ERROR Dynamic too many open files - restarting\n2019-05-17 22:35:11,577 ERROR Dynamic too many open files - restarting\n2019-05-17 22:35:11,577 ERROR Dynamic too many open files - restarting\n2019-05-17 22:35:11,578 ERROR Dynamic too many open files - restarting\n2019-05-17 22:35:11,578 ERROR Dynamic too many open files - restarting\n2019-05-17 22:35:11,578 ERROR Dynamic too many open files - restarting\n2019-05-17 22:35:11,579 ERROR Dynamic too many open files - restarting\n2019-05-17 22:35:11,579 ERROR Dynamic too many open files - restarting\n2019-05-17 22:35:11,582 ERROR Dynamic too many open files - restarting\n2019-05-17 22:35:11,583 ERROR Dynamic too many open files - restarting\n2019-05-17 22:35:11,583 ERROR Dynamic too many open files - restarting\n2019-05-17 22:35:11,583 ERROR Dynamic too many open files - restarting\n2019-05-17 22:35:11,570 ERROR Dynamic too many open files - restarting\n2019-05-17 22:35:11,583 ERROR Dynamic too many open files - restarting\n2019-05-17 22:35:11,583 ERROR Dynamic too many open files - restarting\n2019-05-17 22:35:11,570 ERROR Dynamic too many open files - restarting\n2019-05-17 22:35:11,585 ERROR Dynamic too many open files - restarting\n2019-05-17 22:35:11,585 ERROR Dynamic too many open files - restarting\n2019-05-17 22:35:11,585 ERROR Dynamic too many open files - restarting\n2019-05-17 22:35:11,585 ERROR Dynamic too many open files - restarting\n2019-05-17 22:35:11,585 ERROR Dynamic too many open files - restarting\n2019-05-17 22:35:11,585 ERROR Dynamic too many open files - restarting\n2019-05-17 22:35:11,588 ERROR Dynamic too many open files - restarting\n2019-05-17 22:35:11,588 ERROR Dynamic too many open files - restarting\n2019-05-17 22:35:11,588 ERROR Dynamic too many open files - restarting\n2019-05-17 22:35:11,588 ERROR Dynamic too many open files - restarting\n2019-05-17 22:35:11,588 ERROR Dynamic too many open files - restarting\n2019-05-17 22:35:11,588 ERROR Dynamic too many open files - restarting\n2019-05-17 22:35:11,591 ERROR Dynamic too many open files - restarting\n2019-05-17 22:35:11,643 ERROR Dynamic too many open files - restarting",
        "ts": "1558132496.006100",
        "username": "edhrecbot",
        "icons": {
            "emoji": ":robot_face:",
            "image_64": "https:\/\/a.slack-edge.com\/37d58\/img\/emoji_2017_12_06\/apple\/1f916.png"
        },
        "bot_id": "B2867AJ5C"
    },
    {
        "type": "message",
        "subtype": "bot_message",
        "text": "2019-05-17 22:35:11,643 ERROR Dynamic too many open files - restarting\n2019-05-17 22:35:11,657 ERROR Dynamic too many open files - restarting\n2019-05-17 22:35:11,761 CRITICAL Uncaught exception\nTraceback (most recent call last):\n  File \"\/home\/ubuntu\/edhrec\/batch\/cache_get_cards.py\", line 23, in &lt;module&gt;\n    run()\n  File \"\/home\/ubuntu\/edhrec\/batch\/cache_get_cards.py\", line 18, in run\n    database.get_card(name, ignore_cached=True)\n  File \"\/home\/ubuntu\/edhrec\/core\/database.py\", line 494, in get_card\n    _TABLE_PREFIX), (card,))\n  File \"\/usr\/local\/lib\/python3.5\/dist-packages\/psycopg2\/extras.py\", line 141, in execute\n    return super(DictCursor, self).execute(query, vars)\npsycopg2.OperationalError: terminating connection due to administrator command\nserver closed the connection unexpectedly\n\tThis probably means the server terminated abnormally\n\tbefore or while processing the request.\n\n2019-05-17 22:35:12,397 CRITICAL Uncaught exception\nTraceback (most recent call last):\n  File \"\/home\/ubuntu\/edhrec\/web\/dynamic.py\", line 6, in &lt;module&gt;\n    import nightly\n  File \"\/home\/ubuntu\/edhrec\/web\/nightly.py\", line 23, in &lt;module&gt;\n    import edhrec.core.cards as cards\n  File \"\/home\/ubuntu\/edhrec\/core\/cards.py\", line 27, in &lt;module&gt;\n    _CARDS = cache.get('allcards')\n  File \"\/home\/ubuntu\/edhrec\/core\/cache.py\", line 47, in get\n    with _getcursor() as cur:\n  File \"\/usr\/lib\/python3.5\/contextlib.py\", line 59, in __enter__\n    return next(self.gen)\n  File \"\/home\/ubuntu\/edhrec\/core\/cache.py\", line 20, in _getcursor\n    pool = psycopg2.pool.ThreadedConnectionPool(1, 10, user='postgres')\n  File \"\/usr\/local\/lib\/python3.5\/dist-packages\/psycopg2\/pool.py\", line 161, in __init__\n    self, minconn, maxconn, *args, **kwargs)\n  File \"\/usr\/local\/lib\/python3.5\/dist-packages\/psycopg2\/pool.py\", line 58, in __init__\n    self._connect()\n  File \"\/usr\/local\/lib\/python3.5\/dist-packages\/psycopg2\/pool.py\", line 62, in _connect\n    conn = psycopg2.connect(*self._args, **self._kwargs)\n  File \"\/usr\/local\/lib\/python3.5\/dist-packages\/psycopg2\/__init__.py\", line 130, in connect\n    conn = _connect(dsn, connection_factory=connection_factory, **kwasync)\npsycopg2.OperationalError: could not connect to server: No such file or directory\n\tIs the server running locally and accepting\n\tconnections on Unix domain socket \"\/var\/run\/postgresql\/.s.PGSQL.5432\"?\n\n```",
        "ts": "1558132496.006200",
        "username": "edhrecbot",
        "icons": {
            "emoji": ":robot_face:",
            "image_64": "https:\/\/a.slack-edge.com\/37d58\/img\/emoji_2017_12_06\/apple\/1f916.png"
        },
        "bot_id": "B2867AJ5C"
    },
    {
        "client_msg_id": "9dcebd76-770a-415f-b7c9-1625bd74687c",
        "type": "message",
        "text": "shits fine now but there was like 50+ postgres processes",
        "user": "U28TLDP0R",
        "ts": "1558132540.006600",
        "team": "T286HM2F3",
        "user_team": "T286HM2F3",
        "source_team": "T286HM2F3",
        "user_profile": {
            "avatar_hash": "2a61603e280e",
            "image_72": "https:\/\/avatars.slack-edge.com\/2016-11-16\/104915990673_2a61603e280ecee0ab38_72.jpg",
            "first_name": "David",
            "real_name": "David Keatts",
            "display_name": "keattz",
            "team": "T286HM2F3",
            "name": "keattz",
            "is_restricted": false,
            "is_ultra_restricted": false
        }
    },
    {
        "type": "message",
        "subtype": "bot_message",
        "text": "Nightly failed:\nterminating connection due to administrator command\nserver closed the connection unexpectedly\n\tThis probably means the server terminated abnormally\n\tbefore or while processing the request.\n\nmultiprocessing.pool.RemoteTraceback: \n\"\"\"\nTraceback (most recent call last):\n  File \"\/usr\/lib\/python3.5\/multiprocessing\/pool.py\", line 119, in worker\n    result = (True, func(*args, **kwds))\n  File \"\/usr\/lib\/python3.5\/multiprocessing\/pool.py\", line 44, in mapstar\n    return list(map(*args))\n  File \".\/nightly.py\", line 504, in make_card\n    data = origin.getcards(card=name)\n  File \"\/home\/ubuntu\/edhrec\/web\/origin.py\", line 67, in getcards\n    data = database.tally(decks)\n  File \"\/home\/ubuntu\/edhrec\/core\/database.py\", line 1844, in tally\n    deckdata = get_decks(deck_keys)\n  File \"\/home\/ubuntu\/edhrec\/core\/database.py\", line 941, in get_decks\n    return _get_decks_helper(urls) # + _get_decks_helper(urls, brawl=True) + _get_decks_helper(urls, tiny=True) BRAWL\n  File \"\/home\/ubuntu\/edhrec\/core\/database.py\", line 902, in _get_decks_helper\n    ), urls[:fetch_size])\n  File \"\/usr\/local\/lib\/python3.5\/dist-packages\/psycopg2\/extras.py\", line 141, in execute\n    return super(DictCursor, self).execute(query, vars)\npsycopg2.OperationalError: terminating connection due to administrator command\nserver closed the connection unexpectedly\n\tThis probably means the server terminated abnormally\n\tbefore or while processing the request.\n\n\"\"\"\n\nThe above exception was the direct cause of the following exception:\n\nTraceback (most recent call last):\n  File \".\/nightly.py\", line 942, in nightly\n    make_cards()\n  File \".\/nightly.py\", line 783, in make_cards\n    pool.map(make_card, cards.get_all(transform=False, split=False))\n  File \"\/usr\/lib\/python3.5\/multiprocessing\/pool.py\", line 260, in map\n    return self._map_async(func, iterable, mapstar, chunksize).get()\n  File \"\/usr\/lib\/python3.5\/multiprocessing\/pool.py\", line 608, in get\n    raise self._value\npsycopg2.OperationalError: terminating connection due to administrator command\nserver closed the connection unexpectedly\n\tThis probably means the server terminated abnormally\n\tbefore or while processing the request.\n\n",
        "ts": "1558132556.006700",
        "username": "edhrecbot",
        "icons": {
            "emoji": ":robot_face:",
            "image_64": "https:\/\/a.slack-edge.com\/37d58\/img\/emoji_2017_12_06\/apple\/1f916.png"
        },
        "bot_id": "B2867AJ5C"
    },
    {
        "type": "message",
        "subtype": "bot_message",
        "text": "```2019-05-17 22:37:30,100 INFO nightly.py took 7:08:15.560893\n```",
        "ts": "1558132617.007200",
        "username": "edhrecbot",
        "icons": {
            "emoji": ":robot_face:",
            "image_64": "https:\/\/a.slack-edge.com\/37d58\/img\/emoji_2017_12_06\/apple\/1f916.png"
        },
        "bot_id": "B2867AJ5C"
    },
    {
        "client_msg_id": "c252f098-fab2-4126-9890-efd4ff74772b",
        "type": "message",
        "text": "eh, maybe just stressing the box out too much trying to run nightly in combination with other regular cron tasks",
        "user": "U28TLDP0R",
        "ts": "1558132621.007400",
        "team": "T286HM2F3",
        "user_team": "T286HM2F3",
        "source_team": "T286HM2F3",
        "user_profile": {
            "avatar_hash": "2a61603e280e",
            "image_72": "https:\/\/avatars.slack-edge.com\/2016-11-16\/104915990673_2a61603e280ecee0ab38_72.jpg",
            "first_name": "David",
            "real_name": "David Keatts",
            "display_name": "keattz",
            "team": "T286HM2F3",
            "name": "keattz",
            "is_restricted": false,
            "is_ultra_restricted": false
        }
    },
    {
        "type": "message",
        "subtype": "bot_message",
        "text": "```2019-05-17 23:47:14,064 CRITICAL Uncaught exception\nTraceback (most recent call last):\n  File \"&lt;string&gt;\", line 1, in &lt;module&gt;\n  File \"\/home\/ubuntu\/edhrec\/web\/nightly.py\", line 171, in make_top_index\n    alltime = origin.gettop()\n  File \"\/home\/ubuntu\/edhrec\/web\/origin.py\", line 737, in gettop\n    data = database.get_top(cardtype=cardtype, cardsubtype=cardsubtype, colorid=colorid, keyword=keyword, start_date=start_date, end_date=end_date)\n  File \"\/home\/ubuntu\/edhrec\/core\/database.py\", line 1253, in get_top\n    '''.format(qualifier=qualifier, coloridline=coloridline, typeline=typeline, limit=limit, sort_col=sort_col, dateline=dateline)\nUnboundLocalError: local variable 'dateline' referenced before assignment\n```",
        "ts": "1558136741.007500",
        "username": "edhrecbot",
        "icons": {
            "emoji": ":robot_face:",
            "image_64": "https:\/\/a.slack-edge.com\/37d58\/img\/emoji_2017_12_06\/apple\/1f916.png"
        },
        "bot_id": "B2867AJ5C"
    },
    {
        "type": "message",
        "subtype": "bot_message",
        "text": "```2019-05-18 00:00:28,317 ERROR screeching bat missing from cardkingdom prices json\n2019-05-18 00:00:28,317 ERROR uninvited geist missing from cardkingdom prices json\n2019-05-18 00:00:28,318 ERROR tormented pariah missing from cardkingdom prices json\n2019-05-18 00:00:28,318 ERROR solitary hunter missing from cardkingdom prices json\n2019-05-18 00:00:28,318 ERROR skin invasion missing from cardkingdom prices json\n2019-05-18 00:00:28,318 ERROR autumnal gloom missing from cardkingdom prices json\n2019-05-18 00:00:28,318 ERROR hinterland hermit missing from cardkingdom prices json\n2019-05-18 00:00:28,319 ERROR lambholt elder missing from cardkingdom prices json\n2019-05-18 00:00:28,319 ERROR thraben gargoyle missing from cardkingdom prices json\n2019-05-18 00:00:28,319 ERROR civilized scholar missing from cardkingdom prices json\n2019-05-18 00:00:28,319 ERROR ulvenwald mystics missing from cardkingdom prices json\n2019-05-18 00:00:28,320 ERROR soul seizer missing from cardkingdom prices json\n2019-05-18 00:00:28,320 ERROR thraben sentry missing from cardkingdom prices json\n2019-05-18 00:00:28,320 ERROR elusive tormentor missing from cardkingdom prices json\n2019-05-18 00:00:28,320 ERROR lambholt pacifist missing from cardkingdom prices json\n2019-05-18 00:00:28,320 ERROR ravenous demon missing from cardkingdom prices json\n2019-05-18 00:00:28,321 ERROR grizzled angler missing from cardkingdom prices json\n2019-05-18 00:00:28,321 ERROR cryptolith fragment missing from cardkingdom prices json\n2019-05-18 00:00:28,321 ERROR kindly stranger missing from cardkingdom prices json\n2019-05-18 00:00:28,321 ERROR convicted killer missing from cardkingdom prices json\n2019-05-18 00:00:28,321 ERROR avacynian missionaries missing from cardkingdom prices json\n2019-05-18 00:00:28,322 ERROR chosen of markov missing from cardkingdom prices json\n2019-05-18 00:00:28,322 ERROR daring sleuth missing from cardkingdom prices json\n2019-05-18 00:00:28,322 ERROR hinterland logger missing from cardkingdom prices json\n2019-05-18 00:00:28,322 ERROR cloistered youth missing from cardkingdom prices json\n2019-05-18 00:00:28,322 ERROR grizzled outcasts missing from cardkingdom prices json\n2019-05-18 00:00:28,323 ERROR villagers of estwald missing from cardkingdom prices json\n2019-05-18 00:00:28,323 ERROR village ironsmith missing from cardkingdom prices json\n2019-05-18 00:00:28,323 ERROR gatstaf shepherd missing from cardkingdom prices json\n2019-05-18 00:00:28,323 ERROR neglected heirloom missing from cardkingdom prices json\n2019-05-18 00:00:28,324 ERROR aberrant researcher missing from cardkingdom prices json\n```",
        "ts": "1558137535.007600",
        "username": "edhrecbot",
        "icons": {
            "emoji": ":robot_face:",
            "image_64": "https:\/\/a.slack-edge.com\/37d58\/img\/emoji_2017_12_06\/apple\/1f916.png"
        },
        "bot_id": "B2867AJ5C"
    },
    {
        "type": "message",
        "subtype": "bot_message",
        "text": "```2019-05-18 00:08:26,062 INFO cards.py took 0:08:22.318259\n```",
        "ts": "1558138013.007700",
        "username": "edhrecbot",
        "icons": {
            "emoji": ":robot_face:",
            "image_64": "https:\/\/a.slack-edge.com\/37d58\/img\/emoji_2017_12_06\/apple\/1f916.png"
        },
        "bot_id": "B2867AJ5C"
    },
    {
        "type": "message",
        "subtype": "bot_message",
        "text": "```2019-05-18 00:18:21,059 CRITICAL Uncaught exception\nTraceback (most recent call last):\n  File \"&lt;string&gt;\", line 1, in &lt;module&gt;\n  File \"\/home\/ubuntu\/edhrec\/web\/nightly.py\", line 169, in make_top_index\n    week = origin.gettop(start_date=(date.today() - timedelta(7)))['cards']\nTypeError: list indices must be integers or slices, not str\n```",
        "ts": "1558138607.007800",
        "username": "edhrecbot",
        "icons": {
            "emoji": ":robot_face:",
            "image_64": "https:\/\/a.slack-edge.com\/37d58\/img\/emoji_2017_12_06\/apple\/1f916.png"
        },
        "bot_id": "B2867AJ5C"
    },
    {
        "type": "message",
        "subtype": "bot_message",
        "text": "```2019-05-18 00:24:58,182 CRITICAL Uncaught exception\nTraceback (most recent call last):\n  File \"&lt;string&gt;\", line 1, in &lt;module&gt;\n  File \"\/home\/ubuntu\/edhrec\/web\/nightly.py\", line 238, in make_top_types\n    cardlists = CardList(data, 'Top ' + subpage['name'])\nNameError: name 'data' is not defined\n```",
        "ts": "1558139005.007900",
        "username": "edhrecbot",
        "icons": {
            "emoji": ":robot_face:",
            "image_64": "https:\/\/a.slack-edge.com\/37d58\/img\/emoji_2017_12_06\/apple\/1f916.png"
        },
        "bot_id": "B2867AJ5C"
    },
    {
        "type": "message",
        "subtype": "bot_message",
        "text": "```2019-05-18 00:35:30,525 INFO archidekt.py took 0:25:07.326497\n```",
        "ts": "1558139637.008000",
        "username": "edhrecbot",
        "icons": {
            "emoji": ":robot_face:",
            "image_64": "https:\/\/a.slack-edge.com\/37d58\/img\/emoji_2017_12_06\/apple\/1f916.png"
        },
        "bot_id": "B2867AJ5C"
    },
    {
        "type": "message",
        "subtype": "bot_message",
        "text": "```2019-05-18 00:47:00,433 WARNING Chaos Orb from A Display of My Dark Power in <https:\/\/deckstats.net\/decks\/107010\/1296615-nezahal-primal-tide\/en>\n```",
        "ts": "1558140327.008100",
        "username": "edhrecbot",
        "icons": {
            "emoji": ":robot_face:",
            "image_64": "https:\/\/a.slack-edge.com\/37d58\/img\/emoji_2017_12_06\/apple\/1f916.png"
        },
        "bot_id": "B2867AJ5C"
    },
    {
        "type": "message",
        "subtype": "bot_message",
        "text": "```2019-05-18 00:59:40,674 WARNING Chaos Orb from Crow Storm in <https:\/\/deckstats.net\/decks\/119746\/1185214-kenrith-twins-spellslingers\/en#Row>\n```",
        "ts": "1558141087.008200",
        "username": "edhrecbot",
        "icons": {
            "emoji": ":robot_face:",
            "image_64": "https:\/\/a.slack-edge.com\/37d58\/img\/emoji_2017_12_06\/apple\/1f916.png"
        },
        "bot_id": "B2867AJ5C"
    },
    {
        "type": "message",
        "subtype": "bot_message",
        "text": "```2019-05-18 01:07:18,538 INFO deckstats.py took 0:29:49.010194\n```",
        "ts": "1558141545.008300",
        "username": "edhrecbot",
        "icons": {
            "emoji": ":robot_face:",
            "image_64": "https:\/\/a.slack-edge.com\/37d58\/img\/emoji_2017_12_06\/apple\/1f916.png"
        },
        "bot_id": "B2867AJ5C"
    },
    {
        "type": "message",
        "subtype": "bot_message",
        "text": "```2019-05-18 01:49:13,194 ERROR Chaos Orb in <http:\/\/www.mtggoldfish.com\/deck\/1916311>\n```",
        "ts": "1558144060.008400",
        "username": "edhrecbot",
        "icons": {
            "emoji": ":robot_face:",
            "image_64": "https:\/\/a.slack-edge.com\/37d58\/img\/emoji_2017_12_06\/apple\/1f916.png"
        },
        "bot_id": "B2867AJ5C"
    },
    {
        "type": "message",
        "subtype": "bot_message",
        "text": "```2019-05-18 01:57:47,068 INFO mtggoldfish.py took 0:30:09.469906\n```",
        "ts": "1558144573.008500",
        "username": "edhrecbot",
        "icons": {
            "emoji": ":robot_face:",
            "image_64": "https:\/\/a.slack-edge.com\/37d58\/img\/emoji_2017_12_06\/apple\/1f916.png"
        },
        "bot_id": "B2867AJ5C"
    },
    {
        "type": "message",
        "subtype": "bot_message",
        "text": "```2019-05-18 02:15:59,248 INFO update_deckswithprices.py took 0:18:10.029808\n```",
        "ts": "1558145666.008600",
        "username": "edhrecbot",
        "icons": {
            "emoji": ":robot_face:",
            "image_64": "https:\/\/a.slack-edge.com\/37d58\/img\/emoji_2017_12_06\/apple\/1f916.png"
        },
        "bot_id": "B2867AJ5C"
    },
    {
        "type": "message",
        "subtype": "bot_message",
        "text": "Nightly started, onlydecks=False, skipdecks=False",
        "ts": "1558145669.008700",
        "username": "edhrecbot",
        "icons": {
            "emoji": ":robot_face:",
            "image_64": "https:\/\/a.slack-edge.com\/37d58\/img\/emoji_2017_12_06\/apple\/1f916.png"
        },
        "bot_id": "B2867AJ5C"
    }
]